Workbook

Sheet log
A1: log
A2: Done. I read your comments in the log and Summary tabs and applied them. Your comments stay in the file; my answers are in the new columns (log: "My response"; Summary: columns G and H). What I produced - 5 Joomla import files, exact export format (checked by a round trip), only the products to update, nothing overlaps: 1 mason jar (MJ11-57, MJ102-53, AUMJ100-05, MJ100-17), 2 greenery (MJ100-07, DC-02A, DC112-01A), 3 colours (AU1211-04, AU1111-04, AU219-40), 4 title count (AU11-30), 5 containers and fruit (FBAU61-66, FBAU76-60). - AU-Recipe-Fixes-v1-control.xlsx: the Flag Jarrod lists, Before-After (1 row per SKU, red BEFORE and green AFTER per variant, plus added / removed / changed and Ingredient Price before and after) and Final recipes (all 36 Designer Collection products and every fixed SKU). - This workbook (v10): comments kept and answered, the lists as classes (Flag Jarrod x6, Wine products 18+, Title vs recipe linguistic, Labels removed), an Origin column in colour, and Bunches and Stems lines rewritten to be more inspiring. - AUS master MD v7, both skills v9, the rules artifact republished and the Claude Doc "AU Pricing Rules" updated (nothing held, wine rule for every wine product, container / colour / greenery rules, Joomla upload rules, PV1-PV6, voice codes V1-V19). Your questions - FBAU76-60 fruit: I did not lower it. Live is 6/8/12/15, Jarrod's file is 8/10/12/15. My earlier "Alejandro lowered it to 8" was an assumption I could not verify and I withdraw it. File 5 restores Jarrod's 8 and 10 (upload only, because Jarrod's recipe is right). - Containers: the issue is in Jarrod's file (Small Basket and Gift Basket Box on FBAU61-66 and FBAU76-60; also AU64-11, GBAU71-61, FBAU61-62, outside the five buckets, listed not fixed). I removed the Gift Basket Box in file 5; it looks like outer packaging, so confirm before uploading. - Colours: Jarrod had not fixed them. Replacements are carried. In the AU-Cost master the swaps are the same price, but not in Joomla's own unit costs (Roses Red 1.20 vs Yellow, White, light pink 1.01): AU1211-04's Ingredient Price rises by 1.71 to 3.42 per size; AU1111-04 and AU219-40 do not change. AU199-07's green is its ruscus, so no fix. I could not check KEN or COL (the Product Master has no such column), only the Full Ingredient List. - Greenery: caps do exist (A-C1 in the master file; the Doc said they were never given) and every addition is within them. MJ100-17 and MJ100-07 get 2 x Ruscus Israeli per size (rule G1 from another session today); DC-02A 2/3/3/4 and DC112-01A 2/2/3/3. - Item 2 vs 1b: 1b is a recipe with no jar; item 2 is a recipe that already has the vase or jar and the text had to name it, so nothing to notify. New rule: add the Mason Jar, not a vase. - Blooms vs stems: labels and rule deleted. Not on storefront: only AU11-14 is still N (the other three are live on 7 Oct). Wine: the 18+ notice now applies to all 64 live wine products (list in the log); legal wording first, brand adaptation only after legal agrees. Another session published rules v6 (J1-J5 and G1) while I worked; I merged it into the master file and followed it (Ingredient Price from Joomla unit costs, branch rule, G1). Needs your attention: AUMJ100-05 Petite is priced 39.95 but has no ingredient lines in Joomla, so I did not patch it (decision needed). AU11-30 now has Petite = Standard = 6.
A4: Your comments | B4: My response | C4: SKU | D4: Product title | E4: Bucket | F4: Class | G4: Origin of the problem | H4: Issue type | I4: Detail | J4: Source | K4: Owner / notify
A5: First apply what I mentioned in the summary and we will continue from there. | B5: Applied what you wrote in the Summary: jar added to every size that has a recipe in Joomla_import_1_mason_jar_v1. Petite is priced 39.95 but has no ingredient lines in live, so I did not touch it and flagged it. | C5: AUMJ100-05 | D5: Gerbera Daisies in Mason Jar | E5: Mason Jar | F5: Flag Jarrod: mason jar | G5: Jarrod file (his Standard has no Mason Jar) | H5: Mason jar | I5: Added: - | Removed: - | Changed: - | 7.22→7.54 | 11.3→11.62 | 15.65→15.97 | J5: Joomla_import_1_mason_jar_v1.xlsx | K5: Jarrod: list + upload (J4)
C6: MJ100-17 | D6: Thirty Blooms of Alstroemeria in Mason Jar | E6: Mason Jar | F6: Flag Jarrod: mason jar | G6: Jarrod file (his Standard has no Mason Jar) | H6: Mason jar | I6: Added: - | Removed: - | Changed: 7.85→10.53 | 10.49→13.17 | 13.13→15.81 | 15.77→18.45 | J6: Joomla_import_1_mason_jar_v1.xlsx | K6: Jarrod: list + upload (J4)
C7: MJ102-53 | D7: Make a Wish in Mason Jar Birthday Bundle | E7: Mason Jar | F7: Flag Jarrod: mason jar | G7: Jarrod file (his Standard has no Mason Jar) | H7: Mason jar | I7: Added: - | Removed: - | Changed: 13.73→14.05 | 15.85→16.17 | 18.61→18.93 | 22.13→22.45 | J7: Joomla_import_1_mason_jar_v1.xlsx | K7: Jarrod: list + upload (J4)
C8: MJ11-57 | D8: Half Dozen Assorted Roses in Mason Jar | E8: Mason Jar | F8: Flag Jarrod: mason jar | G8: Jarrod file (his Standard has no Mason Jar) | H8: Mason jar | I8: Added: - | Removed: - | Changed: 9.53→9.85 | 11.73→12.05 | 11.73→12.05 | 15.01→15.33 | J8: Joomla_import_1_mason_jar_v1.xlsx | K8: Jarrod: list + upload (J4)
C9: DC-02A | D9: Designer Collection Anniversary II | E9: Designer Collection | F9: Flag Jarrod: greenery | G9: Jarrod file (his Standard has no greenery) | H9: Greenery | I9: Added: - | Removed: - | Changed: 11.04→13.4 | 14.44→17.98 | 17.84→21.38 | 21.24→25.96 | J9: Joomla_import_2_greenery_v1.xlsx | K9: Jarrod: list + upload (J4)
C10: DC112-01A | D10: Designers Collection I | E10: Designer Collection | F10: Flag Jarrod: greenery | G10: Jarrod file (his Standard has no greenery) | H10: Greenery | I10: Added: - | Removed: - | Changed: 7.64→10.0 | 10.19→12.55 | 12.74→16.28 | 15.29→18.83 | J10: Joomla_import_2_greenery_v1.xlsx | K10: Jarrod: list + upload (J4)
C11: MJ100-07 | D11: Thirty Blooms Of Alstroemeria In Mason Jar | E11: Mason Jar | F11: Flag Jarrod: greenery | G11: Jarrod file (his Standard has no greenery) | H11: Greenery | I11: Added: - | Removed: - | Changed: 9.05→11.41 | 11.69→14.05 | 14.33→16.69 | 16.97→19.33 | J11: Joomla_import_2_greenery_v1.xlsx | K11: Jarrod: list + upload (J4)
C12: AU1111-04 | D12: 24 Pink and White Roses | E12: Bouquets | F12: Flag Jarrod: colour (title says two, recipe has one) | G12: Jarrod file (his Standard has the same colours as live) | H12: Colour | I12: Added: - | Removed: Petite: Roses White 18 → 9, Standard: Roses White 24 → 12, Deluxe: Roses White 30 → 15, Supersize: Roses White 36 → 18 | Changed: 25.57→25.57 | 33.89→33.89 | 39.95→39.95 | 47.19→47.19 | J12: Joomla_import_3_colours_v1.xlsx | K12: Jarrod: list + upload (J4)
C13: AU1211-04 | D13: 24 Red and Yellow Roses | E13: Roses | F13: Flag Jarrod: colour (title says two, recipe has one) | G13: Jarrod file (his Standard has the same colours as live) | H13: Colour | I13: Added: - | Removed: Petite: Roses Yellow 18 → 9, Standard: Roses Yellow 24 → 12, Deluxe: Roses Yellow 30 → 15, Supersize: Roses Yellow 36 → 18 | Changed: 25.57→27.28 | 33.89→36.17 | 41.13→43.98 | 49.45→52.87 | J13: Joomla_import_3_colours_v1.xlsx | K13: Jarrod: list + upload (J4)
A14: verify if we have that ingredient in KEN COL recipe (if we have then include it in the list of changes and in a separated file to udate wit the (mixed colors file this list (1c Title colours (AU1211-04, AU1111-04, AU219-40, AU199-07)) is in the instructions from the summary || Do the same the AU219-40 | B14: Checked the Full Ingredient List of the Product Master (it has no KEN or COL label, so I could not check those two lists): Roses light pink (ING-429, $1.30) = Roses Yellow ($1.30) and Mini Carnations Pink (ING-111, $0.95) = Mini Carnations Red ($0.95), both carried and same price. Jarrod's Standard has the same yellow and red, so he did not fix it. Swap applied in all sizes in Joomla_import_3_colours_v1. Listed here for you to notify Jarrod. | C14: AU219-40 | D14: Pink and Lavender Bouquet | E14: Bouquets | F14: Flag Jarrod: colour (title says two, recipe has one) | G14: Jarrod file (his Standard has the same colours as live) | H14: Colour | I14: Added: Petite: −2 × Roses Yellow, Standard: −3 × Roses Yellow, Deluxe: −4 × Roses Yellow, Supersize: −5 × Roses Yellow, Petite: −1 × Mini Carnations Red, Standard: −2 × Mini Carnations Red, Deluxe: −2 × Mini Carnations Red, Supersize: −3 × Mini Carnations Red | Removed: - | Changed: 13.3→13.3 | 19.04→19.04 | 25.02→25.02 | 31.94→31.94 | J14: Joomla_import_3_colours_v1.xlsx | K14: Jarrod: list + upload (J4)
C15: AU11-30 | D15: Half-Dozen Red Roses | E15: Bouquets | F15: Flag Jarrod: title count | G15: Jarrod file (his Standard is 12 roses, same as live) | H15: Title count | I15: Added: - | Removed: Standard: Roses Red 12 → 6 | Changed: 12.33→12.33 | 21.79→14.59 | 28.99→28.99 | 38.45→38.45 | J15: Joomla_import_4_title_count_v1.xlsx | K15: Jarrod: list + upload (J4)
C16: AU64-11 | D16: Christmas Glory | F16: Flag Jarrod: container / quantity | G16: Jarrod file has both Small Basket and Gift Basket Box | H16: Container (not in the five buckets) | I16: Same two-container issue; not fixed here because the product is outside the five buckets. Tell me if you want them in file 5 | J16: Recipe rules C1-C9 | K16: Jarrod (you notify manually)
C17: FBAU61-62 | D17: Fruit Lover Basket | F17: Flag Jarrod: container / quantity | G17: Jarrod file has both Small Basket and Gift Basket Box | H17: Container (not in the five buckets) | I17: Same two-container issue; not fixed here because the product is outside the five buckets. Tell me if you want them in file 5 | J17: Recipe rules C1-C9 | K17: Jarrod (you notify manually)
C18: GBAU71-61 | D18: Classic Collection II | F18: Flag Jarrod: container / quantity | G18: Jarrod file has both Small Basket and Gift Basket Box | H18: Container (not in the five buckets) | I18: Same two-container issue; not fixed here because the product is outside the five buckets. Tell me if you want them in file 5 | J18: Recipe rules C1-C9 | K18: Jarrod (you notify manually)
A19: Only one containre, Is the issue in Jarrod recipe ? If so as I mention in the cell E18 of summary tab, add those in the list of mason jar so I notify Jarrod manualy. But fix the recipe, include them in the file for the lsit and include it in the product export for joomla, (So I have the other file for me,) to control to learlty see the difference in the recipe, what it was what was missing what was added, the version of every variant in a secon tab, and the file to export the one that I'd need for joomla | B19: The issue is in Jarrod's file: his Petite to Supersize list both a Small Basket and a Gift Basket Box - Medium (same on AU64-11, GBAU71-61 and FBAU61-62, outside the five buckets, listed but not fixed). Fixed in Joomla_import_5 by removing the Gift Basket Box and keeping the Small Basket. The box looks like outer packaging, so confirm with Jarrod before uploading. What it was, what was missing and what was added per variant: AU-Recipe-Fixes-v1-control.xlsx (Before-After tab). | C19: FBAU61-66 | D19: European Sampler Basket | E19: Bouquets | F19: Flag Jarrod: container / quantity | G19: Jarrod file has both Small Basket and Gift Basket Box | H19: Container / fruit | I19: Added: Petite: −1 × Gift Basket Box - Medium, Standard: −1 × Gift Basket Box - Medium, Deluxe: −1 × Gift Basket Box - Medium, Supersize: −1 × Gift Basket Box - Medium | Removed: - | Changed: 18.29→17.29 | 22.29→21.29 | 26.29→25.29 | 30.29→29.29 | J19: Joomla_import_5_containers_fruit_v1.xlsx | K19: Jarrod: list + upload (J4)
A20: Leave my questions, create in from your response, why did we lower to 8? I don't see why this should be lowered, this should remain 8 10 … and so on as jarrods file if not explain me the reason, (review the rules and the AUS maste) | B20: I did not lower it on purpose. Live and master have fruit 6 / 8 / 12 / 15 (Petite to Supersize); Jarrod's file has 8 / 10 / 12 / 15. My earlier label 'Alejandro lowered it to 8' was an assumption I could not verify; I withdraw it. Rule: Jarrod's recipe is the base (A-R1), so Joomla_import_5 sets Petite 8 and Standard 10 (Deluxe and Supersize already match). Please ask Jarrod why live shows 6 / 8. Est. ING price +$4.00 on Petite and Standard. | C20: FBAU76-60 | D20: Fruits & Chocolates | E20: Bouquets | F20: Flag Jarrod: container / quantity | G20: Jarrod file has both Small Basket and Gift Basket Box; fruit: live 6/8 vs Jarrod 8/10 (live/master differs from Jarrod) | H20: Container / fruit | I20: Added: Petite: −1 × Gift Basket Box - Medium, Standard: −1 × Gift Basket Box - Medium, Deluxe: −1 × Gift Basket Box - Medium, Supersize: −1 × Gift Basket Box - Medium | Removed: Petite: Fresh Fruit 6 → 8, Standard: Fresh Fruit 8 → 10 | Changed: 16.29→19.29 | 20.29→23.29 | 30.29→29.29 | 36.29→35.29 | J20: Joomla_import_5_containers_fruit_v1.xlsx | K20: Jarrod: list + upload (J4)
C21: AUMJ100-05 | D21: Gerbera Daisies in Mason Jar | E21: Mason Jar | F21: Flag Jarrod: empty recipe on a priced size | G21: Live export | H21: Empty recipe | I21: Petite is priced 39.95 but has no ingredient lines; the fix was not applied to this size | J21: Joomla_import_1_mason_jar_v1.xlsx | K21: Jarrod (you notify manually)
C22: AU0511-17 | D22: Summer Blooms | E22: Bouquets | F22: Recipe fix: notify Jarrod | G22: Master / live | H22: Gate Item not carried ($0) removed per rule I4 | I22: 2 x Lisianthus Orange: ING-1155 is $0 in the catalogue, so it is removed, not replaced | J22: Recipe rules | K22: Jarrod / Benny
C23: RBC-02C | D23: Bunches Purply Pink Collection III | E23: Bouquets | F23: Recipe fix: notify Jarrod | G23: Master / live | H23: Gate Item not carried ($0) removed per rule I4 | I23: 3 x Carnations Purple: ING-1516 is $0 in the catalogue, so it is removed, not replaced | J23: Recipe rules | K23: Jarrod / Benny
C24: RBC-02C | D24: Bunches Purply Pink Collection III | E24: Bouquets | F24: Recipe fix: notify Jarrod | G24: Master / live | H24: Gate Quantity differs from Jarrod | I24: Israeli ruscus is 2 in the master; Jarrod typed two lines of 2 (4) | J24: Recipe rules | K24: Jarrod / Benny
C25: AU-ADD-BUNDLE-PREM-WINE-CHOC-5495 | D25: Bundle: Premium Wine + Chocolates | E25: (outside the five buckets) | F25: Wine products: 18+ notice | G25: Ashraf gate file / your rule | H25: Wine in the live recipe | I25: Live status N. notice NOT in the current text. Legal wording first (as live), brand adaptation only after legal OK | J25: Joomla export 7 Oct
C26: AU-ADD-BUNDLE-SPARK-CELEB-6995 | D26: Bundle: Sparkling Wine + Chocolates + Card | E26: (outside the five buckets) | F26: Wine products: 18+ notice | G26: Ashraf gate file / your rule | H26: Wine in the live recipe | I26: Live status N. notice NOT in the current text. Legal wording first (as live), brand adaptation only after legal OK | J26: Joomla export 7 Oct
C27: AU-ADD-BUNDLE-WB-CHOC-5995 | D27: Bundle: Wolf Blass Wine + Chocolates | E27: (outside the five buckets) | F27: Wine products: 18+ notice | G27: Ashraf gate file / your rule | H27: Wine in the live recipe | I27: Live status N. notice NOT in the current text. Legal wording first (as live), brand adaptation only after legal OK | J27: Joomla export 7 Oct
C28: AU-ADD-PREM-RED-WINE-4495 | D28: Premium Red Wine | E28: (outside the five buckets) | F28: Wine products: 18+ notice | G28: Ashraf gate file / your rule | H28: Wine in the live recipe | I28: Live status N. notice NOT in the current text. Legal wording first (as live), brand adaptation only after legal OK | J28: Joomla export 7 Oct
C29: AU-ADD-PREM-WHITE-WINE-4495 | D29: Premium White Wine | E29: (outside the five buckets) | F29: Wine products: 18+ notice | G29: Ashraf gate file / your rule | H29: Wine in the live recipe | I29: Live status N. notice NOT in the current text. Legal wording first (as live), brand adaptation only after legal OK | J29: Joomla export 7 Oct
C30: AU-ADD-RED-WINE-6995 | D30: Red Wine | E30: (outside the five buckets) | F30: Wine products: 18+ notice | G30: Ashraf gate file / your rule | H30: Wine in the live recipe | I30: Live status N. notice NOT in the current text. Legal wording first (as live), brand adaptation only after legal OK | J30: Joomla export 7 Oct
C31: AU-ADD-SPARKLING-WINE-5495 | D31: Sparkling White Wine | E31: (outside the five buckets) | F31: Wine products: 18+ notice | G31: Ashraf gate file / your rule | H31: Wine in the live recipe | I31: Live status N. notice NOT in the current text. Legal wording first (as live), brand adaptation only after legal OK | J31: Joomla export 7 Oct
C32: AU-ADD-WB-WHITE-WINE-4495 | D32: Wolf Blass White Wine | E32: (outside the five buckets) | F32: Wine products: 18+ notice | G32: Ashraf gate file / your rule | H32: Wine in the live recipe | I32: Live status N. notice NOT in the current text. Legal wording first (as live), brand adaptation only after legal OK | J32: Joomla export 7 Oct
C33: AU-ADD-WHITE-WINE-4495 | D33: White Wine | E33: (outside the five buckets) | F33: Wine products: 18+ notice | G33: Ashraf gate file / your rule | H33: Wine in the live recipe | I33: Live status N. notice NOT in the current text. Legal wording first (as live), brand adaptation only after legal OK | J33: Joomla export 7 Oct
C34: AU110-04 | D34: Dozen Mixed Colour Roses, Vase, Card & Chocolates | E34: (outside the five buckets) | F34: Wine products: 18+ notice | G34: Ashraf gate file / your rule | H34: Wine in the live recipe | I34: Live status Y. notice NOT in the current text. Legal wording first (as live), brand adaptation only after legal OK | J34: Joomla export 7 Oct
C35: AU115-03R | D35: 3 Red Roses and Red Wine Combo | E35: (outside the five buckets) | F35: Wine products: 18+ notice | G35: Ashraf gate file / your rule | H35: Wine in the live recipe | I35: Live status Y. notice NOT in the current text. Legal wording first (as live), brand adaptation only after legal OK | J35: Joomla export 7 Oct
C36: AU115-03W | D36: 3 Red Roses and White Wine Combo | E36: (outside the five buckets) | F36: Wine products: 18+ notice | G36: Ashraf gate file / your rule | H36: Wine in the live recipe | I36: Live status Y. notice NOT in the current text. Legal wording first (as live), brand adaptation only after legal OK | J36: Joomla export 7 Oct
... C88: WBLD-WW-VW | D88: Lindt & Chardonnay Basket | E88: (outside the five buckets) | F88: Wine products: 18+ notice | G88: Ashraf gate file / your rule | H88: Wine in the live recipe | I88: Live status Y. notice NOT in the current text. Legal wording first (as live), brand adaptation only after legal OK | J88: Joomla export 7 Oct
C89: AU1111-04 | D89: 24 Pink and White Roses | E89: Bouquets | F89: Ashraf gate item | G89: Ashraf gate file | H89: Gate: Approved split | I89: Half light pink / half white approved; ingredient carried, price unchanged. Master Standard still shows 24 white until updated (resolved) | J89: Ashraf gate file | K89: Benny (Jarrod from about 12 Oct)
C90: AUFS-11 | D90: Dozen Red Roses, Wine & Truffles | E90: Roses | F90: Ashraf gate item | G90: Ashraf gate file | H90: Gate: Confirm Classic build | I90: Wine and truffles are in the master Standard; Jarrod Standard lists only roses, baby's breath and ruscus | J90: Ashraf gate file | K90: Benny (Jarrod from about 12 Oct)
C91: AU0511-17 | D91: Summer Blooms | E91: Bouquets | F91: Ashraf gate item | G91: Ashraf gate file | H91: Gate: Item not carried ($0) removed per rule I4 | I91: 2 x Lisianthus Orange: ING-1155 is $0 in the catalogue, so it is removed, not replaced | J91: Ashraf gate file | K91: Benny (Jarrod from about 12 Oct)
C92: RBC-02C | D92: Bunches Purply Pink Collection III | E92: Bouquets | F92: Ashraf gate item | G92: Ashraf gate file | H92: Gate: Item not carried ($0) removed per rule I4 | I92: 3 x Carnations Purple: ING-1516 is $0 in the catalogue, so it is removed, not replaced | J92: Ashraf gate file | K92: Benny (Jarrod from about 12 Oct)
...

Sheet Summary
A1: AU product descriptions v10: summary (counts are live formulas)
A3: A. Ashraf concerns and how each was handled | B3: SKUs | C3: How it was handled | D3: Where to check | E3: Questions alejandro | F3: Question 2 | G3: My response to column E | H3: My response to column F
A4: 1 Recipe accuracy (12 rows on the old hold list) | B4: =COUNTIF(log!$H$5:$H$989,"Gate: was on the hold list, now handled by rule") | C4: Nothing is held. Every old gate-hold row is now either fixed in a Joomla import file, listed under a Flag Jarrod class, or resolved by the live export (AU112-90, AUFS-11, AU111-41). | D4: log | E4: Yes fix the greenery following the caps, notify. Notify Jarrod, create a list of these products. | F4: From this document I should find, differences beetween the master sheet and the recipes loaded in Joomla. 2) I should see differences bettween the titles and the recipes (linguistic) Label and use colors for those problems (Use an additional label if the issue comes from Jarrod file or if it was there before). | G4: Yes, fixed in the Joomla files. The cap values have never been given (the Doc says so), so the additions are proposals by sibling pattern: Ruscus Israeli 1/1/2/2 on MJ100-17 and MJ100-07 (as MJ100-48), 2/3/3/4 on DC-02A and 2/2/3/3 on DC112-01A (as AUDC-01 and DC-03A). Joomla_import_1 (MJ100-17) and Joomla_import_2. Jarrod list: class Flag Jarrod: greenery. | H4: 1) Master vs Joomla: class 'Live differs from master' (9 SKUs). 2) Titles vs recipes: classes 'Flag Jarrod: ...' and 'Title vs recipe (linguistic)' (a flower named in the title that the recipe lacks). The 'Origin of the problem' column and its colour tell you whether it comes from Jarrod's file (orange), the master or live (blue), Ashraf's file (purple) or the Joomla export (green).
A5: 1b Mason jar missing (MJ100-17, MJ11-57, MJ102-53, AUMJ100-05) | B5: =COUNTIF(log!$F$5:$F$989,"Flag Jarrod: mason jar") | C5: Mason Jar x1 added to every size that has a recipe: Joomla_import_1. List = class Flag Jarrod: mason jar. | D5: log; Joomla_import_1 | E5: If the product says mason jar (verify that has it in the recipe) or at least a substitution. If not add it to the master, (and create a second joomla export with only the products with the fixies (meaning adding the 4 prodcuts that don't have a reciient in the list of ingredients (a document identically to export) | F5: Create a separated list with these 4 products | G5: Done: jar added in Joomla_import_1_mason_jar_v1 (MJ11-57, MJ102-53, AUMJ100-05, MJ100-17) in the identical export format. The Mason Jar (ING-1212, $0.50) is carried, so no substitution was needed. Jarrod's Standard has no jar on any of the four. | H5: List created: class 'Flag Jarrod: mason jar' (4 rows) in the log and in AU-Recipe-Fixes-v1-control.xlsx.
A6: 1c Title colours (AU1211-04, AU1111-04, AU219-40, AU199-07) | B6: =COUNTIF(log!$F$5:$F$989,"Flag Jarrod: colour (title says two, recipe has one)") | C6: Same-price swaps in Joomla_import_3 (AU199-07 is not a recipe problem: its green is the ruscus). | D6: log; Joomla_import_3 | E6: IF it's color,(first confirm if this wasn't fixed in the recipe by Jarrod) If not, fix it in the master, and create a list, usually we have the colors. Verify wit the list of ingerdients, if it has a substitution or the item is listed, then replace and if it has the same price) then create a separated product export for Joomla with only these products, and add them to other list as the past concernt. | F6: Verify prices, fix the master, create a product export with only those product for joomla, and create a list with this 4 products | G6: Checked first: Jarrod did not fix them (his Standard: AU1211-04 24 yellow, AU1111-04 24 white, AU219-40 no pink). Replacements are carried and same price: Roses Red = Roses Yellow ($1.30), Roses light pink = Roses White = Roses Yellow ($1.30), Mini Carnations Pink = Red ($0.95). AU1211-04 and AU1111-04 are split half and half in every size; AU219-40 swaps Roses Yellow for Roses light pink and Mini Carnations Red for Pink. Joomla_import_3_colours_v1 holds only these 3. AU199-07 is not a recipe problem (its green is 10 stems of ruscus, live N). | H6: Prices verified: the swaps are price-neutral, so the ING price does not move. Jar and greenery additions add cost: the Before-After tab of the control file shows the estimate per size (AU-Cost prices; Joomla recomputes on import). Retail prices are not changed. List of the colour products: class 'Flag Jarrod: colour'.
A7: 1d Title count (AU11-30 says 6, recipe 12) | B7: =COUNTIF(log!$F$5:$F$989,"Flag Jarrod: title count") | C7: Standard set to 6 in Joomla_import_4; Jarrod to be told (Petite is also 6). | D7: log; Joomla_import_4 | E7: Standar Must have 6 roses. Flagg, fix the recipe, notify jarrod, remind this and add it alon e in other list. | G7: Done: AU11-30 Standard set from 12 to 6 roses in Joomla_import_4_title_count_v1 (alone in its own file). Reminder for Jarrod: Petite is also 6, so Petite and Standard are now equal; Deluxe 18 and Supersize 24 are unchanged. It is in the Flag Jarrod: title count list.
A8: 1e Wine and truffles in AUFS-11 | B8: =COUNTIF(log!$H$5:$H$989,"Flag for Jarrod (confirm wine and truffles in the Classic build)") | C8: Live already has both: confirm label removed. 18+ notice kept. | D8: log, class Label removed | E8: Keep the 18+ notice on the four wine products (AU115-12, AUFS-10, AUFS-11 and AUFS-12). | F8: For all product descriptions with wine, (sabve this to the product description skill and update the artifact with instructions). Confirm if if we're having this artifact updated with all skills. Thisshould be updated in the artifact(https://claude.ai/artifact/14z2sKE33yXsoV5Z9EmYjH?sk=YMx0fnVdrPONIKfGPgpEJw#793324ab-7e56) and in the AUS master skill (that could use this artifact to function to read the ruless | G8: Kept: 18+ notice on AU115-12, AUFS-10, AUFS-11 and AUFS-12 in every brand text. | H8: Saved: the rule now covers every product whose recipe has wine (64 live products, list in the log, class Wine products: 18+ notice). Written into the MD (rule D3 and D3b), both skills and the Doc. To your question: I updated the rules artifact (4X1LU...) every round, but I had never edited the Claude Doc 'AU Pricing Rules' (14z2...) before this round; both are now updated from the same MD. AUFS-12's current text has no notice: it is in the wine list.
A9: 1f Blooms in the title vs stems in the recipe | B9: =COUNTIF(log!$H$5:$H$989,"C7 Title blooms vs stems") | C9: Intentional strategy (titles count blooms, recipes count stems): labels removed, rule C7 deleted. | D9: log | E9: Ignore this, we use blooms because it looks like more, and we deliver stems because is how we calculate. It's not a contradiction it's a strategy. | G9: Understood and applied: blooms-vs-stems labels removed and the C7 rule deleted. Rule C7 now reads: titles count blooms and recipes count stems on purpose, never flag it.
A10: 2 Missing vase or jar (AUSC-02/03/04, LF15-10C, AUSTRT-02/03) | B10: =COUNTIF(log!$H$5:$H$989,"Gate: Vase mention")+COUNTIF(log!$H$5:$H$989,"Gate: Jar mention") | C10: Master and live already have the line; every brand text names it. | D10: Products | E10: If master has the line (do I have to notify Jarrod) was this in jarrod's list? What's the difference with 1b mason jar missing. If they're the same add the mason jar (which is more polular and cheaper instead of a vase) The vase is best sold by separated | G10: Not the same as 1b. 1b = the recipe has no jar. Item 2 = the recipe already has the vase or the jar (red vase on AUSC-02/03/04 and LF15-10C, mason jar on AUSTRT-02/03) and only the text had to name it, so there is nothing to notify. They are in the live recipes. New rule C9: when a container is missing add the Mason Jar (cheaper and more popular); vases are sold separately as add-ons. I did not replace any existing vase.
A11: 3 Sending Solace moved to sympathy | B11: =COUNTIF(log!$H$5:$H$989,"Gate: moved to sympathy line") | C11: Sympathy tribute line / calm wording. | D11: Products | E11: OK
A12: 4 Brand voice (Bloomex AU texts inside 30-45 words) | B12: =COUNTIFS(Products!$N$2:$N$345,">=30",Products!$N$2:$N$345,"<=45") | C12: Voice codes V1-V19 now live in the MD (Part 4). Bunches and Stems lines rewritten. | D12: Products col N | E12: As the rest of the conditions caps and isntructions create a code for the instructions of brands voice, based iin Ashraf independent request, and the brand voice document creaetd before. | G12: Done: voice codes V1 to V19 in the MD (Part 4), built from the brand voice report and Ashraf's request (no delivery or price claims, numerals, 18+ wording rule). The skills load them from the MD.
A13: 5 All-white chrysanthemum designs | B13: =COUNTIF(log!$H$5:$H$989,"Gate: voice (all-white chrysanthemum)")+COUNTIF(log!$H$5:$H$989,"Voice: all-white chrysanthemum design") | C13: Neutral occasions used; Ashraf decides the two named rows. | D13: log
A14: 6 Designer wording / 'stemss' / native | B14: =COUNTIF(log!$H$5:$H$989,"Gate: designer wording applied") | C14: Stem count + florist's choice + illustrative picture. Greenery added to the 2 DC products that had none (Joomla_import_2); final DC recipes in the control file. | D14: Products; control file | E14: Remember me flag Jarod Include the greenery if possible using the cap and greenery instructions, (create a separated file to update joomla) and other Master for designer collections how the final recipe would look like (this view should have the SKU the product title and the recipe for each variant in different columns. Other tab with the recipe look like before and after the fixing for each variant same labeled (1 row per SKU) different columns (use different colors) | G14: Done: Greenery added to DC-02A and DC112-01A, the only two DC products without any (Joomla_import_2_greenery_v1). Control file AU-Recipe-Fixes-v1-control.xlsx: tab Final recipes = SKU, title and the final recipe per variant for all 36 DC products; tab Before-After = one row per SKU with BEFORE (red) and AFTER (green) columns per variant plus what was added, removed and changed. Flag Jarrod: greenery list is in both files.
A15: 7 18+ notice | B15: =COUNTIF(log!$F$5:$F$989,"Wine products: 18+ notice") | C15: Applies to every product with wine in the recipe (list = class Wine products: 18+ notice). Legal wording first. | D15: log | E15: The warning should either first follow legal instructions or 2) be adapted by each brand voice, create a separated list of these products. All lists that I requested should be in the master file with the instructions (What the artifact has) as updated as possible and its log. | G15: Legal wording first, verbatim as live: 'Disclaimer – Purchaser must be 18 years old or over to purchase this product. The recipient, by law, must be at least 18 years of age, with proof of age.' A brand-voice adaptation is only a proposal until legal agrees; proposals are in the MD (rule D3b). List of wine products: class 'Wine products: 18+ notice'.
A16: 8 Not on the live storefront | B16: =COUNTIF(Products!$D$2:$D$345,"CONFIRM STATUS") | C16: Only AU11-14 is live N on 7 Oct. | D16: log | E16: What happened with these products? Keep my questions in this file, repond in additional columns. | G16: AU11-14 is still live N in the 7 Oct export. AU100-71, AU112-56 and AU216-63 are live Y on 7 Oct, so I removed their label. I cannot see why they were reported missing on 6 Oct (re-activated in Joomla, or the storefront check differed from the Joomla status).
A17: 9 Identical copy on two pages | B17: =COUNTIF(log!$F$5:$F$989,"Copy: identical text") | C17: Phrasing variants; remaining pairs are listed. | D17: log | E17: Make a little bit more engagin and spiring the descriptionffor bucnhes and steams | G17: Done: Bunches and Stems closing lines rewritten to be warmer and more inspiring while staying dry and claim-free, e.g. 'Brings the colour in before anyone has said hello.' and 'Some things need no speech. Put these on the table and the message is delivered.'
E18: at the end I need independent list of products to flag jarrod (those that don't have mason jar, those that the recipe still include only one colorthogh the name says 2) etc, and thos that don't have greenery. (I will create the file with the fixes for these problems ) with independent files to upload in jooomla (that modifies only the products to update) equaliy formated. | G18: Delivered: independent Flag Jarrod lists (classes in the log and in the control file) and five Joomla import files, each only the products to update, format identical to the export (checked by round trip). Nothing overlaps, so uploading all five in any order is safe.
A20: B. Rules and conditions (full text in the MD, Part 1 to 5) | B20: SKUs | C20: Rule
A21: C1 One container per product | B21: =COUNTIF(log!$H$5:$H$989,"C1*")+COUNTIF(log!$F$5:$F$989,"Flag Jarrod: container / quantity") | C21: One container only; a Mason Jar title always gets the jar (added, Jarrod notified). Container list = Flag Jarrod: container.
A22: C2 Title count | B22: =COUNTIF(log!$H$5:$H$989,"title count") | C22: Standard follows the title count.
A23: C3 Title colours | B23: =COUNTIF(log!$H$5:$H$989,"colour*") | C23: Title colours must exist in the recipe; same-price swaps; half and half for X and Y roses.
A24: C5 Not carried ($0) | B24: =COUNTIF(log!$H$5:$H$989,"Gate: Item not carried*") | C24: Removed, never replaced (I4).
A25: C7 Blooms vs stems | B25: =COUNTIF(log!$H$5:$H$989,"C7*") | C25: Strategy, never flagged (labels removed).
A26: C9 Container to add | B26: =COUNTIF(log!$H$5:$H$989,"mason jar") | C26: Add the Mason Jar, not a vase.
A27: D1 Descriptions skip greenery and secondary flowers | B27: =COUNTA(Products!$A$2:$A$345) | C27: Exercise only.
A28: D3 18+ notice (every wine recipe) | B28: =COUNTIF(log!$F$5:$F$989,"Wine products: 18+ notice") | C28: Legal wording first; brand adaptation only after legal.
A29: J1 Joomla import files | B29: =5 | C29: Only changed products, identical format, one product per file, retail price unchanged.
A30: L1 Live check | B30: =COUNTIF(log!$F$5:$F$989,"Label removed*") | C30: Labels contradicted by live are removed, never added.
A31: PV1-PV6 Pricing verification | B31: =COUNTIF(log!$F$5:$F$989,"Rule added*") | C31: From your pasted rules: $0 in AU-Cost master, ingredient mismatch, bigger size fewer items, smaller size higher or same price, not checked, scope.
A33: C. Counts
A34: SKUs reviewed | B34: =COUNTA(Products!$A$2:$A$345)
A35: READY TO REVIEW | B35: =COUNTIF(Products!$D$2:$D$345,"READY TO REVIEW")
A36: READY - NOTIFY JARROD | B36: =COUNTIF(Products!$D$2:$D$345,"READY - NOTIFY JARROD")
A37: ADJUSTED - CONFIRM | B37: =COUNTIF(Products!$D$2:$D$345,"ADJUSTED - CONFIRM")
A38: CONFIRM STATUS | B38: =COUNTIF(Products!$D$2:$D$345,"CONFIRM STATUS")
A39: DECISION NEEDED | B39: =COUNTIF(Products!$D$2:$D$345,"DECISION NEEDED")
A41: Descriptions generated / auto-check ok
A42: Bloomex AU | B42: =COUNTIF(Products!$M$2:$M$345,"?*")-COUNTIF(Products!$M$2:$M$345,"n/a*") | C42: =COUNTIF(Products!$P$2:$P$345,"ok")&" ok"
A43: Aussie Blooms | B43: =COUNTIF(Products!$Q$2:$Q$345,"?*")-COUNTIF(Products!$Q$2:$Q$345,"n/a*") | C43: =COUNTIF(Products!$S$2:$S$345,"ok")&" ok"
A44: Bunches and Stems | B44: =COUNTIF(Products!$T$2:$T$345,"?*")-COUNTIF(Products!$T$2:$T$345,"n/a*") | C44: =COUNTIF(Products!$V$2:$V$345,"ok")&" ok"
...

Sheet Products
A1: SKU | B1: Product title | C1: Bucket | D1: Upload status | E1: Current BLX description (Joomla 7 Oct if present, else Shopify 28 Sep) | F1: Current text source | G1: Jarrod recipe (Standard) | H1: Reviewed recipe (master + rules) | I1: Suggested final recipe (after the fixes) | J1: Live recipe (Joomla 7 Oct, Standard) | K1: Live status | L1: Needs before upload | M1: Bloomex AU: suggested text | N1: Bloomex AU: words | O1: Bloomex AU: HTML | P1: Bloomex AU: QA | Q1: Aussie Blooms: suggested text | R1: Aussie Blooms: HTML | S1: Aussie Blooms: QA | T1: Bunches and Stems: suggested text | U1: Bunches and Stems: HTML | V1: Bunches and Stems: QA | W1: Mel's: title (Product Master) | X1: Mel's: suggested text | Y1: Mel's: HTML | Z1: Mel's: QA | AA1: Global sales rank (flowers) | AB1: Net sales YTD 2026 (AUD) | AC1: Net items sold YTD | AD1: % of total flower revenue | AE1: % of category revenue | AF1: Rank within category
A2: MJ100-37 | B2: Pink Wink in Mason Jar | C2: Mason Jar | D2: READY TO REVIEW | F2: none | G2: 2 × Roses Pink; 2 × Carnation Pink; 3 × Alstroemeria Pink; 2 × Ruscus Israeli; 1 × Mason Jar; 2 × Statice Pink Pink; 2 × Mini Carnations Pink | H2: 2 × Roses Pink; 2 × Carnation Pink; 3 × Alstroemeria Pink; 2 × Ruscus Israeli; 1 × Mason Jar; 2 × Statice Pink; 2 × Mini Carnations Pink | I2: 2 × Roses Pink; 2 × Carnation Pink; 3 × Alstroemeria Pink; 2 × Ruscus Israeli; 1 × Mason Jar; 2 × Statice Pink; 2 × Mini Carnations Pink | J2: 2 × Ruscus Israeli; 2 × Mini Carnations Pink; 2 × Statice Pink; 1 × Mason Jar; 3 × Alstroemeria Pink; 2 × Carnation Pink; 2 × Roses Pink | K2: N | M2: A hand-arranged mason jar bouquet of 3 pink alstroemeria, 2 pink carnations and 2 pink roses. A warm gift for a birthday, a thank-you or a just-because moment, with a mason jar to keep once the flowers are gone. | N2: =LEN(TRIM(SUBSTITUTE(M2,CHAR(10)," ")))-LEN(SUBSTITUTE(TRIM(SUBSTITUTE(M2,CHAR(10)," "))," ",""))+1 | O2: <p>A hand-arranged mason jar bouquet of 3 pink alstroemeria, 2 pink carnations and 2 pink roses. A warm gift for a birthday, a thank-you or a just-because moment, with a mason jar to keep once the flowers are gone.</p> | P2: ok | Q2: Pink Wink in Mason Jar brings together 3 pink alstroemeria, 2 pink carnations and 2 pink roses, presented in a mason jar you can keep. It suits a birthday, a thank-you or a just-because moment. Pink tones say affection. We hand-arrange each one at Aussie Blooms so it looks the way you pictured it, ready for a Sunday lunch. Stems can vary with the season, while the pink palette stays. | R2: <p>Pink Wink in Mason Jar brings together 3 pink alstroemeria, 2 pink carnations and 2 pink roses, presented in a mason jar you can keep. It suits a birthday, a thank-you or a just-because moment.</p><p>Pink tones say affection. We hand-arrange each one at Aussie Blooms so it looks the way you pictured it, ready for a Sunday lunch. Stems can vary with the season, while the pink palette stays.</p> | S2: ok | T2: Inside the jar: 3 pink alstroemeria, 2 pink carnations and 2 pink roses. Calm colour for the kind of day that deserves a pause. | U2: <p>Inside the jar: 3 pink alstroemeria, 2 pink carnations and 2 pink roses. Calm colour for the kind of day that deserves a pause.</p> | V2: ok | W2: Rosy Rumour | X2: Rosy Rumour settles 3 pink alstroemeria, 2 pink carnations and 2 pink roses into a relaxed mason jar. Just right sitting on a bench where everyone can enjoy it. A good fit for a birthday, a thank-you or a just-because moment. | Y2: <p>Rosy Rumour settles 3 pink alstroemeria, 2 pink carnations and 2 pink roses into a relaxed mason jar. Just right sitting on a bench where everyone can enjoy it. A good fit for a birthday, a thank-you or a just-because moment.</p> | Z2: ok | AA2: no sales | AB2: 0 | AC2: 0 | AD2: 0 | AE2: 0 | AF2: no sales
A3: MJ22-10 | B3: Shades of Pink in Mason Jar | C3: Mason Jar | D3: READY TO REVIEW | E3: Eleven gerberas, ten alstroemeria and nine chrysanthemums in pretty shades of pink, nestled in a country-style mason jar. Fresh, feminine and full of charm, it's a lovely way to mark a birthday, celebrate good news or welcome someone to a new home. | F3: Shopify (28 Sep) | G3: 3 × Chrysanthemum Daisies Lavender; 3 × Gerbera Daisies Pink; 2 × Ruscus Israeli; 1 × Mason Jar; 3 × Alstroemeria Pink | H3: 3 × Chrysanthemum Daisies Lavender; 3 × Gerbera Daisies Pink; 2 × Ruscus Israeli; 1 × Mason Jar; 3 × Alstroemeria Pink | I3: 3 × Chrysanthemum Daisies Lavender; 3 × Gerbera Daisies Pink; 2 × Ruscus Israeli; 1 × Mason Jar; 3 × Alstroemeria Pink | J3: 2 × Ruscus Israeli; 3 × Alstroemeria Pink; 1 × Mason Jar; 3 × Gerbera Daisies Pink; 3 × Chrysanthemum Daisies Lavender | K3: Y | M3: A hand-arranged mason jar bouquet of 3 lavender chrysanthemum daisies, 3 pink alstroemeria and 3 pink gerberas. A lovely way to mark a birthday, a thank-you or a just-because moment, with a mason jar to keep once the flowers are gone. | N3: =LEN(TRIM(SUBSTITUTE(M3,CHAR(10)," ")))-LEN(SUBSTITUTE(TRIM(SUBSTITUTE(M3,CHAR(10)," "))," ",""))+1 | O3: <p>A hand-arranged mason jar bouquet of 3 lavender chrysanthemum daisies, 3 pink alstroemeria and 3 pink gerberas. A lovely way to mark a birthday, a thank-you or a just-because moment, with a mason jar to keep once the flowers are gone.</p> | P3: ok | Q3: Shades of Pink in Mason Jar brings together 3 lavender chrysanthemum daisies, 3 pink alstroemeria and 3 pink gerberas, presented in a mason jar you can keep. It suits a birthday, a thank-you or a just-because moment. Pink tones say affection. We hand-arrange each one at Aussie Blooms so it looks the way you pictured it, ready for a Sunday lunch. Stems can vary with the season, while the pink and lavender palette stays. | R3: <p>Shades of Pink in Mason Jar brings together 3 lavender chrysanthemum daisies, 3 pink alstroemeria and 3 pink gerberas, presented in a mason jar you can keep. It suits a birthday, a thank-you or a just-because moment.</p><p>Pink tones say affection. We hand-arrange each one at Aussie Blooms so it looks the way you pictured it, ready for a Sunday lunch. Stems can vary with the season, while the pink and lavender palette stays.</p> | S3: ok | T3: In the jar: 3 lavender chrysanthemum daisies, 3 pink alstroemeria and 3 pink gerberas. Soft colours that make a quiet room feel looked after. | U3: <p>In the jar: 3 lavender chrysanthemum daisies, 3 pink alstroemeria and 3 pink gerberas. Soft colours that make a quiet room feel looked after.</p> | V3: ok | W3: All the Pinks | X3: All the Pinks settles 3 lavender chrysanthemum daisies, 3 pink alstroemeria and 3 pink gerberas into a relaxed mason jar. Just right sitting on a bench where everyone can enjoy it. A good fit for a birthday, a thank-you or a just-because moment. A little wild, a little imperfect, the way a jar should be. | Y3: <p>All the Pinks settles 3 lavender chrysanthemum daisies, 3 pink alstroemeria and 3 pink gerberas into a relaxed mason jar. Just right sitting on a bench where everyone can enjoy it. A good fit for a birthday, a thank-you or a just-because moment. A little wild, a little imperfect, the way a jar should be.</p> | Z3: ok | AA3: 105 | AB3: 13672.72 | AC3: 192 | AD3: 0.0015665785 | AE3: 0.0039474106 | AF3: 34
A4: MJ79-16 | B4: Shades of Spring in Mason Jar | C4: Mason Jar | D4: READY TO REVIEW | F4: none | G4: 2 × Roses Spray Hot Pink; 2 × Chrysanthemum Daisies Lavender; 1 × Carnation Yellow; 2 × Ruscus Israeli; 1 × Mason Jar; 2 × Alstroemeria Yellow | H4: 2 × Roses Spray Hot Pink; 2 × Chrysanthemum Daisies Lavender; 1 × Carnation Yellow; 2 × Ruscus Israeli; 1 × Mason Jar; 2 × Alstroemeria Yellow | I4: 2 × Roses Spray Hot Pink; 2 × Chrysanthemum Daisies Lavender; 1 × Carnation Yellow; 2 × Ruscus Israeli; 1 × Mason Jar; 2 × Alstroemeria Yellow | J4: 1 × Carnation Yellow; 2 × Alstroemeria Yellow; 1 × Mason Jar; 2 × Ruscus Israeli; 2 × Chrysanthemum Daisies Lavender; 2 × Roses Spray Hot Pink | K4: N | M4: A mason jar arrangement of 2 hot pink spray roses, 2 lavender chrysanthemum daisies, 2 yellow alstroemeria and 1 yellow carnation. A thoughtful choice for a birthday, a thank-you or a just-because moment, and the mason jar stays useful long after. | N4: =LEN(TRIM(SUBSTITUTE(M4,CHAR(10)," ")))-LEN(SUBSTITUTE(TRIM(SUBSTITUTE(M4,CHAR(10)," "))," ",""))+1 | O4: <p>A mason jar arrangement of 2 hot pink spray roses, 2 lavender chrysanthemum daisies, 2 yellow alstroemeria and 1 yellow carnation. A thoughtful choice for a birthday, a thank-you or a just-because moment, and the mason jar stays useful long after.</p> | P4: ok | Q4: Shades of Spring in Mason Jar brings together 2 hot pink spray roses, 2 lavender chrysanthemum daisies, 2 yellow alstroemeria and 1 yellow carnation, presented in a mason jar you can keep. It suits a birthday, a thank-you or a just-because moment. Yellow tones say friendship and cheer. We hand-arrange each one at Aussie Blooms so it looks the way you pictured it, ready for the kitchen bench. Stems can vary with the season, while the yellow and hot pink palette stays. | R4: <p>Shades of Spring in Mason Jar brings together 2 hot pink spray roses, 2 lavender chrysanthemum daisies, 2 yellow alstroemeria and 1 yellow carnation, presented in a mason jar you can keep. It suits a birthday, a thank-you or a just-because moment.</p><p>Yellow tones say friendship and cheer. We hand-arrange each one at Aussie Blooms so it looks the way you pictured it, ready for the kitchen bench. Stems can vary with the season, while the yellow and hot pink palette stays.</p> | S4: ok | T4: The jar holds: 2 hot pink spray roses, 2 lavender chrysanthemum daisies, 2 yellow alstroemeria and 1 yellow carnation. Enough colour to turn an ordinary bench into the best spot in the house. | U4: <p>The jar holds: 2 hot pink spray roses, 2 lavender chrysanthemum daisies, 2 yellow alstroemeria and 1 yellow carnation. Enough colour to turn an ordinary bench into the best spot in the house.</p> | V4: ok | W4: September Garden | X4: September Garden gathers 2 hot pink spray roses, 2 lavender chrysanthemum daisies, 2 yellow alstroemeria and 1 yellow carnation into a relaxed mason jar. Right at home on a kitchen bench next to the morning cuppa. Made for a birthday, a thank-you or a just-because moment. A little wild, a little imperfect, the way a jar should be. | Y4: <p>September Garden gathers 2 hot pink spray roses, 2 lavender chrysanthemum daisies, 2 yellow alstroemeria and 1 yellow carnation into a relaxed mason jar. Right at home on a kitchen bench next to the morning cuppa. Made for a birthday, a thank-you or a just-because moment. A little wild, a little imperfect, the way a jar should be.</p> | Z4: ok | AA4: no sales | AB4: 0 | AC4: 0 | AD4: 0 | AE4: 0 | AF4: no sales
A5: MJ11-30 | B5: Sweetheart Roses in Mason Jar | C5: Mason Jar | D5: READY TO REVIEW | E5: Twenty-seven romantic roses gathered in a charming mason jar, blending rustic warmth with timeless beauty. A sweetheart gesture for an anniversary, birthday or a heartfelt just-because moment that says you care. | F5: Shopify (28 Sep) | G5: 6 × Roses Red; 1 × Baby's Breath; 2 × Ruscus Israeli; 1 × Mason Jar | H5: 6 × Roses Red; 1 × Baby's Breath; 2 × Ruscus Israeli; 1 × Mason Jar | I5: 6 × Roses Red; 1 × Baby's Breath; 2 × Ruscus Israeli; 1 × Mason Jar | J5: 2 × Ruscus Israeli; 1 × Mason Jar; 1 × Baby's Breath; 6 × Roses Red | K5: Y | M5: A mason jar arrangement of 6 red roses. A lovely way to mark an anniversary or a thank-you, and a bright moment when the door opens. | N5: =LEN(TRIM(SUBSTITUTE(M5,CHAR(10)," ")))-LEN(SUBSTITUTE(TRIM(SUBSTITUTE(M5,CHAR(10)," "))," ",""))+1 | O5: <p>A mason jar arrangement of 6 red roses. A lovely way to mark an anniversary or a thank-you, and a bright moment when the door opens.</p> | P5: ok | Q5: Sweetheart Roses in Mason Jar brings together 6 red roses, presented in a mason jar you can keep. It suits an anniversary or a thank-you. Red tones say love and devotion. We hand-arrange each one at Aussie Blooms so it looks the way you pictured it, ready for the kitchen bench. Stems can vary with the season, while the red palette stays. | R5: <p>Sweetheart Roses in Mason Jar brings together 6 red roses, presented in a mason jar you can keep. It suits an anniversary or a thank-you.</p><p>Red tones say love and devotion. We hand-arrange each one at Aussie Blooms so it looks the way you pictured it, ready for the kitchen bench. Stems can vary with the season, while the red palette stays.</p> | S5: ok | T5: The jar holds: 6 red roses. The classic, handed over without a single word of explanation. | U5: <p>The jar holds: 6 red roses. The classic, handed over without a single word of explanation.</p> | V5: ok | W5: Garden Romance | X5: Garden Romance gathers 6 red roses into a relaxed mason jar. Right at home on a kitchen bench next to the morning cuppa. Made for an anniversary or a thank-you. A little wild, a little imperfect, the way a jar should be. | Y5: <p>Garden Romance gathers 6 red roses into a relaxed mason jar. Right at home on a kitchen bench next to the morning cuppa. Made for an anniversary or a thank-you. A little wild, a little imperfect, the way a jar should be.</p> | Z5: ok | AA5: 165 | AB5: 4658.91 | AC5: 69 | AD5: 0.00053380376 | AE5: 0.0013450603 | AF5: 47
A6: MJ100-04 | B6: What a Treat in Mason Jar | C6: Mason Jar | D6: READY TO REVIEW | E6: A delightful mix of 7 roses, 6 chrysanthemums and 5 alstroemeria arranged in a rustic mason jar. A small but joyful treat to brighten a birthday, celebrate a win or send cheerful get-well wishes. | F6: Shopify (28 Sep) | G6: 2 × Roses Pink; 3 × Chrysanthemum Daisies White; 1 × Baby's Breath; 1 × Ruscus Israeli; 1 × Mason Jar; 2 × Alstroemeria Pink | H6: 2 × Roses Pink; 3 × Chrysanthemum Daisies White; 1 × Baby's Breath; 1 × Ruscus Israeli; 1 × Mason Jar; 2 × Alstroemeria Pink | I6: 2 × Roses Pink; 3 × Chrysanthemum Daisies White; 1 × Baby's Breath; 1 × Ruscus Israeli; 1 × Mason Jar; 2 × Alstroemeria Pink | J6: 1 × Baby's Breath; 2 × Alstroemeria Pink; 1 × Mason Jar; 1 × Ruscus Israeli; 3 × Chrysanthemum Daisies White; 2 × Roses Pink | K6: Y | M6: A mason jar arrangement of 3 white chrysanthemum daisies, 2 pink alstroemeria and 2 pink roses. A warm gift for a birthday, a thank-you or a just-because moment, and the mason jar stays useful long after. | N6: =LEN(TRIM(SUBSTITUTE(M6,CHAR(10)," ")))-LEN(SUBSTITUTE(TRIM(SUBSTITUTE(M6,CHAR(10)," "))," ",""))+1 | O6: <p>A mason jar arrangement of 3 white chrysanthemum daisies, 2 pink alstroemeria and 2 pink roses. A warm gift for a birthday, a thank-you or a just-because moment, and the mason jar stays useful long after.</p> | P6: ok | Q6: What a Treat in Mason Jar brings together 3 white chrysanthemum daisies, 2 pink alstroemeria and 2 pink roses, presented in a mason jar you can keep. It suits a birthday, a thank-you or a just-because moment. Pink tones say affection. We hand-arrange each one at Aussie Blooms so it looks the way you pictured it, ready for the bedside table. Stems can vary with the season, while the pink and white palette stays. | R6: <p>What a Treat in Mason Jar brings together 3 white chrysanthemum daisies, 2 pink alstroemeria and 2 pink roses, presented in a mason jar you can keep. It suits a birthday, a thank-you or a just-because moment.</p><p>Pink tones say affection. We hand-arrange each one at Aussie Blooms so it looks the way you pictured it, ready for the bedside table. Stems can vary with the season, while the pink and white palette stays.</p> | S6: ok | T6: Inside the jar: 3 white chrysanthemum daisies, 2 pink alstroemeria and 2 pink roses. Calm colour for the kind of day that deserves a pause. | U6: <p>Inside the jar: 3 white chrysanthemum daisies, 2 pink alstroemeria and 2 pink roses. Calm colour for the kind of day that deserves a pause.</p> | V6: ok | W6: Mel's Best Pick | X6: Mel's Best Pick nestles 3 white chrysanthemum daisies, 2 pink alstroemeria and 2 pink roses into a relaxed mason jar. Happy on a sunny windowsill. Made for a birthday, a thank-you or a just-because moment. A little wild, a little imperfect, the way a jar should be. | Y6: <p>Mel's Best Pick nestles 3 white chrysanthemum daisies, 2 pink alstroemeria and 2 pink roses into a relaxed mason jar. Happy on a sunny windowsill. Made for a birthday, a thank-you or a just-because moment. A little wild, a little imperfect, the way a jar should be.</p> | Z6: ok | AA6: 5 | AB6: 279924.76 | AC6: 5211 | AD6: 0.032072928 | AE6: 0.080816261 | AF6: 4
A7: MJ-01 | B7: Summer Breeze in Mason Jar | C7: Mason Jar | D7: READY TO REVIEW | F7: none | G7: 2 × Chrysanthemum Button Green; 2 × Chrysanthemum Daisies Lavender; 2 × Ruscus Israeli; 1 × Mason Jar; 3 × Carnation Yellow; 3 × Alstroemeria Red | H7: 2 × Chrysanthemum Button Green; 2 × Chrysanthemum Daisies Lavender; 2 × Ruscus Israeli; 1 × Mason Jar; 3 × Carnation Yellow; 3 × Alstroemeria Red | I7: 2 × Chrysanthemum Button Green; 2 × Chrysanthemum Daisies Lavender; 2 × Ruscus Israeli; 1 × Mason Jar; 3 × Carnation Yellow; 3 × Alstroemeria Red | J7: 2 × Ruscus Israeli; 3 × Alstroemeria Red; 3 × Carnation Yellow; 1 × Mason Jar; 2 × Chrysanthemum Daisies Lavender; 2 × Chrysanthemum Button Green | K7: N | M7: A hand-arranged mason jar bouquet of 3 red alstroemeria, 3 yellow carnations and 2 lavender chrysanthemum daisies. A thoughtful choice for a birthday, a thank-you or a just-because moment, with a mason jar to keep once the flowers are gone. | N7: =LEN(TRIM(SUBSTITUTE(M7,CHAR(10)," ")))-LEN(SUBSTITUTE(TRIM(SUBSTITUTE(M7,CHAR(10)," "))," ",""))+1 | O7: <p>A hand-arranged mason jar bouquet of 3 red alstroemeria, 3 yellow carnations and 2 lavender chrysanthemum daisies. A thoughtful choice for a birthday, a thank-you or a just-because moment, with a mason jar to keep once the flowers are gone.</p> | P7: ok | Q7: Summer Breeze in Mason Jar brings together 3 red alstroemeria, 3 yellow carnations and 2 lavender chrysanthemum daisies, presented in a mason jar you can keep. It suits a birthday, a thank-you or a just-because moment. Red tones say love and devotion. We hand-arrange each one at Aussie Blooms so it looks the way you pictured it, ready for a summer table. Stems can vary with the season, while the red and yellow palette stays. | R7: <p>Summer Breeze in Mason Jar brings together 3 red alstroemeria, 3 yellow carnations and 2 lavender chrysanthemum daisies, presented in a mason jar you can keep. It suits a birthday, a thank-you or a just-because moment.</p><p>Red tones say love and devotion. We hand-arrange each one at Aussie Blooms so it looks the way you pictured it, ready for a summer table. Stems can vary with the season, while the red and yellow palette stays.</p> | S7: ok | T7: The jar holds: 3 red alstroemeria, 3 yellow carnations and 2 lavender chrysanthemum daisies. Enough colour to turn an ordinary bench into the best spot in the house. | U7: <p>The jar holds: 3 red alstroemeria, 3 yellow carnations and 2 lavender chrysanthemum daisies. Enough colour to turn an ordinary bench into the best spot in the house.</p> | V7: ok | W7: Long Weekend | X7: Long Weekend tucks 3 red alstroemeria, 3 yellow carnations and 2 lavender chrysanthemum daisies into a relaxed mason jar. Lovely on a bedside table, or anywhere it can be seen. A good fit for a birthday, a thank-you or a just-because moment. A little wild, a little imperfect, the way a jar should be. | Y7: <p>Long Weekend tucks 3 red alstroemeria, 3 yellow carnations and 2 lavender chrysanthemum daisies into a relaxed mason jar. Lovely on a bedside table, or anywhere it can be seen. A good fit for a birthday, a thank-you or a just-because moment. A little wild, a little imperfect, the way a jar should be.</p> | Z7: ok | AA7: no sales | AB7: 0 | AC7: 0 | AD7: 0 | AE7: 0 | AF7: no sales
A8: MJ100-24 | B8: Assorted Roses in Mason Jar | C8: Mason Jar | D8: READY TO REVIEW | E8: Fourteen assorted roses gathered in a charming mason jar, blending romance with rustic, timeless appeal. A versatile and heartfelt arrangement that brings warmth and beauty to any room, and a lovely way to brighten someone's day just because. | F8: Shopify (28 Sep) | G8: 5 × Roses Assorted; 1 × Baby's Breath; 1 × Ruscus Israeli; 1 × Mason Jar | H8: 5 × Roses Assorted; 1 × Baby's Breath; 1 × Ruscus Israeli; 1 × Mason Jar | I8: 5 × Roses Assorted; 1 × Baby's Breath; 1 × Ruscus Israeli; 1 × Mason Jar | J8: 1 × Ruscus Israeli; 1 × Mason Jar; 1 × Baby's Breath; 5 × Roses Assorted | K8: Y | M8: A mason jar arrangement of 5 assorted-colour roses. A lovely way to mark a birthday, a thank-you or a just-because moment, and the mason jar stays useful long after. | N8: =LEN(TRIM(SUBSTITUTE(M8,CHAR(10)," ")))-LEN(SUBSTITUTE(TRIM(SUBSTITUTE(M8,CHAR(10)," "))," ",""))+1 | O8: <p>A mason jar arrangement of 5 assorted-colour roses. A lovely way to mark a birthday, a thank-you or a just-because moment, and the mason jar stays useful long after.</p> | P8: ok | Q8: Assorted Roses in Mason Jar brings together 5 assorted-colour roses, presented in a mason jar you can keep. It suits a birthday, a thank-you or a just-because moment. Mixed colours say thoughtfulness. We hand-arrange each one at Aussie Blooms so it looks the way you pictured it, ready for the kitchen bench. Stems can vary with the season, while the colourful palette stays. | R8: <p>Assorted Roses in Mason Jar brings together 5 assorted-colour roses, presented in a mason jar you can keep. It suits a birthday, a thank-you or a just-because moment.</p><p>Mixed colours say thoughtfulness. We hand-arrange each one at Aussie Blooms so it looks the way you pictured it, ready for the kitchen bench. Stems can vary with the season, while the colourful palette stays.</p> | S8: ok | T8: In the jar: 5 assorted-colour roses. Hand it over and watch the day get a little better. | U8: <p>In the jar: 5 assorted-colour roses. Hand it over and watch the day get a little better.</p> | V8: ok | W8: Mixed Callas | X8: Mixed Callas gathers 5 assorted-colour roses into a relaxed mason jar. Right at home on a kitchen bench next to the morning cuppa. Made for a birthday, a thank-you or a just-because moment. | Y8: <p>Mixed Callas gathers 5 assorted-colour roses into a relaxed mason jar. Right at home on a kitchen bench next to the morning cuppa. Made for a birthday, a thank-you or a just-because moment.</p> | Z8: ok | AA8: 150 | AB8: 6301.98 | AC8: 141 | AD8: 0.00072206207 | AE8: 0.0018194272 | AF8: 41
