Workbook

Sheet Dashboard
A1: Designer Collection - Refund Report (add-ons excluded)
A2: 94 SKUs | 4 stores | Jan - 9 Oct 2026 | ranked by units, revenue impact and refund rate on own sales
B4: Designer gross sales | D4: Designer refund $ | F4: % of ALL company refunds | H4: Refund rate since Aug | J4: vs rest of catalog | L4: SKUs flagged HIGH RATE
B5: =Settings!$B$17 -> 1654508.3 | D5: =Settings!$B$18 -> 59422.49 | F5: =Settings!$B$19 -> 0.056859629 | H5: =Settings!$B$21/Settings!$B$22 -> 0.066493506 | J5: =(Settings!$B$21/Settings!$B$22)/Settings!$B$14 -> 0.88758967 | L5: =COUNTIF('SKU Data'!$Y$2:$Y$95,"HIGH RATE") -> 1
A8: Key findings (at export date)
A9: 1. Designer = 12.8% of company gross but only 5.7% of company refund $ ($59,422 of $1,045,073) - yet 52% of all refunds have no SKU and cannot be assigned, so this is a floor (pro-rata illustration: +~$69,722). Since Aug the Designer refund rate is 6.6% vs 7.5% for the rest of the catalog (0.89x): not worse overall.
A10: 2. Where the dollars are: Sympathy = 44% of Designer refund $ at a 5.9% rate (below the 6.6% average): a volume story. #1 SKU: DC-04S (Designer Sympathy Collection IV) $8,683. Highest-rate sizeable lines: Anniversary 8.7%, Birthday 8.2%.
A11: 3. TIME: the Designer rate rose 4.9% (Aug) -> 7.5% (Sep) -> 9.2% (Oct, partial) while the rest of the catalog went 6.5% -> 8.5% -> 7.7%. Jan-Jul are understated (refunds not yet on SKUs), so no earlier comparison.
A12: 4. Stores (window rate vs 6.6% avg): Mel's Flowers 10.2%, Bunches and Stems 8.4%, Bloomex 6.8%, Aussie Blooms 4.1%. 1 SKU(s) are statistically above the designer average: DCA-02-00.
A13: 5. Excluded: add-ons (none of the Designer SKUs is one). Add-ons sold with Designer bouquets cannot be linked (no order id in the export), so their refunds are not in these numbers.
A15: Top 10 priority Designer SKUs (full list: Priority SKUs tab)
A16: Rank | B16: SKU | C16: Product | D16: Line | E16: Units ordered (window) | F16: Refunded units (window) | G16: Refund rate (window) | H16: Refund $ (all months) | I16: % of total company revenue | J16: Tier | K16: Main store
A17: ='Priority SKUs'!A5 -> 1 | B17: ='Priority SKUs'!C5 -> DC-02B | C17: ='Priority SKUs'!D5 -> Birthday Designer Collection II | D17: ='Priority SKUs'!E5 -> Birthday | E17: ='Priority SKUs'!F5 -> 223 | F17: ='Priority SKUs'!H5 -> 25 | G17: ='Priority SKUs'!I5 -> 0.11210762 | H17: ='Priority SKUs'!J5 -> 2889.28 | I17: ='Priority SKUs'!L5 -> 0.00022430113 | J17: ='Priority SKUs'!B5 -> 1 - Fix first | K17: =IFERROR(INDEX('SKU Data'!$D$2:$D$95,MATCH(B17,'SKU Data'!$A$2:$A$95,0)),"") -> Bloomex - AUS
A18: ='Priority SKUs'!A6 -> 2 | B18: ='Priority SKUs'!C6 -> DC-02S | C18: ='Priority SKUs'!D6 -> Designer Sympathy Collection II | D18: ='Priority SKUs'!E6 -> Sympathy | E18: ='Priority SKUs'!F6 -> 849 | F18: ='Priority SKUs'!H6 -> 59 | G18: ='Priority SKUs'!I6 -> 0.069493522 | H18: ='Priority SKUs'!J6 -> 6122.41 | I18: ='Priority SKUs'!L6 -> 0.00047529608 | J18: ='Priority SKUs'!B6 -> 1 - Fix first | K18: =IFERROR(INDEX('SKU Data'!$D$2:$D$95,MATCH(B18,'SKU Data'!$A$2:$A$95,0)),"") -> Bloomex - AUS
A19: ='Priority SKUs'!A7 -> 3 | B19: ='Priority SKUs'!C7 -> AUDNAT-02 | C19: ='Priority SKUs'!D7 -> Native Flowers Bouquet Designer Collection II | D19: ='Priority SKUs'!E7 -> Native Flowers | E19: ='Priority SKUs'!F7 -> 802 | F19: ='Priority SKUs'!H7 -> 55 | G19: ='Priority SKUs'!I7 -> 0.068578554 | H19: ='Priority SKUs'!J7 -> 6090.57 | I19: ='Priority SKUs'!L7 -> 0.00047282428 | J19: ='Priority SKUs'!B7 -> 1 - Fix first | K19: =IFERROR(INDEX('SKU Data'!$D$2:$D$95,MATCH(B19,'SKU Data'!$A$2:$A$95,0)),"") -> Bloomex - AUS
A20: ='Priority SKUs'!A8 -> 4 | B20: ='Priority SKUs'!C8 -> DCMJ-01 | C20: ='Priority SKUs'!D8 -> Designer Collection Mason Jar I | D20: ='Priority SKUs'!E8 -> Mason Jar | E20: ='Priority SKUs'!F8 -> 110 | F20: ='Priority SKUs'!H8 -> 14 | G20: ='Priority SKUs'!I8 -> 0.12727273 | H20: ='Priority SKUs'!J8 -> 941.68 | I20: ='Priority SKUs'!L8 -> 7.3104679e-05 | J20: ='Priority SKUs'!B8 -> 1 - Fix first | K20: =IFERROR(INDEX('SKU Data'!$D$2:$D$95,MATCH(B20,'SKU Data'!$A$2:$A$95,0)),"") -> Bunches and Stems - AUS
A21: ='Priority SKUs'!A9 -> 5 | B21: ='Priority SKUs'!C9 -> AUDNAT-03 | C21: ='Priority SKUs'!D9 -> Native Flowers Bouquet Designer Collection III | D21: ='Priority SKUs'!E9 -> Native Flowers | E21: ='Priority SKUs'!F9 -> 353 | F21: ='Priority SKUs'!H9 -> 25 | G21: ='Priority SKUs'!I9 -> 0.07082153 | H21: ='Priority SKUs'!J9 -> 4128.81 | I21: ='Priority SKUs'!L9 -> 0.00032052855 | J21: ='Priority SKUs'!B9 -> 1 - Fix first | K21: =IFERROR(INDEX('SKU Data'!$D$2:$D$95,MATCH(B21,'SKU Data'!$A$2:$A$95,0)),"") -> Bloomex - AUS
A22: ='Priority SKUs'!A10 -> 6 | B22: ='Priority SKUs'!C10 -> DCB-02 | C22: ='Priority SKUs'!D10 -> Birthday Designer Collection II | D22: ='Priority SKUs'!E10 -> Birthday | E22: ='Priority SKUs'!F10 -> 87 | F22: ='Priority SKUs'!H10 -> 10 | G22: ='Priority SKUs'!I10 -> 0.11494253 | H22: ='Priority SKUs'!J10 -> 1216.35 | I22: ='Priority SKUs'!L10 -> 9.4427912e-05 | J22: ='Priority SKUs'!B10 -> 1 - Fix first | K22: =IFERROR(INDEX('SKU Data'!$D$2:$D$95,MATCH(B22,'SKU Data'!$A$2:$A$95,0)),"") -> Bunches and Stems - AUS
A23: ='Priority SKUs'!A11 -> 7 | B23: ='Priority SKUs'!C11 -> DCB-01C | C23: ='Priority SKUs'!D11 -> Birthday Designer Collection I Combo | D23: ='Priority SKUs'!E11 -> Birthday | E23: ='Priority SKUs'!F11 -> 95 | F23: ='Priority SKUs'!H11 -> 10 | G23: ='Priority SKUs'!I11 -> 0.10526316 | H23: ='Priority SKUs'!J11 -> 957.93 | I23: ='Priority SKUs'!L11 -> 7.4366202e-05 | J23: ='Priority SKUs'!B11 -> 1 - Fix first | K23: =IFERROR(INDEX('SKU Data'!$D$2:$D$95,MATCH(B23,'SKU Data'!$A$2:$A$95,0)),"") -> Bloomex - AUS
A24: ='Priority SKUs'!A12 -> 8 | B24: ='Priority SKUs'!C12 -> AUDNAT-01 | C24: ='Priority SKUs'!D12 -> Native Flowers Bouquet Designer Collection I | D24: ='Priority SKUs'!E12 -> Native Flowers | E24: ='Priority SKUs'!F12 -> 374 | F24: ='Priority SKUs'!H12 -> 26 | G24: ='Priority SKUs'!I12 -> 0.069518717 | H24: ='Priority SKUs'!J12 -> 2872.37 | I24: ='Priority SKUs'!L12 -> 0.00022298837 | J24: ='Priority SKUs'!B12 -> 1 - Fix first | K24: =IFERROR(INDEX('SKU Data'!$D$2:$D$95,MATCH(B24,'SKU Data'!$A$2:$A$95,0)),"") -> Bloomex - AUS
A25: ='Priority SKUs'!A13 -> 9 | B25: ='Priority SKUs'!C13 -> DCA-02-00 | C25: ='Priority SKUs'!D13 -> Anniversary Designer Collection II | D25: ='Priority SKUs'!E13 -> Anniversary | E25: ='Priority SKUs'!F13 -> 36 | F25: ='Priority SKUs'!H13 -> 8 | G25: ='Priority SKUs'!I13 -> 0.22222222 | H25: ='Priority SKUs'!J13 -> 735.3 | I25: ='Priority SKUs'!L13 -> 5.7082948e-05 | J25: ='Priority SKUs'!B13 -> 1 - Fix first | K25: =IFERROR(INDEX('SKU Data'!$D$2:$D$95,MATCH(B25,'SKU Data'!$A$2:$A$95,0)),"") -> Bunches and Stems - AUS
A26: ='Priority SKUs'!A14 -> 10 | B26: ='Priority SKUs'!C14 -> DCS-02 | C26: ='Priority SKUs'!D14 -> Designer Sympathy Collection II | D26: ='Priority SKUs'!E14 -> Sympathy | E26: ='Priority SKUs'!F14 -> 79 | F26: ='Priority SKUs'!H14 -> 7 | G26: ='Priority SKUs'!I14 -> 0.088607595 | H26: ='Priority SKUs'!J14 -> 798.41 | I26: ='Priority SKUs'!L14 -> 6.1982315e-05 | J26: ='Priority SKUs'!B14 -> 1 - Fix first | K26: =IFERROR(INDEX('SKU Data'!$D$2:$D$95,MATCH(B26,'SKU Data'!$A$2:$A$95,0)),"") -> Bunches and Stems - AUS
A28: Charts
A110: Sheet guide: Lines (sub-collections) | Priority SKUs | Rankings | Stores | Monthly | Anomalies | Review List | Notes | Settings | Detail + SKU Data (inputs)

Sheet Lines
A1: Product lines inside the Designer Collection
A2: Lines are derived from the product name / SKU (Sympathy, Birthday, Anniversary, Mason Jar, Native Flowers, Mother's Day, Christmas, General). Live SUMIFS on SKU Data. Comments written from the data at export date.
A4: Line | B4: # SKUs | C4: Units ordered (window) | D4: Refunded units (window) | E4: Refund rate (window) | F4: Rate vs designer avg | G4: Rate vs rest-of-catalog | H4: z vs designer avg | I4: Gross $ (all months) | J4: Refund $ (all months) | K4: % of designer refund $ | L4: % of total company revenue | M4: Flag | N4: Comment 1 | O4: Comment 2 | P4: Comment 3 | Q4: Designer avg | R4: Rest of catalog
A5: Sympathy | B5: =COUNTIF('SKU Data'!$C$2:$C$95,$A5) -> 9 | C5: =SUMIFS('SKU Data'!$E$2:$E$95,'SKU Data'!$C$2:$C$95,$A5) -> 3754 | D5: =SUMIFS('SKU Data'!$J$2:$J$95,'SKU Data'!$C$2:$C$95,$A5) -> 220 | E5: =IF(C5>0,D5/C5,0) -> 0.058604156 | F5: =E5/Settings!$B$3 -> 0.88135156 | G5: =E5/Settings!$B$14 -> 0.78227854 | H5: =IF(C5>0,(D5-C5*Settings!$B$3)/SQRT(C5*Settings!$B$3*(1-Settings!$B$3)),0) -> -1.9401715 | I5: =SUMIFS('SKU Data'!$I$2:$I$95,'SKU Data'!$C$2:$C$95,$A5) -> 711515.82 | J5: =SUMIFS('SKU Data'!$H$2:$H$95,'SKU Data'!$C$2:$C$95,$A5) -> 26197.77 | K5: =J5/Settings!$B$18 -> 0.44087298 | L5: =J5/Settings!$B$15 -> 0.0020337902 | M5: =IF(AND(C5>=Settings!$B$4,D5>=Settings!$B$5,H5>=Settings!$B$6),"HIGH RATE",IF(AND(C5>=Settings!$B$4,H5<=-Settings!$B$6),"BELOW AVG","")) | N5: Window refund rate 5.9% = 0.88x the designer average (6.6%) and 0.78x the rest of catalog (7.5%); 220 of 3,754 units since 2026-08. | O5: 44% of designer refund $ ($26,198) on 43% of designer gross. Top SKUs by refund $: DC-04S ($8,683), DC-02S ($6,122), DC-03S ($4,565). | P5: No SKU statistically above average. Highest rates: DCS-01 12.8%, DCS-02 8.9%. | Q5: =Settings!$B$3 -> 0.066493506 | R5: =Settings!$B$14 -> 0.074914692
A6: Native Flowers | B6: =COUNTIF('SKU Data'!$C$2:$C$95,$A6) -> 10 | C6: =SUMIFS('SKU Data'!$E$2:$E$95,'SKU Data'!$C$2:$C$95,$A6) -> 1529 | D6: =SUMIFS('SKU Data'!$J$2:$J$95,'SKU Data'!$C$2:$C$95,$A6) -> 106 | E6: =IF(C6>0,D6/C6,0) -> 0.069326357 | F6: =E6/Settings!$B$3 -> 1.0426034 | G6: =E6/Settings!$B$14 -> 0.92540402 | H6: =IF(C6>0,(D6-C6*Settings!$B$3)/SQRT(C6*Settings!$B$3*(1-Settings!$B$3)),0) -> 0.4446099 | I6: =SUMIFS('SKU Data'!$I$2:$I$95,'SKU Data'!$C$2:$C$95,$A6) -> 334875.11 | J6: =SUMIFS('SKU Data'!$H$2:$H$95,'SKU Data'!$C$2:$C$95,$A6) -> 13571.55 | K6: =J6/Settings!$B$18 -> 0.2283908 | L6: =J6/Settings!$B$15 -> 0.0010535891 | M6: =IF(AND(C6>=Settings!$B$4,D6>=Settings!$B$5,H6>=Settings!$B$6),"HIGH RATE",IF(AND(C6>=Settings!$B$4,H6<=-Settings!$B$6),"BELOW AVG","")) | N6: Window refund rate 6.9% = 1.04x the designer average (6.6%) and 0.93x the rest of catalog (7.5%); 106 of 1,529 units since 2026-08. | O6: 23% of designer refund $ ($13,572) on 20% of designer gross. Top SKUs by refund $: AUDNAT-02 ($6,091), AUDNAT-03 ($4,129), AUDNAT-01 ($2,872). | P6: No SKU statistically above average. Highest rates: AUDNAT-03 7.1%, AUDNAT-01 7.0%. | Q6: =Settings!$B$3 -> 0.066493506 | R6: =Settings!$B$14 -> 0.074914692
A7: Birthday | B7: =COUNTIF('SKU Data'!$C$2:$C$95,$A7) -> 20 | C7: =SUMIFS('SKU Data'!$E$2:$E$95,'SKU Data'!$C$2:$C$95,$A7) -> 1114 | D7: =SUMIFS('SKU Data'!$J$2:$J$95,'SKU Data'!$C$2:$C$95,$A7) -> 91 | E7: =IF(C7>0,D7/C7,0) -> 0.081687612 | F7: =E7/Settings!$B$3 -> 1.2285051 | G7: =E7/Settings!$B$14 -> 1.0904084 | H7: =IF(C7>0,(D7-C7*Settings!$B$3)/SQRT(C7*Settings!$B$3*(1-Settings!$B$3)),0) -> 2.0354922 | I7: =SUMIFS('SKU Data'!$I$2:$I$95,'SKU Data'!$C$2:$C$95,$A7) -> 191253.48 | J7: =SUMIFS('SKU Data'!$H$2:$H$95,'SKU Data'!$C$2:$C$95,$A7) -> 9169.56 | K7: =J7/Settings!$B$18 -> 0.15431127 | L7: =J7/Settings!$B$15 -> 0.00071185301 | M7: =IF(AND(C7>=Settings!$B$4,D7>=Settings!$B$5,H7>=Settings!$B$6),"HIGH RATE",IF(AND(C7>=Settings!$B$4,H7<=-Settings!$B$6),"BELOW AVG","")) | N7: Window refund rate 8.2% = 1.23x the designer average (6.6%) and 1.09x the rest of catalog (7.5%); 91 of 1,114 units since 2026-08. | O7: 15% of designer refund $ ($9,170) on 12% of designer gross. Top SKUs by refund $: DC-02B ($2,889), DC-01B ($2,433), DCB-02 ($1,216). | P7: No SKU statistically above average. Highest rates: DCB-02 11.5%, DC-02B 11.2%. | Q7: =Settings!$B$3 -> 0.066493506 | R7: =Settings!$B$14 -> 0.074914692
A8: Mason Jar | B8: =COUNTIF('SKU Data'!$C$2:$C$95,$A8) -> 20 | C8: =SUMIFS('SKU Data'!$E$2:$E$95,'SKU Data'!$C$2:$C$95,$A8) -> 743 | D8: =SUMIFS('SKU Data'!$J$2:$J$95,'SKU Data'!$C$2:$C$95,$A8) -> 52 | E8: =IF(C8>0,D8/C8,0) -> 0.069986541 | F8: =E8/Settings!$B$3 -> 1.052532 | G8: =E8/Settings!$B$14 -> 0.9342165 | H8: =IF(C8>0,(D8-C8*Settings!$B$3)/SQRT(C8*Settings!$B$3*(1-Settings!$B$3)),0) -> 0.38216332 | I8: =SUMIFS('SKU Data'!$I$2:$I$95,'SKU Data'!$C$2:$C$95,$A8) -> 214678.52 | J8: =SUMIFS('SKU Data'!$H$2:$H$95,'SKU Data'!$C$2:$C$95,$A8) -> 5470.76 | K8: =J8/Settings!$B$18 -> 0.092065479 | L8: =J8/Settings!$B$15 -> 0.00042470707 | M8: =IF(AND(C8>=Settings!$B$4,D8>=Settings!$B$5,H8>=Settings!$B$6),"HIGH RATE",IF(AND(C8>=Settings!$B$4,H8<=-Settings!$B$6),"BELOW AVG","")) | N8: Window refund rate 7.0% = 1.05x the designer average (6.6%) and 0.93x the rest of catalog (7.5%); 52 of 743 units since 2026-08. | O8: 9% of designer refund $ ($5,471) on 13% of designer gross. Top SKUs by refund $: DCMJ-04A ($1,072), DCMJ-01 ($942), DCMJ-03A ($762). | P8: No SKU statistically above average. Highest rates: DCMJ-01 12.7%, AUDNAT-MJ-02 9.1%. | Q8: =Settings!$B$3 -> 0.066493506 | R8: =Settings!$B$14 -> 0.074914692
A9: Anniversary | B9: =COUNTIF('SKU Data'!$C$2:$C$95,$A9) -> 14 | C9: =SUMIFS('SKU Data'!$E$2:$E$95,'SKU Data'!$C$2:$C$95,$A9) -> 378 | D9: =SUMIFS('SKU Data'!$J$2:$J$95,'SKU Data'!$C$2:$C$95,$A9) -> 33 | E9: =IF(C9>0,D9/C9,0) -> 0.087301587 | F9: =E9/Settings!$B$3 -> 1.312934 | G9: =E9/Settings!$B$14 -> 1.1653467 | H9: =IF(C9>0,(D9-C9*Settings!$B$3)/SQRT(C9*Settings!$B$3*(1-Settings!$B$3)),0) -> 1.6237892 | I9: =SUMIFS('SKU Data'!$I$2:$I$95,'SKU Data'!$C$2:$C$95,$A9) -> 111082.56 | J9: =SUMIFS('SKU Data'!$H$2:$H$95,'SKU Data'!$C$2:$C$95,$A9) -> 3429.16 | K9: =J9/Settings!$B$18 -> 0.057708117 | L9: =J9/Settings!$B$15 -> 0.00026621319 | M9: =IF(AND(C9>=Settings!$B$4,D9>=Settings!$B$5,H9>=Settings!$B$6),"HIGH RATE",IF(AND(C9>=Settings!$B$4,H9<=-Settings!$B$6),"BELOW AVG","")) | N9: Window refund rate 8.7% = 1.31x the designer average (6.6%) and 1.17x the rest of catalog (7.5%); 33 of 378 units since 2026-08. | O9: 6% of designer refund $ ($3,429) on 7% of designer gross. Top SKUs by refund $: DCA-02-00 ($735), AUDC-04A ($711), DC-01A ($670). | P9: Attention: 1 SKU(s) statistically above the designer average: DCA-02-00 (22.2% on 36 units). | Q9: =Settings!$B$3 -> 0.066493506 | R9: =Settings!$B$14 -> 0.074914692
A10: General (Designer Collection) | B10: =COUNTIF('SKU Data'!$C$2:$C$95,$A10) -> 9 | C10: =SUMIFS('SKU Data'!$E$2:$E$95,'SKU Data'!$C$2:$C$95,$A10) -> 156 | D10: =SUMIFS('SKU Data'!$J$2:$J$95,'SKU Data'!$C$2:$C$95,$A10) -> 8 | E10: =IF(C10>0,D10/C10,0) -> 0.051282051 | F10: =E10/Settings!$B$3 -> 0.77123397 | G10: =E10/Settings!$B$14 -> 0.68453931 | H10: =IF(C10>0,(D10-C10*Settings!$B$3)/SQRT(C10*Settings!$B$3*(1-Settings!$B$3)),0) -> -0.76257888 | I10: =SUMIFS('SKU Data'!$I$2:$I$95,'SKU Data'!$C$2:$C$95,$A10) -> 55290.553 | J10: =SUMIFS('SKU Data'!$H$2:$H$95,'SKU Data'!$C$2:$C$95,$A10) -> 1131.15 | K10: =J10/Settings!$B$18 -> 0.019035722 | L10: =J10/Settings!$B$15 -> 8.7813649e-05 | M10: =IF(AND(C10>=Settings!$B$4,D10>=Settings!$B$5,H10>=Settings!$B$6),"HIGH RATE",IF(AND(C10>=Settings!$B$4,H10<=-Settings!$B$6),"BELOW AVG","")) | N10: Window refund rate 5.1% = 0.77x the designer average (6.6%) and 0.68x the rest of catalog (7.5%); 8 of 156 units since 2026-08. | O10: 2% of designer refund $ ($1,131) on 3% of designer gross. Top SKUs by refund $: AUDC-04 ($427), AUDC-02 ($404), AUDC-03 ($165). | P10: Small sample (156 window units) - rates are noisy; watch rather than act. | Q10: =Settings!$B$3 -> 0.066493506 | R10: =Settings!$B$14 -> 0.074914692
A11: Mother's Day | B11: =COUNTIF('SKU Data'!$C$2:$C$95,$A11) -> 11 | C11: =SUMIFS('SKU Data'!$E$2:$E$95,'SKU Data'!$C$2:$C$95,$A11) -> 26 | D11: =SUMIFS('SKU Data'!$J$2:$J$95,'SKU Data'!$C$2:$C$95,$A11) -> 2 | E11: =IF(C11>0,D11/C11,0) -> 0.076923077 | F11: =E11/Settings!$B$3 -> 1.156851 | G11: =E11/Settings!$B$14 -> 1.026809 | H11: =IF(C11>0,(D11-C11*Settings!$B$3)/SQRT(C11*Settings!$B$3*(1-Settings!$B$3)),0) -> 0.21345425 | I11: =SUMIFS('SKU Data'!$I$2:$I$95,'SKU Data'!$C$2:$C$95,$A11) -> 35738.276 | J11: =SUMIFS('SKU Data'!$H$2:$H$95,'SKU Data'!$C$2:$C$95,$A11) -> 452.54 | K11: =J11/Settings!$B$18 -> 0.0076156351 | L11: =J11/Settings!$B$15 -> 3.513167e-05 | M11: =IF(AND(C11>=Settings!$B$4,D11>=Settings!$B$5,H11>=Settings!$B$6),"HIGH RATE",IF(AND(C11>=Settings!$B$4,H11<=-Settings!$B$6),"BELOW AVG","")) | N11: Window refund rate 7.7% = 1.16x the designer average (6.6%) and 1.03x the rest of catalog (7.5%); 2 of 26 units since 2026-08. | O11: 1% of designer refund $ ($453) on 2% of designer gross. Top SKUs by refund $: MDDC-01 ($200), MDBC-02 ($143), FYF-mother-s-day-designer-collection-premium-C ($110). | P11: Small sample (26 window units) - rates are noisy; watch rather than act. | Q11: =Settings!$B$3 -> 0.066493506 | R11: =Settings!$B$14 -> 0.074914692
A12: Christmas | B12: =COUNTIF('SKU Data'!$C$2:$C$95,$A12) -> 1 | C12: =SUMIFS('SKU Data'!$E$2:$E$95,'SKU Data'!$C$2:$C$95,$A12) -> 0 | D12: =SUMIFS('SKU Data'!$J$2:$J$95,'SKU Data'!$C$2:$C$95,$A12) -> 0 | E12: =IF(C12>0,D12/C12,0) -> 0 | F12: =E12/Settings!$B$3 -> 0 | G12: =E12/Settings!$B$14 -> 0 | H12: =IF(C12>0,(D12-C12*Settings!$B$3)/SQRT(C12*Settings!$B$3*(1-Settings!$B$3)),0) -> 0 | I12: =SUMIFS('SKU Data'!$I$2:$I$95,'SKU Data'!$C$2:$C$95,$A12) -> 73.95 | J12: =SUMIFS('SKU Data'!$H$2:$H$95,'SKU Data'!$C$2:$C$95,$A12) -> 0 | K12: =J12/Settings!$B$18 -> 0 | L12: =J12/Settings!$B$15 -> 0 | M12: =IF(AND(C12>=Settings!$B$4,D12>=Settings!$B$5,H12>=Settings!$B$6),"HIGH RATE",IF(AND(C12>=Settings!$B$4,H12<=-Settings!$B$6),"BELOW AVG","")) | N12: No units sold since 2026-08; refunds are from earlier months only. | O12: 0% of designer refund $ ($0) on 0% of designer gross. Top SKUs by refund $: DCX-01 ($0). | P12: Small sample (0 window units) - rates are noisy; watch rather than act. | Q12: =Settings!$B$3 -> 0.066493506 | R12: =Settings!$B$14 -> 0.074914692

Sheet Priority SKUs
A1: Priority SKUs - Designer Collection (add-ons excluded)
A2: Score = equal blend of percentile ranks for refunded units (all months), refund $ (all months = impact on revenue) and refund rate on the SKU's own sales since the rate-window start (shrunk for small volume). Live: change Settings and it re-ranks.
A4: Rank | B4: Tier | C4: SKU | D4: Product | E4: Line | F4: Units ordered (window) | G4: Refunded units (all months) | H4: Refunded units (window) | I4: Refund rate (window) | J4: Refund $ (all months) | K4: % of designer revenue | L4: % of total company revenue | M4: Rate vs designer avg | N4: Rate vs rest-of-catalog | O4: z vs designer avg | P4: Flag
A5: 1 | B5: =IFERROR(INDEX('SKU Data'!$X$2:$X$95,MATCH($A5,'SKU Data'!$W$2:$W$95,0)),"") -> 1 - Fix first | C5: =IFERROR(INDEX('SKU Data'!$A$2:$A$95,MATCH($A5,'SKU Data'!$W$2:$W$95,0)),"") -> DC-02B | D5: =IFERROR(INDEX('SKU Data'!$B$2:$B$95,MATCH($A5,'SKU Data'!$W$2:$W$95,0)),"") -> Birthday Designer Collection II | E5: =IFERROR(INDEX('SKU Data'!$C$2:$C$95,MATCH($A5,'SKU Data'!$W$2:$W$95,0)),"") -> Birthday | F5: =IFERROR(INDEX('SKU Data'!$E$2:$E$95,MATCH($A5,'SKU Data'!$W$2:$W$95,0)),"") -> 223 | G5: =IFERROR(INDEX('SKU Data'!$F$2:$F$95,MATCH($A5,'SKU Data'!$W$2:$W$95,0)),"") -> 28 | H5: =IFERROR(INDEX('SKU Data'!$J$2:$J$95,MATCH($A5,'SKU Data'!$W$2:$W$95,0)),"") -> 25 | I5: =IFERROR(INDEX('SKU Data'!$L$2:$L$95,MATCH($A5,'SKU Data'!$W$2:$W$95,0)),"") -> 0.11210762 | J5: =IFERROR(INDEX('SKU Data'!$H$2:$H$95,MATCH($A5,'SKU Data'!$W$2:$W$95,0)),"") -> 2889.28 | K5: =IFERROR(INDEX('SKU Data'!$N$2:$N$95,MATCH($A5,'SKU Data'!$W$2:$W$95,0)),"") -> 0.0017463074 | L5: =IFERROR(INDEX('SKU Data'!$O$2:$O$95,MATCH($A5,'SKU Data'!$W$2:$W$95,0)),"") -> 0.00022430113 | M5: =IFERROR(I5/Settings!$B$3,"") -> 1.6859936 | N5: =IFERROR(INDEX('SKU Data'!$AF$2:$AF$95,MATCH($A5,'SKU Data'!$W$2:$W$95,0)),"") -> 1.4964705 | O5: =IFERROR(INDEX('SKU Data'!$Q$2:$Q$95,MATCH($A5,'SKU Data'!$W$2:$W$95,0)),"") -> 2.7340309 | P5: =IFERROR(INDEX('SKU Data'!$Y$2:$Y$95,MATCH($A5,'SKU Data'!$W$2:$W$95,0)),"")
A6: 2 | B6: =IFERROR(INDEX('SKU Data'!$X$2:$X$95,MATCH($A6,'SKU Data'!$W$2:$W$95,0)),"") -> 1 - Fix first | C6: =IFERROR(INDEX('SKU Data'!$A$2:$A$95,MATCH($A6,'SKU Data'!$W$2:$W$95,0)),"") -> DC-02S | D6: =IFERROR(INDEX('SKU Data'!$B$2:$B$95,MATCH($A6,'SKU Data'!$W$2:$W$95,0)),"") -> Designer Sympathy Collection II | E6: =IFERROR(INDEX('SKU Data'!$C$2:$C$95,MATCH($A6,'SKU Data'!$W$2:$W$95,0)),"") -> Sympathy | F6: =IFERROR(INDEX('SKU Data'!$E$2:$E$95,MATCH($A6,'SKU Data'!$W$2:$W$95,0)),"") -> 849 | G6: =IFERROR(INDEX('SKU Data'!$F$2:$F$95,MATCH($A6,'SKU Data'!$W$2:$W$95,0)),"") -> 62 | H6: =IFERROR(INDEX('SKU Data'!$J$2:$J$95,MATCH($A6,'SKU Data'!$W$2:$W$95,0)),"") -> 59 | I6: =IFERROR(INDEX('SKU Data'!$L$2:$L$95,MATCH($A6,'SKU Data'!$W$2:$W$95,0)),"") -> 0.069493522 | J6: =IFERROR(INDEX('SKU Data'!$H$2:$H$95,MATCH($A6,'SKU Data'!$W$2:$W$95,0)),"") -> 6122.41 | K6: =IFERROR(INDEX('SKU Data'!$N$2:$N$95,MATCH($A6,'SKU Data'!$W$2:$W$95,0)),"") -> 0.0037004409 | L6: =IFERROR(INDEX('SKU Data'!$O$2:$O$95,MATCH($A6,'SKU Data'!$W$2:$W$95,0)),"") -> 0.00047529608 | M6: =IFERROR(I6/Settings!$B$3,"") -> 1.0451174 | N6: =IFERROR(INDEX('SKU Data'!$AF$2:$AF$95,MATCH($A6,'SKU Data'!$W$2:$W$95,0)),"") -> 0.92763542 | O6: =IFERROR(INDEX('SKU Data'!$Q$2:$Q$95,MATCH($A6,'SKU Data'!$W$2:$W$95,0)),"") -> 0.35085609 | P6: =IFERROR(INDEX('SKU Data'!$Y$2:$Y$95,MATCH($A6,'SKU Data'!$W$2:$W$95,0)),"")
A7: 3 | B7: =IFERROR(INDEX('SKU Data'!$X$2:$X$95,MATCH($A7,'SKU Data'!$W$2:$W$95,0)),"") -> 1 - Fix first | C7: =IFERROR(INDEX('SKU Data'!$A$2:$A$95,MATCH($A7,'SKU Data'!$W$2:$W$95,0)),"") -> AUDNAT-02 | D7: =IFERROR(INDEX('SKU Data'!$B$2:$B$95,MATCH($A7,'SKU Data'!$W$2:$W$95,0)),"") -> Native Flowers Bouquet Designer Collection II | E7: =IFERROR(INDEX('SKU Data'!$C$2:$C$95,MATCH($A7,'SKU Data'!$W$2:$W$95,0)),"") -> Native Flowers | F7: =IFERROR(INDEX('SKU Data'!$E$2:$E$95,MATCH($A7,'SKU Data'!$W$2:$W$95,0)),"") -> 802 | G7: =IFERROR(INDEX('SKU Data'!$F$2:$F$95,MATCH($A7,'SKU Data'!$W$2:$W$95,0)),"") -> 62 | H7: =IFERROR(INDEX('SKU Data'!$J$2:$J$95,MATCH($A7,'SKU Data'!$W$2:$W$95,0)),"") -> 55 | I7: =IFERROR(INDEX('SKU Data'!$L$2:$L$95,MATCH($A7,'SKU Data'!$W$2:$W$95,0)),"") -> 0.068578554 | J7: =IFERROR(INDEX('SKU Data'!$H$2:$H$95,MATCH($A7,'SKU Data'!$W$2:$W$95,0)),"") -> 6090.57 | K7: =IFERROR(INDEX('SKU Data'!$N$2:$N$95,MATCH($A7,'SKU Data'!$W$2:$W$95,0)),"") -> 0.0036811965 | L7: =IFERROR(INDEX('SKU Data'!$O$2:$O$95,MATCH($A7,'SKU Data'!$W$2:$W$95,0)),"") -> 0.00047282428 | M7: =IFERROR(I7/Settings!$B$3,"") -> 1.0313572 | N7: =IFERROR(INDEX('SKU Data'!$AF$2:$AF$95,MATCH($A7,'SKU Data'!$W$2:$W$95,0)),"") -> 0.91542195 | O7: =IFERROR(INDEX('SKU Data'!$Q$2:$Q$95,MATCH($A7,'SKU Data'!$W$2:$W$95,0)),"") -> 0.23700351 | P7: =IFERROR(INDEX('SKU Data'!$Y$2:$Y$95,MATCH($A7,'SKU Data'!$W$2:$W$95,0)),"")
A8: 4 | B8: =IFERROR(INDEX('SKU Data'!$X$2:$X$95,MATCH($A8,'SKU Data'!$W$2:$W$95,0)),"") -> 1 - Fix first | C8: =IFERROR(INDEX('SKU Data'!$A$2:$A$95,MATCH($A8,'SKU Data'!$W$2:$W$95,0)),"") -> DCMJ-01 | D8: =IFERROR(INDEX('SKU Data'!$B$2:$B$95,MATCH($A8,'SKU Data'!$W$2:$W$95,0)),"") -> Designer Collection Mason Jar I | E8: =IFERROR(INDEX('SKU Data'!$C$2:$C$95,MATCH($A8,'SKU Data'!$W$2:$W$95,0)),"") -> Mason Jar | F8: =IFERROR(INDEX('SKU Data'!$E$2:$E$95,MATCH($A8,'SKU Data'!$W$2:$W$95,0)),"") -> 110 | G8: =IFERROR(INDEX('SKU Data'!$F$2:$F$95,MATCH($A8,'SKU Data'!$W$2:$W$95,0)),"") -> 18 | H8: =IFERROR(INDEX('SKU Data'!$J$2:$J$95,MATCH($A8,'SKU Data'!$W$2:$W$95,0)),"") -> 14 | I8: =IFERROR(INDEX('SKU Data'!$L$2:$L$95,MATCH($A8,'SKU Data'!$W$2:$W$95,0)),"") -> 0.12727273 | J8: =IFERROR(INDEX('SKU Data'!$H$2:$H$95,MATCH($A8,'SKU Data'!$W$2:$W$95,0)),"") -> 941.68 | K8: =IFERROR(INDEX('SKU Data'!$N$2:$N$95,MATCH($A8,'SKU Data'!$W$2:$W$95,0)),"") -> 0.00056916004 | L8: =IFERROR(INDEX('SKU Data'!$O$2:$O$95,MATCH($A8,'SKU Data'!$W$2:$W$95,0)),"") -> 7.3104679e-05 | M8: =IFERROR(I8/Settings!$B$3,"") -> 1.9140625 | N8: =IFERROR(INDEX('SKU Data'!$AF$2:$AF$95,MATCH($A8,'SKU Data'!$W$2:$W$95,0)),"") -> 1.6989021 | O8: =IFERROR(INDEX('SKU Data'!$Q$2:$Q$95,MATCH($A8,'SKU Data'!$W$2:$W$95,0)),"") -> 2.5586046 | P8: =IFERROR(INDEX('SKU Data'!$Y$2:$Y$95,MATCH($A8,'SKU Data'!$W$2:$W$95,0)),"")
A9: 5 | B9: =IFERROR(INDEX('SKU Data'!$X$2:$X$95,MATCH($A9,'SKU Data'!$W$2:$W$95,0)),"") -> 1 - Fix first | C9: =IFERROR(INDEX('SKU Data'!$A$2:$A$95,MATCH($A9,'SKU Data'!$W$2:$W$95,0)),"") -> AUDNAT-03 | D9: =IFERROR(INDEX('SKU Data'!$B$2:$B$95,MATCH($A9,'SKU Data'!$W$2:$W$95,0)),"") -> Native Flowers Bouquet Designer Collection III | E9: =IFERROR(INDEX('SKU Data'!$C$2:$C$95,MATCH($A9,'SKU Data'!$W$2:$W$95,0)),"") -> Native Flowers | F9: =IFERROR(INDEX('SKU Data'!$E$2:$E$95,MATCH($A9,'SKU Data'!$W$2:$W$95,0)),"") -> 353 | G9: =IFERROR(INDEX('SKU Data'!$F$2:$F$95,MATCH($A9,'SKU Data'!$W$2:$W$95,0)),"") -> 31 | H9: =IFERROR(INDEX('SKU Data'!$J$2:$J$95,MATCH($A9,'SKU Data'!$W$2:$W$95,0)),"") -> 25 | I9: =IFERROR(INDEX('SKU Data'!$L$2:$L$95,MATCH($A9,'SKU Data'!$W$2:$W$95,0)),"") -> 0.07082153 | J9: =IFERROR(INDEX('SKU Data'!$H$2:$H$95,MATCH($A9,'SKU Data'!$W$2:$W$95,0)),"") -> 4128.81 | K9: =IFERROR(INDEX('SKU Data'!$N$2:$N$95,MATCH($A9,'SKU Data'!$W$2:$W$95,0)),"") -> 0.0024954907 | L9: =IFERROR(INDEX('SKU Data'!$O$2:$O$95,MATCH($A9,'SKU Data'!$W$2:$W$95,0)),"") -> 0.00032052855 | M9: =IFERROR(I9/Settings!$B$3,"") -> 1.0650894 | N9: =IFERROR(INDEX('SKU Data'!$AF$2:$AF$95,MATCH($A9,'SKU Data'!$W$2:$W$95,0)),"") -> 0.94536236 | O9: =IFERROR(INDEX('SKU Data'!$Q$2:$Q$95,MATCH($A9,'SKU Data'!$W$2:$W$95,0)),"") -> 0.32638384 | P9: =IFERROR(INDEX('SKU Data'!$Y$2:$Y$95,MATCH($A9,'SKU Data'!$W$2:$W$95,0)),"")
A10: 6 | B10: =IFERROR(INDEX('SKU Data'!$X$2:$X$95,MATCH($A10,'SKU Data'!$W$2:$W$95,0)),"") -> 1 - Fix first | C10: =IFERROR(INDEX('SKU Data'!$A$2:$A$95,MATCH($A10,'SKU Data'!$W$2:$W$95,0)),"") -> DCB-02 | D10: =IFERROR(INDEX('SKU Data'!$B$2:$B$95,MATCH($A10,'SKU Data'!$W$2:$W$95,0)),"") -> Birthday Designer Collection II | E10: =IFERROR(INDEX('SKU Data'!$C$2:$C$95,MATCH($A10,'SKU Data'!$W$2:$W$95,0)),"") -> Birthday | F10: =IFERROR(INDEX('SKU Data'!$E$2:$E$95,MATCH($A10,'SKU Data'!$W$2:$W$95,0)),"") -> 87 | G10: =IFERROR(INDEX('SKU Data'!$F$2:$F$95,MATCH($A10,'SKU Data'!$W$2:$W$95,0)),"") -> 12 | H10: =IFERROR(INDEX('SKU Data'!$J$2:$J$95,MATCH($A10,'SKU Data'!$W$2:$W$95,0)),"") -> 10 | I10: =IFERROR(INDEX('SKU Data'!$L$2:$L$95,MATCH($A10,'SKU Data'!$W$2:$W$95,0)),"") -> 0.11494253 | J10: =IFERROR(INDEX('SKU Data'!$H$2:$H$95,MATCH($A10,'SKU Data'!$W$2:$W$95,0)),"") -> 1216.35 | K10: =IFERROR(INDEX('SKU Data'!$N$2:$N$95,MATCH($A10,'SKU Data'!$W$2:$W$95,0)),"") -> 0.00073517311 | L10: =IFERROR(INDEX('SKU Data'!$O$2:$O$95,MATCH($A10,'SKU Data'!$W$2:$W$95,0)),"") -> 9.4427912e-05 | M10: =IFERROR(I10/Settings!$B$3,"") -> 1.7286279 | N10: =IFERROR(INDEX('SKU Data'!$AF$2:$AF$95,MATCH($A10,'SKU Data'!$W$2:$W$95,0)),"") -> 1.5343122 | O10: =IFERROR(INDEX('SKU Data'!$Q$2:$Q$95,MATCH($A10,'SKU Data'!$W$2:$W$95,0)),"") -> 1.8138291 | P10: =IFERROR(INDEX('SKU Data'!$Y$2:$Y$95,MATCH($A10,'SKU Data'!$W$2:$W$95,0)),"")
A11: 7 | B11: =IFERROR(INDEX('SKU Data'!$X$2:$X$95,MATCH($A11,'SKU Data'!$W$2:$W$95,0)),"") -> 1 - Fix first | C11: =IFERROR(INDEX('SKU Data'!$A$2:$A$95,MATCH($A11,'SKU Data'!$W$2:$W$95,0)),"") -> DCB-01C | D11: =IFERROR(INDEX('SKU Data'!$B$2:$B$95,MATCH($A11,'SKU Data'!$W$2:$W$95,0)),"") -> Birthday Designer Collection I Combo | E11: =IFERROR(INDEX('SKU Data'!$C$2:$C$95,MATCH($A11,'SKU Data'!$W$2:$W$95,0)),"") -> Birthday | F11: =IFERROR(INDEX('SKU Data'!$E$2:$E$95,MATCH($A11,'SKU Data'!$W$2:$W$95,0)),"") -> 95 | G11: =IFERROR(INDEX('SKU Data'!$F$2:$F$95,MATCH($A11,'SKU Data'!$W$2:$W$95,0)),"") -> 12 | H11: =IFERROR(INDEX('SKU Data'!$J$2:$J$95,MATCH($A11,'SKU Data'!$W$2:$W$95,0)),"") -> 10 | I11: =IFERROR(INDEX('SKU Data'!$L$2:$L$95,MATCH($A11,'SKU Data'!$W$2:$W$95,0)),"") -> 0.10526316 | J11: =IFERROR(INDEX('SKU Data'!$H$2:$H$95,MATCH($A11,'SKU Data'!$W$2:$W$95,0)),"") -> 957.93 | K11: =IFERROR(INDEX('SKU Data'!$N$2:$N$95,MATCH($A11,'SKU Data'!$W$2:$W$95,0)),"") -> 0.00057898169 | L11: =IFERROR(INDEX('SKU Data'!$O$2:$O$95,MATCH($A11,'SKU Data'!$W$2:$W$95,0)),"") -> 7.4366202e-05 | M11: =IFERROR(I11/Settings!$B$3,"") -> 1.5830592 | N11: =IFERROR(INDEX('SKU Data'!$AF$2:$AF$95,MATCH($A11,'SKU Data'!$W$2:$W$95,0)),"") -> 1.405107 | O11: =IFERROR(INDEX('SKU Data'!$Q$2:$Q$95,MATCH($A11,'SKU Data'!$W$2:$W$95,0)),"") -> 1.51672 | P11: =IFERROR(INDEX('SKU Data'!$Y$2:$Y$95,MATCH($A11,'SKU Data'!$W$2:$W$95,0)),"")
A12: 8 | B12: =IFERROR(INDEX('SKU Data'!$X$2:$X$95,MATCH($A12,'SKU Data'!$W$2:$W$95,0)),"") -> 1 - Fix first | C12: =IFERROR(INDEX('SKU Data'!$A$2:$A$95,MATCH($A12,'SKU Data'!$W$2:$W$95,0)),"") -> AUDNAT-01 | D12: =IFERROR(INDEX('SKU Data'!$B$2:$B$95,MATCH($A12,'SKU Data'!$W$2:$W$95,0)),"") -> Native Flowers Bouquet Designer Collection I | E12: =IFERROR(INDEX('SKU Data'!$C$2:$C$95,MATCH($A12,'SKU Data'!$W$2:$W$95,0)),"") -> Native Flowers | F12: =IFERROR(INDEX('SKU Data'!$E$2:$E$95,MATCH($A12,'SKU Data'!$W$2:$W$95,0)),"") -> 374 | G12: =IFERROR(INDEX('SKU Data'!$F$2:$F$95,MATCH($A12,'SKU Data'!$W$2:$W$95,0)),"") -> 34 | H12: =IFERROR(INDEX('SKU Data'!$J$2:$J$95,MATCH($A12,'SKU Data'!$W$2:$W$95,0)),"") -> 26 | I12: =IFERROR(INDEX('SKU Data'!$L$2:$L$95,MATCH($A12,'SKU Data'!$W$2:$W$95,0)),"") -> 0.069518717 | J12: =IFERROR(INDEX('SKU Data'!$H$2:$H$95,MATCH($A12,'SKU Data'!$W$2:$W$95,0)),"") -> 2872.37 | K12: =IFERROR(INDEX('SKU Data'!$N$2:$N$95,MATCH($A12,'SKU Data'!$W$2:$W$95,0)),"") -> 0.0017360868 | L12: =IFERROR(INDEX('SKU Data'!$O$2:$O$95,MATCH($A12,'SKU Data'!$W$2:$W$95,0)),"") -> 0.00022298837 | M12: =IFERROR(I12/Settings!$B$3,"") -> 1.0454963 | N12: =IFERROR(INDEX('SKU Data'!$AF$2:$AF$95,MATCH($A12,'SKU Data'!$W$2:$W$95,0)),"") -> 0.92797174 | O12: =IFERROR(INDEX('SKU Data'!$Q$2:$Q$95,MATCH($A12,'SKU Data'!$W$2:$W$95,0)),"") -> 0.23482431 | P12: =IFERROR(INDEX('SKU Data'!$Y$2:$Y$95,MATCH($A12,'SKU Data'!$W$2:$W$95,0)),"")
A13: 9 | B13: =IFERROR(INDEX('SKU Data'!$X$2:$X$95,MATCH($A13,'SKU Data'!$W$2:$W$95,0)),"") -> 1 - Fix first | C13: =IFERROR(INDEX('SKU Data'!$A$2:$A$95,MATCH($A13,'SKU Data'!$W$2:$W$95,0)),"") -> DCA-02-00 | D13: =IFERROR(INDEX('SKU Data'!$B$2:$B$95,MATCH($A13,'SKU Data'!$W$2:$W$95,0)),"") -> Anniversary Designer Collection II | E13: =IFERROR(INDEX('SKU Data'!$C$2:$C$95,MATCH($A13,'SKU Data'!$W$2:$W$95,0)),"") -> Anniversary | F13: =IFERROR(INDEX('SKU Data'!$E$2:$E$95,MATCH($A13,'SKU Data'!$W$2:$W$95,0)),"") -> 36 | G13: =IFERROR(INDEX('SKU Data'!$F$2:$F$95,MATCH($A13,'SKU Data'!$W$2:$W$95,0)),"") -> 8 | H13: =IFERROR(INDEX('SKU Data'!$J$2:$J$95,MATCH($A13,'SKU Data'!$W$2:$W$95,0)),"") -> 8 | I13: =IFERROR(INDEX('SKU Data'!$L$2:$L$95,MATCH($A13,'SKU Data'!$W$2:$W$95,0)),"") -> 0.22222222 | J13: =IFERROR(INDEX('SKU Data'!$H$2:$H$95,MATCH($A13,'SKU Data'!$W$2:$W$95,0)),"") -> 735.3 | K13: =IFERROR(INDEX('SKU Data'!$N$2:$N$95,MATCH($A13,'SKU Data'!$W$2:$W$95,0)),"") -> 0.00044442208 | L13: =IFERROR(INDEX('SKU Data'!$O$2:$O$95,MATCH($A13,'SKU Data'!$W$2:$W$95,0)),"") -> 5.7082948e-05 | M13: =IFERROR(I13/Settings!$B$3,"") -> 3.3420139 | N13: =IFERROR(INDEX('SKU Data'!$AF$2:$AF$95,MATCH($A13,'SKU Data'!$W$2:$W$95,0)),"") -> 2.966337 | O13: =IFERROR(INDEX('SKU Data'!$Q$2:$Q$95,MATCH($A13,'SKU Data'!$W$2:$W$95,0)),"") -> 3.7503488 | P13: =IFERROR(INDEX('SKU Data'!$Y$2:$Y$95,MATCH($A13,'SKU Data'!$W$2:$W$95,0)),"") -> HIGH RATE
A14: 10 | B14: =IFERROR(INDEX('SKU Data'!$X$2:$X$95,MATCH($A14,'SKU Data'!$W$2:$W$95,0)),"") -> 1 - Fix first | C14: =IFERROR(INDEX('SKU Data'!$A$2:$A$95,MATCH($A14,'SKU Data'!$W$2:$W$95,0)),"") -> DCS-02 | D14: =IFERROR(INDEX('SKU Data'!$B$2:$B$95,MATCH($A14,'SKU Data'!$W$2:$W$95,0)),"") -> Designer Sympathy Collection II | E14: =IFERROR(INDEX('SKU Data'!$C$2:$C$95,MATCH($A14,'SKU Data'!$W$2:$W$95,0)),"") -> Sympathy | F14: =IFERROR(INDEX('SKU Data'!$E$2:$E$95,MATCH($A14,'SKU Data'!$W$2:$W$95,0)),"") -> 79 | G14: =IFERROR(INDEX('SKU Data'!$F$2:$F$95,MATCH($A14,'SKU Data'!$W$2:$W$95,0)),"") -> 8 | H14: =IFERROR(INDEX('SKU Data'!$J$2:$J$95,MATCH($A14,'SKU Data'!$W$2:$W$95,0)),"") -> 7 | I14: =IFERROR(INDEX('SKU Data'!$L$2:$L$95,MATCH($A14,'SKU Data'!$W$2:$W$95,0)),"") -> 0.088607595 | J14: =IFERROR(INDEX('SKU Data'!$H$2:$H$95,MATCH($A14,'SKU Data'!$W$2:$W$95,0)),"") -> 798.41 | K14: =IFERROR(INDEX('SKU Data'!$N$2:$N$95,MATCH($A14,'SKU Data'!$W$2:$W$95,0)),"") -> 0.00048256634 | L14: =IFERROR(INDEX('SKU Data'!$O$2:$O$95,MATCH($A14,'SKU Data'!$W$2:$W$95,0)),"") -> 6.1982315e-05 | M14: =IFERROR(I14/Settings!$B$3,"") -> 1.3325752 | N14: =IFERROR(INDEX('SKU Data'!$AF$2:$AF$95,MATCH($A14,'SKU Data'!$W$2:$W$95,0)),"") -> 1.1827799 | O14: =IFERROR(INDEX('SKU Data'!$Q$2:$Q$95,MATCH($A14,'SKU Data'!$W$2:$W$95,0)),"") -> 0.78892242 | P14: =IFERROR(INDEX('SKU Data'!$Y$2:$Y$95,MATCH($A14,'SKU Data'!$W$2:$W$95,0)),"")
A15: 11 | B15: =IFERROR(INDEX('SKU Data'!$X$2:$X$95,MATCH($A15,'SKU Data'!$W$2:$W$95,0)),"") -> 2 - Review | C15: =IFERROR(INDEX('SKU Data'!$A$2:$A$95,MATCH($A15,'SKU Data'!$W$2:$W$95,0)),"") -> DCMJ-03A | D15: =IFERROR(INDEX('SKU Data'!$B$2:$B$95,MATCH($A15,'SKU Data'!$W$2:$W$95,0)),"") -> Designer Collection Mason Jar III | E15: =IFERROR(INDEX('SKU Data'!$C$2:$C$95,MATCH($A15,'SKU Data'!$W$2:$W$95,0)),"") -> Mason Jar | F15: =IFERROR(INDEX('SKU Data'!$E$2:$E$95,MATCH($A15,'SKU Data'!$W$2:$W$95,0)),"") -> 108 | G15: =IFERROR(INDEX('SKU Data'!$F$2:$F$95,MATCH($A15,'SKU Data'!$W$2:$W$95,0)),"") -> 10 | H15: =IFERROR(INDEX('SKU Data'!$J$2:$J$95,MATCH($A15,'SKU Data'!$W$2:$W$95,0)),"") -> 8 | I15: =IFERROR(INDEX('SKU Data'!$L$2:$L$95,MATCH($A15,'SKU Data'!$W$2:$W$95,0)),"") -> 0.074074074 | J15: =IFERROR(INDEX('SKU Data'!$H$2:$H$95,MATCH($A15,'SKU Data'!$W$2:$W$95,0)),"") -> 762.09 | K15: =IFERROR(INDEX('SKU Data'!$N$2:$N$95,MATCH($A15,'SKU Data'!$W$2:$W$95,0)),"") -> 0.0004606142 | L15: =IFERROR(INDEX('SKU Data'!$O$2:$O$95,MATCH($A15,'SKU Data'!$W$2:$W$95,0)),"") -> 5.9162714e-05 | M15: =IFERROR(I15/Settings!$B$3,"") -> 1.1140046 | N15: =IFERROR(INDEX('SKU Data'!$AF$2:$AF$95,MATCH($A15,'SKU Data'!$W$2:$W$95,0)),"") -> 0.988779 | O15: =IFERROR(INDEX('SKU Data'!$Q$2:$Q$95,MATCH($A15,'SKU Data'!$W$2:$W$95,0)),"") -> 0.31620251 | P15: =IFERROR(INDEX('SKU Data'!$Y$2:$Y$95,MATCH($A15,'SKU Data'!$W$2:$W$95,0)),"")
A16: 12 | B16: =IFERROR(INDEX('SKU Data'!$X$2:$X$95,MATCH($A16,'SKU Data'!$W$2:$W$95,0)),"") -> 2 - Review | C16: =IFERROR(INDEX('SKU Data'!$A$2:$A$95,MATCH($A16,'SKU Data'!$W$2:$W$95,0)),"") -> DCS-01 | D16: =IFERROR(INDEX('SKU Data'!$B$2:$B$95,MATCH($A16,'SKU Data'!$W$2:$W$95,0)),"") -> Designer Sympathy Collection I | E16: =IFERROR(INDEX('SKU Data'!$C$2:$C$95,MATCH($A16,'SKU Data'!$W$2:$W$95,0)),"") -> Sympathy | F16: =IFERROR(INDEX('SKU Data'!$E$2:$E$95,MATCH($A16,'SKU Data'!$W$2:$W$95,0)),"") -> 47 | G16: =IFERROR(INDEX('SKU Data'!$F$2:$F$95,MATCH($A16,'SKU Data'!$W$2:$W$95,0)),"") -> 8 | H16: =IFERROR(INDEX('SKU Data'!$J$2:$J$95,MATCH($A16,'SKU Data'!$W$2:$W$95,0)),"") -> 6 | I16: =IFERROR(INDEX('SKU Data'!$L$2:$L$95,MATCH($A16,'SKU Data'!$W$2:$W$95,0)),"") -> 0.12765957 | J16: =IFERROR(INDEX('SKU Data'!$H$2:$H$95,MATCH($A16,'SKU Data'!$W$2:$W$95,0)),"") -> 609.82 | K16: =IFERROR(INDEX('SKU Data'!$N$2:$N$95,MATCH($A16,'SKU Data'!$W$2:$W$95,0)),"") -> 0.00036858081 | L16: =IFERROR(INDEX('SKU Data'!$O$2:$O$95,MATCH($A16,'SKU Data'!$W$2:$W$95,0)),"") -> 4.7341661e-05 | M16: =IFERROR(I16/Settings!$B$3,"") -> 1.9198803 | N16: =IFERROR(INDEX('SKU Data'!$AF$2:$AF$95,MATCH($A16,'SKU Data'!$W$2:$W$95,0)),"") -> 1.7040659 | O16: =IFERROR(INDEX('SKU Data'!$Q$2:$Q$95,MATCH($A16,'SKU Data'!$W$2:$W$95,0)),"") -> 1.683105 | P16: =IFERROR(INDEX('SKU Data'!$Y$2:$Y$95,MATCH($A16,'SKU Data'!$W$2:$W$95,0)),"")
... A29: 25 | B29: =IFERROR(INDEX('SKU Data'!$X$2:$X$95,MATCH($A29,'SKU Data'!$W$2:$W$95,0)),"") -> 2 - Review | C29: =IFERROR(INDEX('SKU Data'!$A$2:$A$95,MATCH($A29,'SKU Data'!$W$2:$W$95,0)),"") -> DCMJ-04A | D29: =IFERROR(INDEX('SKU Data'!$B$2:$B$95,MATCH($A29,'SKU Data'!$W$2:$W$95,0)),"") -> Designer Collection Mason Jar IV | E29: =IFERROR(INDEX('SKU Data'!$C$2:$C$95,MATCH($A29,'SKU Data'!$W$2:$W$95,0)),"") -> Mason Jar | F29: =IFERROR(INDEX('SKU Data'!$E$2:$E$95,MATCH($A29,'SKU Data'!$W$2:$W$95,0)),"") -> 133 | G29: =IFERROR(INDEX('SKU Data'!$F$2:$F$95,MATCH($A29,'SKU Data'!$W$2:$W$95,0)),"") -> 13 | H29: =IFERROR(INDEX('SKU Data'!$J$2:$J$95,MATCH($A29,'SKU Data'!$W$2:$W$95,0)),"") -> 8 | I29: =IFERROR(INDEX('SKU Data'!$L$2:$L$95,MATCH($A29,'SKU Data'!$W$2:$W$95,0)),"") -> 0.060150376 | J29: =IFERROR(INDEX('SKU Data'!$H$2:$H$95,MATCH($A29,'SKU Data'!$W$2:$W$95,0)),"") -> 1072.34 | K29: =IFERROR(INDEX('SKU Data'!$N$2:$N$95,MATCH($A29,'SKU Data'!$W$2:$W$95,0)),"") -> 0.00064813215 | L29: =IFERROR(INDEX('SKU Data'!$O$2:$O$95,MATCH($A29,'SKU Data'!$W$2:$W$95,0)),"") -> 8.3248101e-05 | M29: =IFERROR(I29/Settings!$B$3,"") -> 0.90460526 | N29: =IFERROR(INDEX('SKU Data'!$AF$2:$AF$95,MATCH($A29,'SKU Data'!$W$2:$W$95,0)),"") -> 0.80291829 | O29: =IFERROR(INDEX('SKU Data'!$Q$2:$Q$95,MATCH($A29,'SKU Data'!$W$2:$W$95,0)),"") -> -0.29361699 | P29: =IFERROR(INDEX('SKU Data'!$Y$2:$Y$95,MATCH($A29,'SKU Data'!$W$2:$W$95,0)),"")

Sheet Rankings
A1: Rankings - the three lenses
A2: Top 15 each. Units and $ use all months; rate uses the rate window (min units in Settings).
A3: 1) BY QUANTITY - most refunded units (all months)
A4: # | B4: SKU | C4: Product | D4: Line | E4: Units ordered (window) | F4: Refunded units (all months) | G4: Refund rate (window) | H4: Refund $ (all months) | I4: % of designer revenue | J4: % of total company revenue | K4: Baseline (designer avg)
A5: 1 | B5: =IFERROR(INDEX('SKU Data'!$A$2:$A$95,MATCH($A5,'SKU Data'!$Z$2:$Z$95,0)),"") -> DC-04S | C5: =IFERROR(INDEX('SKU Data'!$B$2:$B$95,MATCH($A5,'SKU Data'!$Z$2:$Z$95,0)),"") -> Designer Sympathy Collection IV | D5: =IFERROR(INDEX('SKU Data'!$C$2:$C$95,MATCH($A5,'SKU Data'!$Z$2:$Z$95,0)),"") -> Sympathy | E5: =IFERROR(INDEX('SKU Data'!$E$2:$E$95,MATCH($A5,'SKU Data'!$Z$2:$Z$95,0)),"") -> 1192 | F5: =IFERROR(INDEX('SKU Data'!$F$2:$F$95,MATCH($A5,'SKU Data'!$Z$2:$Z$95,0)),"") -> 75 | G5: =IFERROR(INDEX('SKU Data'!$L$2:$L$95,MATCH($A5,'SKU Data'!$Z$2:$Z$95,0)),"") -> 0.05704698 | H5: =IFERROR(INDEX('SKU Data'!$H$2:$H$95,MATCH($A5,'SKU Data'!$Z$2:$Z$95,0)),"") -> 8683.47 | I5: =IFERROR(INDEX('SKU Data'!$N$2:$N$95,MATCH($A5,'SKU Data'!$Z$2:$Z$95,0)),"") -> 0.005248369 | J5: =IFERROR(INDEX('SKU Data'!$O$2:$O$95,MATCH($A5,'SKU Data'!$Z$2:$Z$95,0)),"") -> 0.00067411678 | K5: =Settings!$B$3 -> 0.066493506
A6: 2 | B6: =IFERROR(INDEX('SKU Data'!$A$2:$A$95,MATCH($A6,'SKU Data'!$Z$2:$Z$95,0)),"") -> DC-02S | C6: =IFERROR(INDEX('SKU Data'!$B$2:$B$95,MATCH($A6,'SKU Data'!$Z$2:$Z$95,0)),"") -> Designer Sympathy Collection II | D6: =IFERROR(INDEX('SKU Data'!$C$2:$C$95,MATCH($A6,'SKU Data'!$Z$2:$Z$95,0)),"") -> Sympathy | E6: =IFERROR(INDEX('SKU Data'!$E$2:$E$95,MATCH($A6,'SKU Data'!$Z$2:$Z$95,0)),"") -> 849 | F6: =IFERROR(INDEX('SKU Data'!$F$2:$F$95,MATCH($A6,'SKU Data'!$Z$2:$Z$95,0)),"") -> 62 | G6: =IFERROR(INDEX('SKU Data'!$L$2:$L$95,MATCH($A6,'SKU Data'!$Z$2:$Z$95,0)),"") -> 0.069493522 | H6: =IFERROR(INDEX('SKU Data'!$H$2:$H$95,MATCH($A6,'SKU Data'!$Z$2:$Z$95,0)),"") -> 6122.41 | I6: =IFERROR(INDEX('SKU Data'!$N$2:$N$95,MATCH($A6,'SKU Data'!$Z$2:$Z$95,0)),"") -> 0.0037004409 | J6: =IFERROR(INDEX('SKU Data'!$O$2:$O$95,MATCH($A6,'SKU Data'!$Z$2:$Z$95,0)),"") -> 0.00047529608 | K6: =Settings!$B$3 -> 0.066493506
A7: 3 | B7: =IFERROR(INDEX('SKU Data'!$A$2:$A$95,MATCH($A7,'SKU Data'!$Z$2:$Z$95,0)),"") -> AUDNAT-02 | C7: =IFERROR(INDEX('SKU Data'!$B$2:$B$95,MATCH($A7,'SKU Data'!$Z$2:$Z$95,0)),"") -> Native Flowers Bouquet Designer Collection II | D7: =IFERROR(INDEX('SKU Data'!$C$2:$C$95,MATCH($A7,'SKU Data'!$Z$2:$Z$95,0)),"") -> Native Flowers | E7: =IFERROR(INDEX('SKU Data'!$E$2:$E$95,MATCH($A7,'SKU Data'!$Z$2:$Z$95,0)),"") -> 802 | F7: =IFERROR(INDEX('SKU Data'!$F$2:$F$95,MATCH($A7,'SKU Data'!$Z$2:$Z$95,0)),"") -> 62 | G7: =IFERROR(INDEX('SKU Data'!$L$2:$L$95,MATCH($A7,'SKU Data'!$Z$2:$Z$95,0)),"") -> 0.068578554 | H7: =IFERROR(INDEX('SKU Data'!$H$2:$H$95,MATCH($A7,'SKU Data'!$Z$2:$Z$95,0)),"") -> 6090.57 | I7: =IFERROR(INDEX('SKU Data'!$N$2:$N$95,MATCH($A7,'SKU Data'!$Z$2:$Z$95,0)),"") -> 0.0036811965 | J7: =IFERROR(INDEX('SKU Data'!$O$2:$O$95,MATCH($A7,'SKU Data'!$Z$2:$Z$95,0)),"") -> 0.00047282428 | K7: =Settings!$B$3 -> 0.066493506
A8: 4 | B8: =IFERROR(INDEX('SKU Data'!$A$2:$A$95,MATCH($A8,'SKU Data'!$Z$2:$Z$95,0)),"") -> DC-01S | C8: =IFERROR(INDEX('SKU Data'!$B$2:$B$95,MATCH($A8,'SKU Data'!$Z$2:$Z$95,0)),"") -> Designer Sympathy Collection I | D8: =IFERROR(INDEX('SKU Data'!$C$2:$C$95,MATCH($A8,'SKU Data'!$Z$2:$Z$95,0)),"") -> Sympathy | E8: =IFERROR(INDEX('SKU Data'!$E$2:$E$95,MATCH($A8,'SKU Data'!$Z$2:$Z$95,0)),"") -> 997 | F8: =IFERROR(INDEX('SKU Data'!$F$2:$F$95,MATCH($A8,'SKU Data'!$Z$2:$Z$95,0)),"") -> 60 | G8: =IFERROR(INDEX('SKU Data'!$L$2:$L$95,MATCH($A8,'SKU Data'!$Z$2:$Z$95,0)),"") -> 0.048144433 | H8: =IFERROR(INDEX('SKU Data'!$H$2:$H$95,MATCH($A8,'SKU Data'!$Z$2:$Z$95,0)),"") -> 4255.73 | I8: =IFERROR(INDEX('SKU Data'!$N$2:$N$95,MATCH($A8,'SKU Data'!$Z$2:$Z$95,0)),"") -> 0.0025722023 | J8: =IFERROR(INDEX('SKU Data'!$O$2:$O$95,MATCH($A8,'SKU Data'!$Z$2:$Z$95,0)),"") -> 0.00033038163 | K8: =Settings!$B$3 -> 0.066493506
A9: 5 | B9: =IFERROR(INDEX('SKU Data'!$A$2:$A$95,MATCH($A9,'SKU Data'!$Z$2:$Z$95,0)),"") -> DC-03S | C9: =IFERROR(INDEX('SKU Data'!$B$2:$B$95,MATCH($A9,'SKU Data'!$Z$2:$Z$95,0)),"") -> Designer Sympathy Collection III | D9: =IFERROR(INDEX('SKU Data'!$C$2:$C$95,MATCH($A9,'SKU Data'!$Z$2:$Z$95,0)),"") -> Sympathy | E9: =IFERROR(INDEX('SKU Data'!$E$2:$E$95,MATCH($A9,'SKU Data'!$Z$2:$Z$95,0)),"") -> 549 | F9: =IFERROR(INDEX('SKU Data'!$F$2:$F$95,MATCH($A9,'SKU Data'!$Z$2:$Z$95,0)),"") -> 39 | G9: =IFERROR(INDEX('SKU Data'!$L$2:$L$95,MATCH($A9,'SKU Data'!$Z$2:$Z$95,0)),"") -> 0.052823315 | H9: =IFERROR(INDEX('SKU Data'!$H$2:$H$95,MATCH($A9,'SKU Data'!$Z$2:$Z$95,0)),"") -> 4565.17 | I9: =IFERROR(INDEX('SKU Data'!$N$2:$N$95,MATCH($A9,'SKU Data'!$Z$2:$Z$95,0)),"") -> 0.0027592307 | J9: =IFERROR(INDEX('SKU Data'!$O$2:$O$95,MATCH($A9,'SKU Data'!$Z$2:$Z$95,0)),"") -> 0.00035440414 | K9: =Settings!$B$3 -> 0.066493506
A10: 6 | B10: =IFERROR(INDEX('SKU Data'!$A$2:$A$95,MATCH($A10,'SKU Data'!$Z$2:$Z$95,0)),"") -> DC-01B | C10: =IFERROR(INDEX('SKU Data'!$B$2:$B$95,MATCH($A10,'SKU Data'!$Z$2:$Z$95,0)),"") -> Birthday Designer Collection I | D10: =IFERROR(INDEX('SKU Data'!$C$2:$C$95,MATCH($A10,'SKU Data'!$Z$2:$Z$95,0)),"") -> Birthday | E10: =IFERROR(INDEX('SKU Data'!$E$2:$E$95,MATCH($A10,'SKU Data'!$Z$2:$Z$95,0)),"") -> 551 | F10: =IFERROR(INDEX('SKU Data'!$F$2:$F$95,MATCH($A10,'SKU Data'!$Z$2:$Z$95,0)),"") -> 36 | G10: =IFERROR(INDEX('SKU Data'!$L$2:$L$95,MATCH($A10,'SKU Data'!$Z$2:$Z$95,0)),"") -> 0.063520871 | H10: =IFERROR(INDEX('SKU Data'!$H$2:$H$95,MATCH($A10,'SKU Data'!$Z$2:$Z$95,0)),"") -> 2433.11 | I10: =IFERROR(INDEX('SKU Data'!$N$2:$N$95,MATCH($A10,'SKU Data'!$Z$2:$Z$95,0)),"") -> 0.001470594 | J10: =IFERROR(INDEX('SKU Data'!$O$2:$O$95,MATCH($A10,'SKU Data'!$Z$2:$Z$95,0)),"") -> 0.00018888765 | K10: =Settings!$B$3 -> 0.066493506
A11: 7 | B11: =IFERROR(INDEX('SKU Data'!$A$2:$A$95,MATCH($A11,'SKU Data'!$Z$2:$Z$95,0)),"") -> AUDNAT-01 | C11: =IFERROR(INDEX('SKU Data'!$B$2:$B$95,MATCH($A11,'SKU Data'!$Z$2:$Z$95,0)),"") -> Native Flowers Bouquet Designer Collection I | D11: =IFERROR(INDEX('SKU Data'!$C$2:$C$95,MATCH($A11,'SKU Data'!$Z$2:$Z$95,0)),"") -> Native Flowers | E11: =IFERROR(INDEX('SKU Data'!$E$2:$E$95,MATCH($A11,'SKU Data'!$Z$2:$Z$95,0)),"") -> 374 | F11: =IFERROR(INDEX('SKU Data'!$F$2:$F$95,MATCH($A11,'SKU Data'!$Z$2:$Z$95,0)),"") -> 34 | G11: =IFERROR(INDEX('SKU Data'!$L$2:$L$95,MATCH($A11,'SKU Data'!$Z$2:$Z$95,0)),"") -> 0.069518717 | H11: =IFERROR(INDEX('SKU Data'!$H$2:$H$95,MATCH($A11,'SKU Data'!$Z$2:$Z$95,0)),"") -> 2872.37 | I11: =IFERROR(INDEX('SKU Data'!$N$2:$N$95,MATCH($A11,'SKU Data'!$Z$2:$Z$95,0)),"") -> 0.0017360868 | J11: =IFERROR(INDEX('SKU Data'!$O$2:$O$95,MATCH($A11,'SKU Data'!$Z$2:$Z$95,0)),"") -> 0.00022298837 | K11: =Settings!$B$3 -> 0.066493506
A12: 8 | B12: =IFERROR(INDEX('SKU Data'!$A$2:$A$95,MATCH($A12,'SKU Data'!$Z$2:$Z$95,0)),"") -> AUDNAT-03 | C12: =IFERROR(INDEX('SKU Data'!$B$2:$B$95,MATCH($A12,'SKU Data'!$Z$2:$Z$95,0)),"") -> Native Flowers Bouquet Designer Collection III | D12: =IFERROR(INDEX('SKU Data'!$C$2:$C$95,MATCH($A12,'SKU Data'!$Z$2:$Z$95,0)),"") -> Native Flowers | E12: =IFERROR(INDEX('SKU Data'!$E$2:$E$95,MATCH($A12,'SKU Data'!$Z$2:$Z$95,0)),"") -> 353 | F12: =IFERROR(INDEX('SKU Data'!$F$2:$F$95,MATCH($A12,'SKU Data'!$Z$2:$Z$95,0)),"") -> 31 | G12: =IFERROR(INDEX('SKU Data'!$L$2:$L$95,MATCH($A12,'SKU Data'!$Z$2:$Z$95,0)),"") -> 0.07082153 | H12: =IFERROR(INDEX('SKU Data'!$H$2:$H$95,MATCH($A12,'SKU Data'!$Z$2:$Z$95,0)),"") -> 4128.81 | I12: =IFERROR(INDEX('SKU Data'!$N$2:$N$95,MATCH($A12,'SKU Data'!$Z$2:$Z$95,0)),"") -> 0.0024954907 | J12: =IFERROR(INDEX('SKU Data'!$O$2:$O$95,MATCH($A12,'SKU Data'!$Z$2:$Z$95,0)),"") -> 0.00032052855 | K12: =Settings!$B$3 -> 0.066493506
A13: 9 | B13: =IFERROR(INDEX('SKU Data'!$A$2:$A$95,MATCH($A13,'SKU Data'!$Z$2:$Z$95,0)),"") -> DC-02B | C13: =IFERROR(INDEX('SKU Data'!$B$2:$B$95,MATCH($A13,'SKU Data'!$Z$2:$Z$95,0)),"") -> Birthday Designer Collection II | D13: =IFERROR(INDEX('SKU Data'!$C$2:$C$95,MATCH($A13,'SKU Data'!$Z$2:$Z$95,0)),"") -> Birthday | E13: =IFERROR(INDEX('SKU Data'!$E$2:$E$95,MATCH($A13,'SKU Data'!$Z$2:$Z$95,0)),"") -> 223 | F13: =IFERROR(INDEX('SKU Data'!$F$2:$F$95,MATCH($A13,'SKU Data'!$Z$2:$Z$95,0)),"") -> 28 | G13: =IFERROR(INDEX('SKU Data'!$L$2:$L$95,MATCH($A13,'SKU Data'!$Z$2:$Z$95,0)),"") -> 0.11210762 | H13: =IFERROR(INDEX('SKU Data'!$H$2:$H$95,MATCH($A13,'SKU Data'!$Z$2:$Z$95,0)),"") -> 2889.28 | I13: =IFERROR(INDEX('SKU Data'!$N$2:$N$95,MATCH($A13,'SKU Data'!$Z$2:$Z$95,0)),"") -> 0.0017463074 | J13: =IFERROR(INDEX('SKU Data'!$O$2:$O$95,MATCH($A13,'SKU Data'!$Z$2:$Z$95,0)),"") -> 0.00022430113 | K13: =Settings!$B$3 -> 0.066493506
A14: 10 | B14: =IFERROR(INDEX('SKU Data'!$A$2:$A$95,MATCH($A14,'SKU Data'!$Z$2:$Z$95,0)),"") -> DCMJ-01 | C14: =IFERROR(INDEX('SKU Data'!$B$2:$B$95,MATCH($A14,'SKU Data'!$Z$2:$Z$95,0)),"") -> Designer Collection Mason Jar I | D14: =IFERROR(INDEX('SKU Data'!$C$2:$C$95,MATCH($A14,'SKU Data'!$Z$2:$Z$95,0)),"") -> Mason Jar | E14: =IFERROR(INDEX('SKU Data'!$E$2:$E$95,MATCH($A14,'SKU Data'!$Z$2:$Z$95,0)),"") -> 110 | F14: =IFERROR(INDEX('SKU Data'!$F$2:$F$95,MATCH($A14,'SKU Data'!$Z$2:$Z$95,0)),"") -> 18 | G14: =IFERROR(INDEX('SKU Data'!$L$2:$L$95,MATCH($A14,'SKU Data'!$Z$2:$Z$95,0)),"") -> 0.12727273 | H14: =IFERROR(INDEX('SKU Data'!$H$2:$H$95,MATCH($A14,'SKU Data'!$Z$2:$Z$95,0)),"") -> 941.68 | I14: =IFERROR(INDEX('SKU Data'!$N$2:$N$95,MATCH($A14,'SKU Data'!$Z$2:$Z$95,0)),"") -> 0.00056916004 | J14: =IFERROR(INDEX('SKU Data'!$O$2:$O$95,MATCH($A14,'SKU Data'!$Z$2:$Z$95,0)),"") -> 7.3104679e-05 | K14: =Settings!$B$3 -> 0.066493506
A15: 11 | B15: =IFERROR(INDEX('SKU Data'!$A$2:$A$95,MATCH($A15,'SKU Data'!$Z$2:$Z$95,0)),"") -> DCMJ-04A | C15: =IFERROR(INDEX('SKU Data'!$B$2:$B$95,MATCH($A15,'SKU Data'!$Z$2:$Z$95,0)),"") -> Designer Collection Mason Jar IV | D15: =IFERROR(INDEX('SKU Data'!$C$2:$C$95,MATCH($A15,'SKU Data'!$Z$2:$Z$95,0)),"") -> Mason Jar | E15: =IFERROR(INDEX('SKU Data'!$E$2:$E$95,MATCH($A15,'SKU Data'!$Z$2:$Z$95,0)),"") -> 133 | F15: =IFERROR(INDEX('SKU Data'!$F$2:$F$95,MATCH($A15,'SKU Data'!$Z$2:$Z$95,0)),"") -> 13 | G15: =IFERROR(INDEX('SKU Data'!$L$2:$L$95,MATCH($A15,'SKU Data'!$Z$2:$Z$95,0)),"") -> 0.060150376 | H15: =IFERROR(INDEX('SKU Data'!$H$2:$H$95,MATCH($A15,'SKU Data'!$Z$2:$Z$95,0)),"") -> 1072.34 | I15: =IFERROR(INDEX('SKU Data'!$N$2:$N$95,MATCH($A15,'SKU Data'!$Z$2:$Z$95,0)),"") -> 0.00064813215 | J15: =IFERROR(INDEX('SKU Data'!$O$2:$O$95,MATCH($A15,'SKU Data'!$Z$2:$Z$95,0)),"") -> 8.3248101e-05 | K15: =Settings!$B$3 -> 0.066493506
A16: 12 | B16: =IFERROR(INDEX('SKU Data'!$A$2:$A$95,MATCH($A16,'SKU Data'!$Z$2:$Z$95,0)),"") -> DCB-02 | C16: =IFERROR(INDEX('SKU Data'!$B$2:$B$95,MATCH($A16,'SKU Data'!$Z$2:$Z$95,0)),"") -> Birthday Designer Collection II | D16: =IFERROR(INDEX('SKU Data'!$C$2:$C$95,MATCH($A16,'SKU Data'!$Z$2:$Z$95,0)),"") -> Birthday | E16: =IFERROR(INDEX('SKU Data'!$E$2:$E$95,MATCH($A16,'SKU Data'!$Z$2:$Z$95,0)),"") -> 87 | F16: =IFERROR(INDEX('SKU Data'!$F$2:$F$95,MATCH($A16,'SKU Data'!$Z$2:$Z$95,0)),"") -> 12 | G16: =IFERROR(INDEX('SKU Data'!$L$2:$L$95,MATCH($A16,'SKU Data'!$Z$2:$Z$95,0)),"") -> 0.11494253 | H16: =IFERROR(INDEX('SKU Data'!$H$2:$H$95,MATCH($A16,'SKU Data'!$Z$2:$Z$95,0)),"") -> 1216.35 | I16: =IFERROR(INDEX('SKU Data'!$N$2:$N$95,MATCH($A16,'SKU Data'!$Z$2:$Z$95,0)),"") -> 0.00073517311 | J16: =IFERROR(INDEX('SKU Data'!$O$2:$O$95,MATCH($A16,'SKU Data'!$Z$2:$Z$95,0)),"") -> 9.4427912e-05 | K16: =Settings!$B$3 -> 0.066493506
... A19: 15 | B19: =IFERROR(INDEX('SKU Data'!$A$2:$A$95,MATCH($A19,'SKU Data'!$Z$2:$Z$95,0)),"") -> DC-01A | C19: =IFERROR(INDEX('SKU Data'!$B$2:$B$95,MATCH($A19,'SKU Data'!$Z$2:$Z$95,0)),"") -> Designer Collection Anniversary I | D19: =IFERROR(INDEX('SKU Data'!$C$2:$C$95,MATCH($A19,'SKU Data'!$Z$2:$Z$95,0)),"") -> Anniversary | E19: =IFERROR(INDEX('SKU Data'!$E$2:$E$95,MATCH($A19,'SKU Data'!$Z$2:$Z$95,0)),"") -> 158 | F19: =IFERROR(INDEX('SKU Data'!$F$2:$F$95,MATCH($A19,'SKU Data'!$Z$2:$Z$95,0)),"") -> 9 | G19: =IFERROR(INDEX('SKU Data'!$L$2:$L$95,MATCH($A19,'SKU Data'!$Z$2:$Z$95,0)),"") -> 0.050632911 | H19: =IFERROR(INDEX('SKU Data'!$H$2:$H$95,MATCH($A19,'SKU Data'!$Z$2:$Z$95,0)),"") -> 669.8 | I19: =IFERROR(INDEX('SKU Data'!$N$2:$N$95,MATCH($A19,'SKU Data'!$Z$2:$Z$95,0)),"") -> 0.00040483327 | J19: =IFERROR(INDEX('SKU Data'!$O$2:$O$95,MATCH($A19,'SKU Data'!$Z$2:$Z$95,0)),"") -> 5.199804e-05 | K19: =Settings!$B$3 -> 0.066493506
A22: 2) BY REVENUE IMPACT - largest refund $ (all months)
A23: # | B23: SKU | C23: Product | D23: Line | E23: Units ordered (window) | F23: Refunded units (all months) | G23: Refund rate (window) | H23: Refund $ (all months) | I23: % of designer revenue | J23: % of total company revenue | K23: Baseline (designer avg)
A24: 1 | B24: =IFERROR(INDEX('SKU Data'!$A$2:$A$95,MATCH($A24,'SKU Data'!$AA$2:$AA$95,0)),"") -> DC-04S | C24: =IFERROR(INDEX('SKU Data'!$B$2:$B$95,MATCH($A24,'SKU Data'!$AA$2:$AA$95,0)),"") -> Designer Sympathy Collection IV | D24: =IFERROR(INDEX('SKU Data'!$C$2:$C$95,MATCH($A24,'SKU Data'!$AA$2:$AA$95,0)),"") -> Sympathy | E24: =IFERROR(INDEX('SKU Data'!$E$2:$E$95,MATCH($A24,'SKU Data'!$AA$2:$AA$95,0)),"") -> 1192 | F24: =IFERROR(INDEX('SKU Data'!$F$2:$F$95,MATCH($A24,'SKU Data'!$AA$2:$AA$95,0)),"") -> 75 | G24: =IFERROR(INDEX('SKU Data'!$L$2:$L$95,MATCH($A24,'SKU Data'!$AA$2:$AA$95,0)),"") -> 0.05704698 | H24: =IFERROR(INDEX('SKU Data'!$H$2:$H$95,MATCH($A24,'SKU Data'!$AA$2:$AA$95,0)),"") -> 8683.47 | I24: =IFERROR(INDEX('SKU Data'!$N$2:$N$95,MATCH($A24,'SKU Data'!$AA$2:$AA$95,0)),"") -> 0.005248369 | J24: =IFERROR(INDEX('SKU Data'!$O$2:$O$95,MATCH($A24,'SKU Data'!$AA$2:$AA$95,0)),"") -> 0.00067411678 | K24: =Settings!$B$3 -> 0.066493506
A25: 2 | B25: =IFERROR(INDEX('SKU Data'!$A$2:$A$95,MATCH($A25,'SKU Data'!$AA$2:$AA$95,0)),"") -> DC-02S | C25: =IFERROR(INDEX('SKU Data'!$B$2:$B$95,MATCH($A25,'SKU Data'!$AA$2:$AA$95,0)),"") -> Designer Sympathy Collection II | D25: =IFERROR(INDEX('SKU Data'!$C$2:$C$95,MATCH($A25,'SKU Data'!$AA$2:$AA$95,0)),"") -> Sympathy | E25: =IFERROR(INDEX('SKU Data'!$E$2:$E$95,MATCH($A25,'SKU Data'!$AA$2:$AA$95,0)),"") -> 849 | F25: =IFERROR(INDEX('SKU Data'!$F$2:$F$95,MATCH($A25,'SKU Data'!$AA$2:$AA$95,0)),"") -> 62 | G25: =IFERROR(INDEX('SKU Data'!$L$2:$L$95,MATCH($A25,'SKU Data'!$AA$2:$AA$95,0)),"") -> 0.069493522 | H25: =IFERROR(INDEX('SKU Data'!$H$2:$H$95,MATCH($A25,'SKU Data'!$AA$2:$AA$95,0)),"") -> 6122.41 | I25: =IFERROR(INDEX('SKU Data'!$N$2:$N$95,MATCH($A25,'SKU Data'!$AA$2:$AA$95,0)),"") -> 0.0037004409 | J25: =IFERROR(INDEX('SKU Data'!$O$2:$O$95,MATCH($A25,'SKU Data'!$AA$2:$AA$95,0)),"") -> 0.00047529608 | K25: =Settings!$B$3 -> 0.066493506
A26: 3 | B26: =IFERROR(INDEX('SKU Data'!$A$2:$A$95,MATCH($A26,'SKU Data'!$AA$2:$AA$95,0)),"") -> AUDNAT-02 | C26: =IFERROR(INDEX('SKU Data'!$B$2:$B$95,MATCH($A26,'SKU Data'!$AA$2:$AA$95,0)),"") -> Native Flowers Bouquet Designer Collection II | D26: =IFERROR(INDEX('SKU Data'!$C$2:$C$95,MATCH($A26,'SKU Data'!$AA$2:$AA$95,0)),"") -> Native Flowers | E26: =IFERROR(INDEX('SKU Data'!$E$2:$E$95,MATCH($A26,'SKU Data'!$AA$2:$AA$95,0)),"") -> 802 | F26: =IFERROR(INDEX('SKU Data'!$F$2:$F$95,MATCH($A26,'SKU Data'!$AA$2:$AA$95,0)),"") -> 62 | G26: =IFERROR(INDEX('SKU Data'!$L$2:$L$95,MATCH($A26,'SKU Data'!$AA$2:$AA$95,0)),"") -> 0.068578554 | H26: =IFERROR(INDEX('SKU Data'!$H$2:$H$95,MATCH($A26,'SKU Data'!$AA$2:$AA$95,0)),"") -> 6090.57 | I26: =IFERROR(INDEX('SKU Data'!$N$2:$N$95,MATCH($A26,'SKU Data'!$AA$2:$AA$95,0)),"") -> 0.0036811965 | J26: =IFERROR(INDEX('SKU Data'!$O$2:$O$95,MATCH($A26,'SKU Data'!$AA$2:$AA$95,0)),"") -> 0.00047282428 | K26: =Settings!$B$3 -> 0.066493506
A27: 4 | B27: =IFERROR(INDEX('SKU Data'!$A$2:$A$95,MATCH($A27,'SKU Data'!$AA$2:$AA$95,0)),"") -> DC-03S | C27: =IFERROR(INDEX('SKU Data'!$B$2:$B$95,MATCH($A27,'SKU Data'!$AA$2:$AA$95,0)),"") -> Designer Sympathy Collection III | D27: =IFERROR(INDEX('SKU Data'!$C$2:$C$95,MATCH($A27,'SKU Data'!$AA$2:$AA$95,0)),"") -> Sympathy | E27: =IFERROR(INDEX('SKU Data'!$E$2:$E$95,MATCH($A27,'SKU Data'!$AA$2:$AA$95,0)),"") -> 549 | F27: =IFERROR(INDEX('SKU Data'!$F$2:$F$95,MATCH($A27,'SKU Data'!$AA$2:$AA$95,0)),"") -> 39 | G27: =IFERROR(INDEX('SKU Data'!$L$2:$L$95,MATCH($A27,'SKU Data'!$AA$2:$AA$95,0)),"") -> 0.052823315 | H27: =IFERROR(INDEX('SKU Data'!$H$2:$H$95,MATCH($A27,'SKU Data'!$AA$2:$AA$95,0)),"") -> 4565.17 | I27: =IFERROR(INDEX('SKU Data'!$N$2:$N$95,MATCH($A27,'SKU Data'!$AA$2:$AA$95,0)),"") -> 0.0027592307 | J27: =IFERROR(INDEX('SKU Data'!$O$2:$O$95,MATCH($A27,'SKU Data'!$AA$2:$AA$95,0)),"") -> 0.00035440414 | K27: =Settings!$B$3 -> 0.066493506
A28: 5 | B28: =IFERROR(INDEX('SKU Data'!$A$2:$A$95,MATCH($A28,'SKU Data'!$AA$2:$AA$95,0)),"") -> DC-01S | C28: =IFERROR(INDEX('SKU Data'!$B$2:$B$95,MATCH($A28,'SKU Data'!$AA$2:$AA$95,0)),"") -> Designer Sympathy Collection I | D28: =IFERROR(INDEX('SKU Data'!$C$2:$C$95,MATCH($A28,'SKU Data'!$AA$2:$AA$95,0)),"") -> Sympathy | E28: =IFERROR(INDEX('SKU Data'!$E$2:$E$95,MATCH($A28,'SKU Data'!$AA$2:$AA$95,0)),"") -> 997 | F28: =IFERROR(INDEX('SKU Data'!$F$2:$F$95,MATCH($A28,'SKU Data'!$AA$2:$AA$95,0)),"") -> 60 | G28: =IFERROR(INDEX('SKU Data'!$L$2:$L$95,MATCH($A28,'SKU Data'!$AA$2:$AA$95,0)),"") -> 0.048144433 | H28: =IFERROR(INDEX('SKU Data'!$H$2:$H$95,MATCH($A28,'SKU Data'!$AA$2:$AA$95,0)),"") -> 4255.73 | I28: =IFERROR(INDEX('SKU Data'!$N$2:$N$95,MATCH($A28,'SKU Data'!$AA$2:$AA$95,0)),"") -> 0.0025722023 | J28: =IFERROR(INDEX('SKU Data'!$O$2:$O$95,MATCH($A28,'SKU Data'!$AA$2:$AA$95,0)),"") -> 0.00033038163 | K28: =Settings!$B$3 -> 0.066493506
A29: 6 | B29: =IFERROR(INDEX('SKU Data'!$A$2:$A$95,MATCH($A29,'SKU Data'!$AA$2:$AA$95,0)),"") -> AUDNAT-03 | C29: =IFERROR(INDEX('SKU Data'!$B$2:$B$95,MATCH($A29,'SKU Data'!$AA$2:$AA$95,0)),"") -> Native Flowers Bouquet Designer Collection III | D29: =IFERROR(INDEX('SKU Data'!$C$2:$C$95,MATCH($A29,'SKU Data'!$AA$2:$AA$95,0)),"") -> Native Flowers | E29: =IFERROR(INDEX('SKU Data'!$E$2:$E$95,MATCH($A29,'SKU Data'!$AA$2:$AA$95,0)),"") -> 353 | F29: =IFERROR(INDEX('SKU Data'!$F$2:$F$95,MATCH($A29,'SKU Data'!$AA$2:$AA$95,0)),"") -> 31 | G29: =IFERROR(INDEX('SKU Data'!$L$2:$L$95,MATCH($A29,'SKU Data'!$AA$2:$AA$95,0)),"") -> 0.07082153 | H29: =IFERROR(INDEX('SKU Data'!$H$2:$H$95,MATCH($A29,'SKU Data'!$AA$2:$AA$95,0)),"") -> 4128.81 | I29: =IFERROR(INDEX('SKU Data'!$N$2:$N$95,MATCH($A29,'SKU Data'!$AA$2:$AA$95,0)),"") -> 0.0024954907 | J29: =IFERROR(INDEX('SKU Data'!$O$2:$O$95,MATCH($A29,'SKU Data'!$AA$2:$AA$95,0)),"") -> 0.00032052855 | K29: =Settings!$B$3 -> 0.066493506
A30: 7 | B30: =IFERROR(INDEX('SKU Data'!$A$2:$A$95,MATCH($A30,'SKU Data'!$AA$2:$AA$95,0)),"") -> DC-02B | C30: =IFERROR(INDEX('SKU Data'!$B$2:$B$95,MATCH($A30,'SKU Data'!$AA$2:$AA$95,0)),"") -> Birthday Designer Collection II | D30: =IFERROR(INDEX('SKU Data'!$C$2:$C$95,MATCH($A30,'SKU Data'!$AA$2:$AA$95,0)),"") -> Birthday | E30: =IFERROR(INDEX('SKU Data'!$E$2:$E$95,MATCH($A30,'SKU Data'!$AA$2:$AA$95,0)),"") -> 223 | F30: =IFERROR(INDEX('SKU Data'!$F$2:$F$95,MATCH($A30,'SKU Data'!$AA$2:$AA$95,0)),"") -> 28 | G30: =IFERROR(INDEX('SKU Data'!$L$2:$L$95,MATCH($A30,'SKU Data'!$AA$2:$AA$95,0)),"") -> 0.11210762 | H30: =IFERROR(INDEX('SKU Data'!$H$2:$H$95,MATCH($A30,'SKU Data'!$AA$2:$AA$95,0)),"") -> 2889.28 | I30: =IFERROR(INDEX('SKU Data'!$N$2:$N$95,MATCH($A30,'SKU Data'!$AA$2:$AA$95,0)),"") -> 0.0017463074 | J30: =IFERROR(INDEX('SKU Data'!$O$2:$O$95,MATCH($A30,'SKU Data'!$AA$2:$AA$95,0)),"") -> 0.00022430113 | K30: =Settings!$B$3 -> 0.066493506
A31: 8 | B31: =IFERROR(INDEX('SKU Data'!$A$2:$A$95,MATCH($A31,'SKU Data'!$AA$2:$AA$95,0)),"") -> AUDNAT-01 | C31: =IFERROR(INDEX('SKU Data'!$B$2:$B$95,MATCH($A31,'SKU Data'!$AA$2:$AA$95,0)),"") -> Native Flowers Bouquet Designer Collection I | D31: =IFERROR(INDEX('SKU Data'!$C$2:$C$95,MATCH($A31,'SKU Data'!$AA$2:$AA$95,0)),"") -> Native Flowers | E31: =IFERROR(INDEX('SKU Data'!$E$2:$E$95,MATCH($A31,'SKU Data'!$AA$2:$AA$95,0)),"") -> 374 | F31: =IFERROR(INDEX('SKU Data'!$F$2:$F$95,MATCH($A31,'SKU Data'!$AA$2:$AA$95,0)),"") -> 34 | G31: =IFERROR(INDEX('SKU Data'!$L$2:$L$95,MATCH($A31,'SKU Data'!$AA$2:$AA$95,0)),"") -> 0.069518717 | H31: =IFERROR(INDEX('SKU Data'!$H$2:$H$95,MATCH($A31,'SKU Data'!$AA$2:$AA$95,0)),"") -> 2872.37 | I31: =IFERROR(INDEX('SKU Data'!$N$2:$N$95,MATCH($A31,'SKU Data'!$AA$2:$AA$95,0)),"") -> 0.0017360868 | J31: =IFERROR(INDEX('SKU Data'!$O$2:$O$95,MATCH($A31,'SKU Data'!$AA$2:$AA$95,0)),"") -> 0.00022298837 | K31: =Settings!$B$3 -> 0.066493506
A32: 9 | B32: =IFERROR(INDEX('SKU Data'!$A$2:$A$95,MATCH($A32,'SKU Data'!$AA$2:$AA$95,0)),"") -> DC-01B | C32: =IFERROR(INDEX('SKU Data'!$B$2:$B$95,MATCH($A32,'SKU Data'!$AA$2:$AA$95,0)),"") -> Birthday Designer Collection I | D32: =IFERROR(INDEX('SKU Data'!$C$2:$C$95,MATCH($A32,'SKU Data'!$AA$2:$AA$95,0)),"") -> Birthday | E32: =IFERROR(INDEX('SKU Data'!$E$2:$E$95,MATCH($A32,'SKU Data'!$AA$2:$AA$95,0)),"") -> 551 | F32: =IFERROR(INDEX('SKU Data'!$F$2:$F$95,MATCH($A32,'SKU Data'!$AA$2:$AA$95,0)),"") -> 36 | G32: =IFERROR(INDEX('SKU Data'!$L$2:$L$95,MATCH($A32,'SKU Data'!$AA$2:$AA$95,0)),"") -> 0.063520871 | H32: =IFERROR(INDEX('SKU Data'!$H$2:$H$95,MATCH($A32,'SKU Data'!$AA$2:$AA$95,0)),"") -> 2433.11 | I32: =IFERROR(INDEX('SKU Data'!$N$2:$N$95,MATCH($A32,'SKU Data'!$AA$2:$AA$95,0)),"") -> 0.001470594 | J32: =IFERROR(INDEX('SKU Data'!$O$2:$O$95,MATCH($A32,'SKU Data'!$AA$2:$AA$95,0)),"") -> 0.00018888765 | K32: =Settings!$B$3 -> 0.066493506
A33: 10 | B33: =IFERROR(INDEX('SKU Data'!$A$2:$A$95,MATCH($A33,'SKU Data'!$AA$2:$AA$95,0)),"") -> DCB-02 | C33: =IFERROR(INDEX('SKU Data'!$B$2:$B$95,MATCH($A33,'SKU Data'!$AA$2:$AA$95,0)),"") -> Birthday Designer Collection II | D33: =IFERROR(INDEX('SKU Data'!$C$2:$C$95,MATCH($A33,'SKU Data'!$AA$2:$AA$95,0)),"") -> Birthday | E33: =IFERROR(INDEX('SKU Data'!$E$2:$E$95,MATCH($A33,'SKU Data'!$AA$2:$AA$95,0)),"") -> 87 | F33: =IFERROR(INDEX('SKU Data'!$F$2:$F$95,MATCH($A33,'SKU Data'!$AA$2:$AA$95,0)),"") -> 12 | G33: =IFERROR(INDEX('SKU Data'!$L$2:$L$95,MATCH($A33,'SKU Data'!$AA$2:$AA$95,0)),"") -> 0.11494253 | H33: =IFERROR(INDEX('SKU Data'!$H$2:$H$95,MATCH($A33,'SKU Data'!$AA$2:$AA$95,0)),"") -> 1216.35 | I33: =IFERROR(INDEX('SKU Data'!$N$2:$N$95,MATCH($A33,'SKU Data'!$AA$2:$AA$95,0)),"") -> 0.00073517311 | J33: =IFERROR(INDEX('SKU Data'!$O$2:$O$95,MATCH($A33,'SKU Data'!$AA$2:$AA$95,0)),"") -> 9.4427912e-05 | K33: =Settings!$B$3 -> 0.066493506
