Workbook

Sheet Dashboard
A1: Refunds & Returns - Problem Product Report
A2: All stores | 2026-01-01 to 2026-10-10 | ranked by units, revenue impact and refund rate on own sales
B4: Gross sales (export) | D4: Refunds (all lines) | F4: …with NO SKU | H4: Refund rate (units) | J4: SKUs flagged HIGH RATE | L4: Top 25 SKUs = % of SKU refund $
B5: =Settings!$B$20 -> 12880888 | D5: =Settings!$B$21 -> 1045073.5 | F5: =Settings!$B$13 -> 542319.62 | H5: =Settings!$B$3 -> 0.030986151 | J5: =COUNTIF('SKU Data'!$X$2:$X$1780,"HIGH RATE") -> 60 | L5: =SUMIFS('SKU Data'!$H$2:$H$1780,'SKU Data'!$Z$2:$Z$1780,"<=25")/Settings!$B$16 -> 0.44728161
A8: Key findings (at export date)
A9: 1. $542,320 (52%) of all refunded sales carry NO SKU / product - cannot be attributed. Investigate first (see Review List #1).
A10: 2. AUMJ-NW-005 (Native Flowers Bouquet in Mason Jar) is the #1 refund $ and #1 units: $30,439, 335 units, 5.3% vs 3.1% baseline. The AU + AUMJ families = 51% of SKU-attributed refund $ with rates 4.3% / 4.8% (z>12): a family-wide issue, not isolated SKUs.
A11: 3. 60 SKUs have refund rates statistically above baseline; the top 25 SKUs hold 45% of SKU-attributed refund $ - fixing a short list moves the total. Worst high-ticket rate offenders: AU100-545 (11.7%), AU189-01 (11.3%), DC-02B (8.7%), AU501-05 (8.7%).
A12: 4. Best-in-class: MDM (2.1%), DCMJ (2.5%), AUDC (2.4%) are well below baseline - benchmark candidates. MJ family sits at baseline (3.1%) while AUMJ (similar mason-jar concept) is at 4.8%.
A13: 5. Date / month spikes could NOT be tested: the export has no date, store or brand column. Re-export with Month/Day + Store (see Anomalies tab, section A).
A15: Top 10 priority SKUs (full list: Priority SKUs tab)
A16: Rank | B16: SKU | C16: Product | D16: Brand | E16: Qty ordered | F16: Refunded units | G16: Refund rate | H16: Refund $ | I16: % of total revenue | J16: Tier
A17: ='Priority SKUs'!A5 -> 1 | B17: ='Priority SKUs'!C5 -> AUMJ-NW-008 | C17: ='Priority SKUs'!D5 -> Golden Hour Bouquet in Mason Jar | D17: ='Priority SKUs'!E5 -> AUMJ | E17: ='Priority SKUs'!F5 -> 503 | F17: ='Priority SKUs'!G5 -> 40 | G17: ='Priority SKUs'!H5 -> 0.079522863 | H17: ='Priority SKUs'!I5 -> 3723.61 | I17: ='Priority SKUs'!L5 -> 0.00028908023 | J17: ='Priority SKUs'!B5 -> 1 - Fix first
A18: ='Priority SKUs'!A6 -> 2 | B18: ='Priority SKUs'!C6 -> AU0511-17 | C18: ='Priority SKUs'!D6 -> Summer Blooms | D18: ='Priority SKUs'!E6 -> AU | E18: ='Priority SKUs'!F6 -> 1560 | F18: ='Priority SKUs'!G6 -> 97 | G18: ='Priority SKUs'!H6 -> 0.062179487 | H18: ='Priority SKUs'!I6 -> 5315.16 | I18: ='Priority SKUs'!L6 -> 0.00041263926 | J18: ='Priority SKUs'!B6 -> 1 - Fix first
A19: ='Priority SKUs'!A7 -> 3 | B19: ='Priority SKUs'!C7 -> AU501-05 | C19: ='Priority SKUs'!D7 -> Half Dozen Red Roses, Card & Teddy | D19: ='Priority SKUs'!E7 -> AU | E19: ='Priority SKUs'!F7 -> 390 | F19: ='Priority SKUs'!G7 -> 34 | G19: ='Priority SKUs'!H7 -> 0.087179487 | H19: ='Priority SKUs'!I7 -> 2661.08 | I19: ='Priority SKUs'!L7 -> 0.00020659135 | J19: ='Priority SKUs'!B7 -> 1 - Fix first
A20: ='Priority SKUs'!A8 -> 4 | B20: ='Priority SKUs'!C8 -> DC-02B | C20: ='Priority SKUs'!D8 -> Birthday Designer Collection II | D20: ='Priority SKUs'!E8 -> DC | E20: ='Priority SKUs'!F8 -> 322 | F20: ='Priority SKUs'!G8 -> 28 | G20: ='Priority SKUs'!H8 -> 0.086956522 | H20: ='Priority SKUs'!I8 -> 2889.28 | I20: ='Priority SKUs'!L8 -> 0.00022430752 | J20: ='Priority SKUs'!B8 -> 1 - Fix first
A21: ='Priority SKUs'!A9 -> 5 | B21: ='Priority SKUs'!C9 -> AUMJ-NW-019 | C21: ='Priority SKUs'!D9 -> Garden Party Bouquet in Mason Jar | D21: ='Priority SKUs'!E9 -> AUMJ | E21: ='Priority SKUs'!F9 -> 1250 | F21: ='Priority SKUs'!G9 -> 74 | G21: ='Priority SKUs'!H9 -> 0.0592 | H21: ='Priority SKUs'!I9 -> 8226.91 | I21: ='Priority SKUs'!L9 -> 0.00063869122 | J21: ='Priority SKUs'!B9 -> 1 - Fix first
A22: ='Priority SKUs'!A10 -> 6 | B22: ='Priority SKUs'!C10 -> AU100-545 | C22: ='Priority SKUs'!D10 -> Gentle Thoughts Spray | D22: ='Priority SKUs'!E10 -> AU | E22: ='Priority SKUs'!F10 -> 128 | F22: ='Priority SKUs'!G10 -> 15 | G22: ='Priority SKUs'!H10 -> 0.1171875 | H22: ='Priority SKUs'!I10 -> 2729.11 | I22: ='Priority SKUs'!L10 -> 0.00021187282 | J22: ='Priority SKUs'!B10 -> 1 - Fix first
A23: ='Priority SKUs'!A11 -> 7 | B23: ='Priority SKUs'!C11 -> AU11-10 | C23: ='Priority SKUs'!D11 -> Ten Long Stemmed Red Roses | D23: ='Priority SKUs'!E11 -> AU | E23: ='Priority SKUs'!F11 -> 651 | F23: ='Priority SKUs'!G11 -> 41 | G23: ='Priority SKUs'!H11 -> 0.062980031 | H23: ='Priority SKUs'!I11 -> 3718.19 | I23: ='Priority SKUs'!L11 -> 0.00028865945 | J23: ='Priority SKUs'!B11 -> 1 - Fix first
A24: ='Priority SKUs'!A12 -> 8 | B24: ='Priority SKUs'!C12 -> AU200-61 | C24: ='Priority SKUs'!D12 -> Country Roads | D24: ='Priority SKUs'!E12 -> AU | E24: ='Priority SKUs'!F12 -> 360 | F24: ='Priority SKUs'!G12 -> 25 | G24: ='Priority SKUs'!H12 -> 0.069444444 | H24: ='Priority SKUs'!I12 -> 3303.38 | I24: ='Priority SKUs'!L12 -> 0.00025645593 | J24: ='Priority SKUs'!B12 -> 1 - Fix first
A25: ='Priority SKUs'!A13 -> 9 | B25: ='Priority SKUs'!C13 -> AUMJ-NW-005 | C25: ='Priority SKUs'!D13 -> Native Flowers Bouquet in Mason Jar | D25: ='Priority SKUs'!E13 -> AUMJ | E25: ='Priority SKUs'!F13 -> 6304 | F25: ='Priority SKUs'!G13 -> 335 | G25: ='Priority SKUs'!H13 -> 0.053140863 | H25: ='Priority SKUs'!I13 -> 30439.34 | I25: ='Priority SKUs'!L13 -> 0.0023631399 | J25: ='Priority SKUs'!B13 -> 1 - Fix first
A26: ='Priority SKUs'!A14 -> 10 | B26: ='Priority SKUs'!C14 -> AUMJ-NW-015 | C26: ='Priority SKUs'!D14 -> Walking on Sunshine Bouquet in Mason Jar | D26: ='Priority SKUs'!E14 -> AUMJ | E26: ='Priority SKUs'!F14 -> 487 | F26: ='Priority SKUs'!G14 -> 33 | G26: ='Priority SKUs'!H14 -> 0.067761807 | H26: ='Priority SKUs'!I14 -> 2389.19 | I26: ='Priority SKUs'!L14 -> 0.00018548333 | J26: ='Priority SKUs'!B14 -> 1 - Fix first
A28: Charts
A89: Sheet guide: Priority SKUs (ranked list) | Rankings (qty / revenue / rate) | Brands + B-* tabs (brand notes) | Anomalies | Review List | Notes | Settings (editable thresholds) | Brand Map | SKU Data

Sheet Priority SKUs
A1: Priority SKUs - ranked by combined problem score
A2: Score = equal-weight blend of 3 percentile ranks: refunded units, refund $ (= % of total revenue), and refund rate on the SKU's own sales (shrunk so tiny-volume SKUs can't dominate). Weights/thresholds live in Settings. List is live: change Settings and the order/tiers update.
A4: Rank | B4: Tier | C4: SKU | D4: Product | E4: Brand / family | F4: Qty ordered | G4: Refunded units | H4: Refund rate (units) | I4: Refund $ | J4: Refund rate ($ own gross) | K4: % of total refund $ | L4: % of total revenue | M4: Rate vs baseline | N4: z-score | O4: Flag
A5: 1 | B5: =IFERROR(INDEX('SKU Data'!$W$2:$W$1780,MATCH($A5,'SKU Data'!$V$2:$V$1780,0)),"") -> 1 - Fix first | C5: =IFERROR(INDEX('SKU Data'!$A$2:$A$1780,MATCH($A5,'SKU Data'!$V$2:$V$1780,0)),"") -> AUMJ-NW-008 | D5: =IFERROR(INDEX('SKU Data'!$B$2:$B$1780,MATCH($A5,'SKU Data'!$V$2:$V$1780,0)),"") -> Golden Hour Bouquet in Mason Jar | E5: =IFERROR(INDEX('SKU Data'!$D$2:$D$1780,MATCH($A5,'SKU Data'!$V$2:$V$1780,0)),"") -> AUMJ | F5: =IFERROR(INDEX('SKU Data'!$E$2:$E$1780,MATCH($A5,'SKU Data'!$V$2:$V$1780,0)),"") -> 503 | G5: =IFERROR(INDEX('SKU Data'!$F$2:$F$1780,MATCH($A5,'SKU Data'!$V$2:$V$1780,0)),"") -> 40 | H5: =IFERROR(INDEX('SKU Data'!$J$2:$J$1780,MATCH($A5,'SKU Data'!$V$2:$V$1780,0)),"") -> 0.079522863 | I5: =IFERROR(INDEX('SKU Data'!$H$2:$H$1780,MATCH($A5,'SKU Data'!$V$2:$V$1780,0)),"") -> 3723.61 | J5: =IFERROR(INDEX('SKU Data'!$K$2:$K$1780,MATCH($A5,'SKU Data'!$V$2:$V$1780,0)),"") -> 0.075984613 | K5: =IFERROR(INDEX('SKU Data'!$L$2:$L$1780,MATCH($A5,'SKU Data'!$V$2:$V$1780,0)),"") -> 0.0074417331 | L5: =IFERROR(INDEX('SKU Data'!$M$2:$M$1780,MATCH($A5,'SKU Data'!$V$2:$V$1780,0)),"") -> 0.00028908023 | M5: =IFERROR(H5/Settings!$B$3,"") -> 2.5664002 | N5: =IFERROR(INDEX('SKU Data'!$O$2:$O$1780,MATCH($A5,'SKU Data'!$V$2:$V$1780,0)),"") -> 6.28211 | O5: =IFERROR(INDEX('SKU Data'!$X$2:$X$1780,MATCH($A5,'SKU Data'!$V$2:$V$1780,0)),"") -> HIGH RATE
A6: 2 | B6: =IFERROR(INDEX('SKU Data'!$W$2:$W$1780,MATCH($A6,'SKU Data'!$V$2:$V$1780,0)),"") -> 1 - Fix first | C6: =IFERROR(INDEX('SKU Data'!$A$2:$A$1780,MATCH($A6,'SKU Data'!$V$2:$V$1780,0)),"") -> AU0511-17 | D6: =IFERROR(INDEX('SKU Data'!$B$2:$B$1780,MATCH($A6,'SKU Data'!$V$2:$V$1780,0)),"") -> Summer Blooms | E6: =IFERROR(INDEX('SKU Data'!$D$2:$D$1780,MATCH($A6,'SKU Data'!$V$2:$V$1780,0)),"") -> AU | F6: =IFERROR(INDEX('SKU Data'!$E$2:$E$1780,MATCH($A6,'SKU Data'!$V$2:$V$1780,0)),"") -> 1560 | G6: =IFERROR(INDEX('SKU Data'!$F$2:$F$1780,MATCH($A6,'SKU Data'!$V$2:$V$1780,0)),"") -> 97 | H6: =IFERROR(INDEX('SKU Data'!$J$2:$J$1780,MATCH($A6,'SKU Data'!$V$2:$V$1780,0)),"") -> 0.062179487 | I6: =IFERROR(INDEX('SKU Data'!$H$2:$H$1780,MATCH($A6,'SKU Data'!$V$2:$V$1780,0)),"") -> 5315.16 | J6: =IFERROR(INDEX('SKU Data'!$K$2:$K$1780,MATCH($A6,'SKU Data'!$V$2:$V$1780,0)),"") -> 0.060010493 | K6: =IFERROR(INDEX('SKU Data'!$L$2:$L$1780,MATCH($A6,'SKU Data'!$V$2:$V$1780,0)),"") -> 0.010622488 | L6: =IFERROR(INDEX('SKU Data'!$M$2:$M$1780,MATCH($A6,'SKU Data'!$V$2:$V$1780,0)),"") -> 0.00041263926 | M6: =IFERROR(H6/Settings!$B$3,"") -> 2.0066864 | N6: =IFERROR(INDEX('SKU Data'!$O$2:$O$1780,MATCH($A6,'SKU Data'!$V$2:$V$1780,0)),"") -> 7.1100935 | O6: =IFERROR(INDEX('SKU Data'!$X$2:$X$1780,MATCH($A6,'SKU Data'!$V$2:$V$1780,0)),"") -> HIGH RATE
A7: 3 | B7: =IFERROR(INDEX('SKU Data'!$W$2:$W$1780,MATCH($A7,'SKU Data'!$V$2:$V$1780,0)),"") -> 1 - Fix first | C7: =IFERROR(INDEX('SKU Data'!$A$2:$A$1780,MATCH($A7,'SKU Data'!$V$2:$V$1780,0)),"") -> AU501-05 | D7: =IFERROR(INDEX('SKU Data'!$B$2:$B$1780,MATCH($A7,'SKU Data'!$V$2:$V$1780,0)),"") -> Half Dozen Red Roses, Card & Teddy | E7: =IFERROR(INDEX('SKU Data'!$D$2:$D$1780,MATCH($A7,'SKU Data'!$V$2:$V$1780,0)),"") -> AU | F7: =IFERROR(INDEX('SKU Data'!$E$2:$E$1780,MATCH($A7,'SKU Data'!$V$2:$V$1780,0)),"") -> 390 | G7: =IFERROR(INDEX('SKU Data'!$F$2:$F$1780,MATCH($A7,'SKU Data'!$V$2:$V$1780,0)),"") -> 34 | H7: =IFERROR(INDEX('SKU Data'!$J$2:$J$1780,MATCH($A7,'SKU Data'!$V$2:$V$1780,0)),"") -> 0.087179487 | I7: =IFERROR(INDEX('SKU Data'!$H$2:$H$1780,MATCH($A7,'SKU Data'!$V$2:$V$1780,0)),"") -> 2661.08 | J7: =IFERROR(INDEX('SKU Data'!$K$2:$K$1780,MATCH($A7,'SKU Data'!$V$2:$V$1780,0)),"") -> 0.078840928 | K7: =IFERROR(INDEX('SKU Data'!$L$2:$L$1780,MATCH($A7,'SKU Data'!$V$2:$V$1780,0)),"") -> 0.0053182388 | L7: =IFERROR(INDEX('SKU Data'!$M$2:$M$1780,MATCH($A7,'SKU Data'!$V$2:$V$1780,0)),"") -> 0.00020659135 | M7: =IFERROR(H7/Settings!$B$3,"") -> 2.8134984 | N7: =IFERROR(INDEX('SKU Data'!$O$2:$O$1780,MATCH($A7,'SKU Data'!$V$2:$V$1780,0)),"") -> 6.4042505 | O7: =IFERROR(INDEX('SKU Data'!$X$2:$X$1780,MATCH($A7,'SKU Data'!$V$2:$V$1780,0)),"") -> HIGH RATE
A8: 4 | B8: =IFERROR(INDEX('SKU Data'!$W$2:$W$1780,MATCH($A8,'SKU Data'!$V$2:$V$1780,0)),"") -> 1 - Fix first | C8: =IFERROR(INDEX('SKU Data'!$A$2:$A$1780,MATCH($A8,'SKU Data'!$V$2:$V$1780,0)),"") -> DC-02B | D8: =IFERROR(INDEX('SKU Data'!$B$2:$B$1780,MATCH($A8,'SKU Data'!$V$2:$V$1780,0)),"") -> Birthday Designer Collection II | E8: =IFERROR(INDEX('SKU Data'!$D$2:$D$1780,MATCH($A8,'SKU Data'!$V$2:$V$1780,0)),"") -> DC | F8: =IFERROR(INDEX('SKU Data'!$E$2:$E$1780,MATCH($A8,'SKU Data'!$V$2:$V$1780,0)),"") -> 322 | G8: =IFERROR(INDEX('SKU Data'!$F$2:$F$1780,MATCH($A8,'SKU Data'!$V$2:$V$1780,0)),"") -> 28 | H8: =IFERROR(INDEX('SKU Data'!$J$2:$J$1780,MATCH($A8,'SKU Data'!$V$2:$V$1780,0)),"") -> 0.086956522 | I8: =IFERROR(INDEX('SKU Data'!$H$2:$H$1780,MATCH($A8,'SKU Data'!$V$2:$V$1780,0)),"") -> 2889.28 | J8: =IFERROR(INDEX('SKU Data'!$K$2:$K$1780,MATCH($A8,'SKU Data'!$V$2:$V$1780,0)),"") -> 0.083097281 | K8: =IFERROR(INDEX('SKU Data'!$L$2:$L$1780,MATCH($A8,'SKU Data'!$V$2:$V$1780,0)),"") -> 0.0057743025 | L8: =IFERROR(INDEX('SKU Data'!$M$2:$M$1780,MATCH($A8,'SKU Data'!$V$2:$V$1780,0)),"") -> 0.00022430752 | M8: =IFERROR(H8/Settings!$B$3,"") -> 2.8063028 | N8: =IFERROR(INDEX('SKU Data'!$O$2:$O$1780,MATCH($A8,'SKU Data'!$V$2:$V$1780,0)),"") -> 5.7961192 | O8: =IFERROR(INDEX('SKU Data'!$X$2:$X$1780,MATCH($A8,'SKU Data'!$V$2:$V$1780,0)),"") -> HIGH RATE
A9: 5 | B9: =IFERROR(INDEX('SKU Data'!$W$2:$W$1780,MATCH($A9,'SKU Data'!$V$2:$V$1780,0)),"") -> 1 - Fix first | C9: =IFERROR(INDEX('SKU Data'!$A$2:$A$1780,MATCH($A9,'SKU Data'!$V$2:$V$1780,0)),"") -> AUMJ-NW-019 | D9: =IFERROR(INDEX('SKU Data'!$B$2:$B$1780,MATCH($A9,'SKU Data'!$V$2:$V$1780,0)),"") -> Garden Party Bouquet in Mason Jar | E9: =IFERROR(INDEX('SKU Data'!$D$2:$D$1780,MATCH($A9,'SKU Data'!$V$2:$V$1780,0)),"") -> AUMJ | F9: =IFERROR(INDEX('SKU Data'!$E$2:$E$1780,MATCH($A9,'SKU Data'!$V$2:$V$1780,0)),"") -> 1250 | G9: =IFERROR(INDEX('SKU Data'!$F$2:$F$1780,MATCH($A9,'SKU Data'!$V$2:$V$1780,0)),"") -> 74 | H9: =IFERROR(INDEX('SKU Data'!$J$2:$J$1780,MATCH($A9,'SKU Data'!$V$2:$V$1780,0)),"") -> 0.0592 | I9: =IFERROR(INDEX('SKU Data'!$H$2:$H$1780,MATCH($A9,'SKU Data'!$V$2:$V$1780,0)),"") -> 8226.91 | J9: =IFERROR(INDEX('SKU Data'!$K$2:$K$1780,MATCH($A9,'SKU Data'!$V$2:$V$1780,0)),"") -> 0.059694511 | K9: =IFERROR(INDEX('SKU Data'!$L$2:$L$1780,MATCH($A9,'SKU Data'!$V$2:$V$1780,0)),"") -> 0.016441697 | L9: =IFERROR(INDEX('SKU Data'!$M$2:$M$1780,MATCH($A9,'SKU Data'!$V$2:$V$1780,0)),"") -> 0.00063869122 | M9: =IFERROR(H9/Settings!$B$3,"") -> 1.9105309 | N9: =IFERROR(INDEX('SKU Data'!$O$2:$O$1780,MATCH($A9,'SKU Data'!$V$2:$V$1780,0)),"") -> 5.7566329 | O9: =IFERROR(INDEX('SKU Data'!$X$2:$X$1780,MATCH($A9,'SKU Data'!$V$2:$V$1780,0)),"") -> HIGH RATE
A10: 6 | B10: =IFERROR(INDEX('SKU Data'!$W$2:$W$1780,MATCH($A10,'SKU Data'!$V$2:$V$1780,0)),"") -> 1 - Fix first | C10: =IFERROR(INDEX('SKU Data'!$A$2:$A$1780,MATCH($A10,'SKU Data'!$V$2:$V$1780,0)),"") -> AU100-545 | D10: =IFERROR(INDEX('SKU Data'!$B$2:$B$1780,MATCH($A10,'SKU Data'!$V$2:$V$1780,0)),"") -> Gentle Thoughts Spray | E10: =IFERROR(INDEX('SKU Data'!$D$2:$D$1780,MATCH($A10,'SKU Data'!$V$2:$V$1780,0)),"") -> AU | F10: =IFERROR(INDEX('SKU Data'!$E$2:$E$1780,MATCH($A10,'SKU Data'!$V$2:$V$1780,0)),"") -> 128 | G10: =IFERROR(INDEX('SKU Data'!$F$2:$F$1780,MATCH($A10,'SKU Data'!$V$2:$V$1780,0)),"") -> 15 | H10: =IFERROR(INDEX('SKU Data'!$J$2:$J$1780,MATCH($A10,'SKU Data'!$V$2:$V$1780,0)),"") -> 0.1171875 | I10: =IFERROR(INDEX('SKU Data'!$H$2:$H$1780,MATCH($A10,'SKU Data'!$V$2:$V$1780,0)),"") -> 2729.11 | J10: =IFERROR(INDEX('SKU Data'!$K$2:$K$1780,MATCH($A10,'SKU Data'!$V$2:$V$1780,0)),"") -> 0.10651399 | K10: =IFERROR(INDEX('SKU Data'!$L$2:$L$1780,MATCH($A10,'SKU Data'!$V$2:$V$1780,0)),"") -> 0.0054541985 | L10: =IFERROR(INDEX('SKU Data'!$M$2:$M$1780,MATCH($A10,'SKU Data'!$V$2:$V$1780,0)),"") -> 0.00021187282 | M10: =IFERROR(H10/Settings!$B$3,"") -> 3.7819315 | N10: =IFERROR(INDEX('SKU Data'!$O$2:$O$1780,MATCH($A10,'SKU Data'!$V$2:$V$1780,0)),"") -> 5.6282093 | O10: =IFERROR(INDEX('SKU Data'!$X$2:$X$1780,MATCH($A10,'SKU Data'!$V$2:$V$1780,0)),"") -> HIGH RATE
A11: 7 | B11: =IFERROR(INDEX('SKU Data'!$W$2:$W$1780,MATCH($A11,'SKU Data'!$V$2:$V$1780,0)),"") -> 1 - Fix first | C11: =IFERROR(INDEX('SKU Data'!$A$2:$A$1780,MATCH($A11,'SKU Data'!$V$2:$V$1780,0)),"") -> AU11-10 | D11: =IFERROR(INDEX('SKU Data'!$B$2:$B$1780,MATCH($A11,'SKU Data'!$V$2:$V$1780,0)),"") -> Ten Long Stemmed Red Roses | E11: =IFERROR(INDEX('SKU Data'!$D$2:$D$1780,MATCH($A11,'SKU Data'!$V$2:$V$1780,0)),"") -> AU | F11: =IFERROR(INDEX('SKU Data'!$E$2:$E$1780,MATCH($A11,'SKU Data'!$V$2:$V$1780,0)),"") -> 651 | G11: =IFERROR(INDEX('SKU Data'!$F$2:$F$1780,MATCH($A11,'SKU Data'!$V$2:$V$1780,0)),"") -> 41 | H11: =IFERROR(INDEX('SKU Data'!$J$2:$J$1780,MATCH($A11,'SKU Data'!$V$2:$V$1780,0)),"") -> 0.062980031 | I11: =IFERROR(INDEX('SKU Data'!$H$2:$H$1780,MATCH($A11,'SKU Data'!$V$2:$V$1780,0)),"") -> 3718.19 | J11: =IFERROR(INDEX('SKU Data'!$K$2:$K$1780,MATCH($A11,'SKU Data'!$V$2:$V$1780,0)),"") -> 0.059146759 | K11: =IFERROR(INDEX('SKU Data'!$L$2:$L$1780,MATCH($A11,'SKU Data'!$V$2:$V$1780,0)),"") -> 0.007430901 | L11: =IFERROR(INDEX('SKU Data'!$M$2:$M$1780,MATCH($A11,'SKU Data'!$V$2:$V$1780,0)),"") -> 0.00028865945 | M11: =IFERROR(H11/Settings!$B$3,"") -> 2.0325219 | N11: =IFERROR(INDEX('SKU Data'!$O$2:$O$1780,MATCH($A11,'SKU Data'!$V$2:$V$1780,0)),"") -> 4.7109511 | O11: =IFERROR(INDEX('SKU Data'!$X$2:$X$1780,MATCH($A11,'SKU Data'!$V$2:$V$1780,0)),"") -> HIGH RATE
A12: 8 | B12: =IFERROR(INDEX('SKU Data'!$W$2:$W$1780,MATCH($A12,'SKU Data'!$V$2:$V$1780,0)),"") -> 1 - Fix first | C12: =IFERROR(INDEX('SKU Data'!$A$2:$A$1780,MATCH($A12,'SKU Data'!$V$2:$V$1780,0)),"") -> AU200-61 | D12: =IFERROR(INDEX('SKU Data'!$B$2:$B$1780,MATCH($A12,'SKU Data'!$V$2:$V$1780,0)),"") -> Country Roads | E12: =IFERROR(INDEX('SKU Data'!$D$2:$D$1780,MATCH($A12,'SKU Data'!$V$2:$V$1780,0)),"") -> AU | F12: =IFERROR(INDEX('SKU Data'!$E$2:$E$1780,MATCH($A12,'SKU Data'!$V$2:$V$1780,0)),"") -> 360 | G12: =IFERROR(INDEX('SKU Data'!$F$2:$F$1780,MATCH($A12,'SKU Data'!$V$2:$V$1780,0)),"") -> 25 | H12: =IFERROR(INDEX('SKU Data'!$J$2:$J$1780,MATCH($A12,'SKU Data'!$V$2:$V$1780,0)),"") -> 0.069444444 | I12: =IFERROR(INDEX('SKU Data'!$H$2:$H$1780,MATCH($A12,'SKU Data'!$V$2:$V$1780,0)),"") -> 3303.38 | J12: =IFERROR(INDEX('SKU Data'!$K$2:$K$1780,MATCH($A12,'SKU Data'!$V$2:$V$1780,0)),"") -> 0.069155547 | K12: =IFERROR(INDEX('SKU Data'!$L$2:$L$1780,MATCH($A12,'SKU Data'!$V$2:$V$1780,0)),"") -> 0.0066018923 | L12: =IFERROR(INDEX('SKU Data'!$M$2:$M$1780,MATCH($A12,'SKU Data'!$V$2:$V$1780,0)),"") -> 0.00025645593 | M12: =IFERROR(H12/Settings!$B$3,"") -> 2.2411446 | N12: =IFERROR(INDEX('SKU Data'!$O$2:$O$1780,MATCH($A12,'SKU Data'!$V$2:$V$1780,0)),"") -> 4.2110699 | O12: =IFERROR(INDEX('SKU Data'!$X$2:$X$1780,MATCH($A12,'SKU Data'!$V$2:$V$1780,0)),"") -> HIGH RATE
A13: 9 | B13: =IFERROR(INDEX('SKU Data'!$W$2:$W$1780,MATCH($A13,'SKU Data'!$V$2:$V$1780,0)),"") -> 1 - Fix first | C13: =IFERROR(INDEX('SKU Data'!$A$2:$A$1780,MATCH($A13,'SKU Data'!$V$2:$V$1780,0)),"") -> AUMJ-NW-005 | D13: =IFERROR(INDEX('SKU Data'!$B$2:$B$1780,MATCH($A13,'SKU Data'!$V$2:$V$1780,0)),"") -> Native Flowers Bouquet in Mason Jar | E13: =IFERROR(INDEX('SKU Data'!$D$2:$D$1780,MATCH($A13,'SKU Data'!$V$2:$V$1780,0)),"") -> AUMJ | F13: =IFERROR(INDEX('SKU Data'!$E$2:$E$1780,MATCH($A13,'SKU Data'!$V$2:$V$1780,0)),"") -> 6304 | G13: =IFERROR(INDEX('SKU Data'!$F$2:$F$1780,MATCH($A13,'SKU Data'!$V$2:$V$1780,0)),"") -> 335 | H13: =IFERROR(INDEX('SKU Data'!$J$2:$J$1780,MATCH($A13,'SKU Data'!$V$2:$V$1780,0)),"") -> 0.053140863 | I13: =IFERROR(INDEX('SKU Data'!$H$2:$H$1780,MATCH($A13,'SKU Data'!$V$2:$V$1780,0)),"") -> 30439.34 | J13: =IFERROR(INDEX('SKU Data'!$K$2:$K$1780,MATCH($A13,'SKU Data'!$V$2:$V$1780,0)),"") -> 0.051522022 | K13: =IFERROR(INDEX('SKU Data'!$L$2:$L$1780,MATCH($A13,'SKU Data'!$V$2:$V$1780,0)),"") -> 0.060833826 | L13: =IFERROR(INDEX('SKU Data'!$M$2:$M$1780,MATCH($A13,'SKU Data'!$V$2:$V$1780,0)),"") -> 0.0023631399 | M13: =IFERROR(H13/Settings!$B$3,"") -> 1.7149875 | N13: =IFERROR(INDEX('SKU Data'!$O$2:$O$1780,MATCH($A13,'SKU Data'!$V$2:$V$1780,0)),"") -> 10.151387 | O13: =IFERROR(INDEX('SKU Data'!$X$2:$X$1780,MATCH($A13,'SKU Data'!$V$2:$V$1780,0)),"") -> HIGH RATE
A14: 10 | B14: =IFERROR(INDEX('SKU Data'!$W$2:$W$1780,MATCH($A14,'SKU Data'!$V$2:$V$1780,0)),"") -> 1 - Fix first | C14: =IFERROR(INDEX('SKU Data'!$A$2:$A$1780,MATCH($A14,'SKU Data'!$V$2:$V$1780,0)),"") -> AUMJ-NW-015 | D14: =IFERROR(INDEX('SKU Data'!$B$2:$B$1780,MATCH($A14,'SKU Data'!$V$2:$V$1780,0)),"") -> Walking on Sunshine Bouquet in Mason Jar | E14: =IFERROR(INDEX('SKU Data'!$D$2:$D$1780,MATCH($A14,'SKU Data'!$V$2:$V$1780,0)),"") -> AUMJ | F14: =IFERROR(INDEX('SKU Data'!$E$2:$E$1780,MATCH($A14,'SKU Data'!$V$2:$V$1780,0)),"") -> 487 | G14: =IFERROR(INDEX('SKU Data'!$F$2:$F$1780,MATCH($A14,'SKU Data'!$V$2:$V$1780,0)),"") -> 33 | H14: =IFERROR(INDEX('SKU Data'!$J$2:$J$1780,MATCH($A14,'SKU Data'!$V$2:$V$1780,0)),"") -> 0.067761807 | I14: =IFERROR(INDEX('SKU Data'!$H$2:$H$1780,MATCH($A14,'SKU Data'!$V$2:$V$1780,0)),"") -> 2389.19 | J14: =IFERROR(INDEX('SKU Data'!$K$2:$K$1780,MATCH($A14,'SKU Data'!$V$2:$V$1780,0)),"") -> 0.059885392 | K14: =IFERROR(INDEX('SKU Data'!$L$2:$L$1780,MATCH($A14,'SKU Data'!$V$2:$V$1780,0)),"") -> 0.0047748594 | L14: =IFERROR(INDEX('SKU Data'!$M$2:$M$1780,MATCH($A14,'SKU Data'!$V$2:$V$1780,0)),"") -> 0.00018548333 | M14: =IFERROR(H14/Settings!$B$3,"") -> 2.1868417 | N14: =IFERROR(INDEX('SKU Data'!$O$2:$O$1780,MATCH($A14,'SKU Data'!$V$2:$V$1780,0)),"") -> 4.6835601 | O14: =IFERROR(INDEX('SKU Data'!$X$2:$X$1780,MATCH($A14,'SKU Data'!$V$2:$V$1780,0)),"") -> HIGH RATE
A15: 11 | B15: =IFERROR(INDEX('SKU Data'!$W$2:$W$1780,MATCH($A15,'SKU Data'!$V$2:$V$1780,0)),"") -> 1 - Fix first | C15: =IFERROR(INDEX('SKU Data'!$A$2:$A$1780,MATCH($A15,'SKU Data'!$V$2:$V$1780,0)),"") -> AUMJ-NW-007 | D15: =IFERROR(INDEX('SKU Data'!$B$2:$B$1780,MATCH($A15,'SKU Data'!$V$2:$V$1780,0)),"") -> Pick-Me-Up Bouquet in Mason Jar | E15: =IFERROR(INDEX('SKU Data'!$D$2:$D$1780,MATCH($A15,'SKU Data'!$V$2:$V$1780,0)),"") -> AUMJ | F15: =IFERROR(INDEX('SKU Data'!$E$2:$E$1780,MATCH($A15,'SKU Data'!$V$2:$V$1780,0)),"") -> 789 | G15: =IFERROR(INDEX('SKU Data'!$F$2:$F$1780,MATCH($A15,'SKU Data'!$V$2:$V$1780,0)),"") -> 48 | H15: =IFERROR(INDEX('SKU Data'!$J$2:$J$1780,MATCH($A15,'SKU Data'!$V$2:$V$1780,0)),"") -> 0.060836502 | I15: =IFERROR(INDEX('SKU Data'!$H$2:$H$1780,MATCH($A15,'SKU Data'!$V$2:$V$1780,0)),"") -> 3223.36 | J15: =IFERROR(INDEX('SKU Data'!$K$2:$K$1780,MATCH($A15,'SKU Data'!$V$2:$V$1780,0)),"") -> 0.057669221 | K15: =IFERROR(INDEX('SKU Data'!$L$2:$L$1780,MATCH($A15,'SKU Data'!$V$2:$V$1780,0)),"") -> 0.0064419702 | L15: =IFERROR(INDEX('SKU Data'!$M$2:$M$1780,MATCH($A15,'SKU Data'!$V$2:$V$1780,0)),"") -> 0.00025024362 | M15: =IFERROR(H15/Settings!$B$3,"") -> 1.9633449 | N15: =IFERROR(INDEX('SKU Data'!$O$2:$O$1780,MATCH($A15,'SKU Data'!$V$2:$V$1780,0)),"") -> 4.8388163 | O15: =IFERROR(INDEX('SKU Data'!$X$2:$X$1780,MATCH($A15,'SKU Data'!$V$2:$V$1780,0)),"") -> HIGH RATE
A16: 12 | B16: =IFERROR(INDEX('SKU Data'!$W$2:$W$1780,MATCH($A16,'SKU Data'!$V$2:$V$1780,0)),"") | C16: =IFERROR(INDEX('SKU Data'!$A$2:$A$1780,MATCH($A16,'SKU Data'!$V$2:$V$1780,0)),"") | D16: =IFERROR(INDEX('SKU Data'!$B$2:$B$1780,MATCH($A16,'SKU Data'!$V$2:$V$1780,0)),"") | E16: =IFERROR(INDEX('SKU Data'!$D$2:$D$1780,MATCH($A16,'SKU Data'!$V$2:$V$1780,0)),"") | F16: =IFERROR(INDEX('SKU Data'!$E$2:$E$1780,MATCH($A16,'SKU Data'!$V$2:$V$1780,0)),"") | G16: =IFERROR(INDEX('SKU Data'!$F$2:$F$1780,MATCH($A16,'SKU Data'!$V$2:$V$1780,0)),"") | H16: =IFERROR(INDEX('SKU Data'!$J$2:$J$1780,MATCH($A16,'SKU Data'!$V$2:$V$1780,0)),"") | I16: =IFERROR(INDEX('SKU Data'!$H$2:$H$1780,MATCH($A16,'SKU Data'!$V$2:$V$1780,0)),"") | J16: =IFERROR(INDEX('SKU Data'!$K$2:$K$1780,MATCH($A16,'SKU Data'!$V$2:$V$1780,0)),"") | K16: =IFERROR(INDEX('SKU Data'!$L$2:$L$1780,MATCH($A16,'SKU Data'!$V$2:$V$1780,0)),"") | L16: =IFERROR(INDEX('SKU Data'!$M$2:$M$1780,MATCH($A16,'SKU Data'!$V$2:$V$1780,0)),"") | M16: =IFERROR(H16/Settings!$B$3,"") | N16: =IFERROR(INDEX('SKU Data'!$O$2:$O$1780,MATCH($A16,'SKU Data'!$V$2:$V$1780,0)),"") | O16: =IFERROR(INDEX('SKU Data'!$X$2:$X$1780,MATCH($A16,'SKU Data'!$V$2:$V$1780,0)),"")
... A104: 100 | B104: =IFERROR(INDEX('SKU Data'!$W$2:$W$1780,MATCH($A104,'SKU Data'!$V$2:$V$1780,0)),"") -> 2 - Review | C104: =IFERROR(INDEX('SKU Data'!$A$2:$A$1780,MATCH($A104,'SKU Data'!$V$2:$V$1780,0)),"") -> DCS-02 | D104: =IFERROR(INDEX('SKU Data'!$B$2:$B$1780,MATCH($A104,'SKU Data'!$V$2:$V$1780,0)),"") -> Designer Sympathy Collection II | E104: =IFERROR(INDEX('SKU Data'!$D$2:$D$1780,MATCH($A104,'SKU Data'!$V$2:$V$1780,0)),"") -> DCS | F104: =IFERROR(INDEX('SKU Data'!$E$2:$E$1780,MATCH($A104,'SKU Data'!$V$2:$V$1780,0)),"") -> 136 | G104: =IFERROR(INDEX('SKU Data'!$F$2:$F$1780,MATCH($A104,'SKU Data'!$V$2:$V$1780,0)),"") -> 8 | H104: =IFERROR(INDEX('SKU Data'!$J$2:$J$1780,MATCH($A104,'SKU Data'!$V$2:$V$1780,0)),"") -> 0.058823529 | I104: =IFERROR(INDEX('SKU Data'!$H$2:$H$1780,MATCH($A104,'SKU Data'!$V$2:$V$1780,0)),"") -> 798.41 | J104: =IFERROR(INDEX('SKU Data'!$K$2:$K$1780,MATCH($A104,'SKU Data'!$V$2:$V$1780,0)),"") -> 0.049994333 | K104: =IFERROR(INDEX('SKU Data'!$L$2:$L$1780,MATCH($A104,'SKU Data'!$V$2:$V$1780,0)),"") -> 0.0015956435 | L104: =IFERROR(INDEX('SKU Data'!$M$2:$M$1780,MATCH($A104,'SKU Data'!$V$2:$V$1780,0)),"") -> 6.1984082e-05 | M104: =IFERROR(H104/Settings!$B$3,"") -> 1.8983813 | N104: =IFERROR(INDEX('SKU Data'!$O$2:$O$1780,MATCH($A104,'SKU Data'!$V$2:$V$1780,0)),"") -> 1.8734796 | O104: =IFERROR(INDEX('SKU Data'!$X$2:$X$1780,MATCH($A104,'SKU Data'!$V$2:$V$1780,0)),"")

Sheet Rankings
A1: Rankings - the three lenses requested
A2: Top 25 each. Live formulas on SKU Data. Rate ranking only includes SKUs with at least the minimum volume in Settings.
A3: 1) BY QUANTITY - most refunded units
A4: # | B4: SKU | C4: Product | D4: Brand / family | E4: Qty ordered | F4: Refunded units | G4: Refund rate (units) | H4: Refund $ | I4: Refund rate ($ own gross) | J4: % of total revenue | K4: % of SKU-attrib. refund $ | L4: Cumulative % of refunds | M4: Baseline rate
A5: 1 | B5: =IFERROR(INDEX('SKU Data'!$A$2:$A$1780,MATCH($A5,'SKU Data'!$Y$2:$Y$1780,0)),"") -> AUSGF16-115 | C5: =IFERROR(INDEX('SKU Data'!$B$2:$B$1780,MATCH($A5,'SKU Data'!$Y$2:$Y$1780,0)),"") -> Delicate Elegance | D5: =IFERROR(INDEX('SKU Data'!$D$2:$D$1780,MATCH($A5,'SKU Data'!$Y$2:$Y$1780,0)),"") -> AUSGF | E5: =IFERROR(INDEX('SKU Data'!$E$2:$E$1780,MATCH($A5,'SKU Data'!$Y$2:$Y$1780,0)),"") -> 11490 | F5: =IFERROR(INDEX('SKU Data'!$F$2:$F$1780,MATCH($A5,'SKU Data'!$Y$2:$Y$1780,0)),"") -> 419 | G5: =IFERROR(INDEX('SKU Data'!$J$2:$J$1780,MATCH($A5,'SKU Data'!$Y$2:$Y$1780,0)),"") -> 0.036466493 | H5: =IFERROR(INDEX('SKU Data'!$H$2:$H$1780,MATCH($A5,'SKU Data'!$Y$2:$Y$1780,0)),"") -> 25834.89 | I5: =IFERROR(INDEX('SKU Data'!$K$2:$K$1780,MATCH($A5,'SKU Data'!$Y$2:$Y$1780,0)),"") -> 0.035459214 | J5: =IFERROR(INDEX('SKU Data'!$M$2:$M$1780,MATCH($A5,'SKU Data'!$Y$2:$Y$1780,0)),"") -> 0.0020056762 | K5: =IFERROR(INDEX('SKU Data'!$L$2:$L$1780,MATCH($A5,'SKU Data'!$Y$2:$Y$1780,0)),"") -> 0.051631711 | M5: =Settings!$B$3 -> 0.030986151
A6: 2 | B6: =IFERROR(INDEX('SKU Data'!$A$2:$A$1780,MATCH($A6,'SKU Data'!$Y$2:$Y$1780,0)),"") -> AURP05 | C6: =IFERROR(INDEX('SKU Data'!$B$2:$B$1780,MATCH($A6,'SKU Data'!$Y$2:$Y$1780,0)),"") -> Full Size Greeting Card | D6: =IFERROR(INDEX('SKU Data'!$D$2:$D$1780,MATCH($A6,'SKU Data'!$Y$2:$Y$1780,0)),"") -> AURP | E6: =IFERROR(INDEX('SKU Data'!$E$2:$E$1780,MATCH($A6,'SKU Data'!$Y$2:$Y$1780,0)),"") -> 11080 | F6: =IFERROR(INDEX('SKU Data'!$F$2:$F$1780,MATCH($A6,'SKU Data'!$Y$2:$Y$1780,0)),"") -> 410 | G6: =IFERROR(INDEX('SKU Data'!$J$2:$J$1780,MATCH($A6,'SKU Data'!$Y$2:$Y$1780,0)),"") -> 0.03700361 | H6: =IFERROR(INDEX('SKU Data'!$H$2:$H$1780,MATCH($A6,'SKU Data'!$Y$2:$Y$1780,0)),"") -> 1427.63 | I6: =IFERROR(INDEX('SKU Data'!$K$2:$K$1780,MATCH($A6,'SKU Data'!$Y$2:$Y$1780,0)),"") -> 0.03432841 | J6: =IFERROR(INDEX('SKU Data'!$M$2:$M$1780,MATCH($A6,'SKU Data'!$Y$2:$Y$1780,0)),"") -> 0.0001108332 | K6: =IFERROR(INDEX('SKU Data'!$L$2:$L$1780,MATCH($A6,'SKU Data'!$Y$2:$Y$1780,0)),"") -> 0.0028531563 | M6: =Settings!$B$3 -> 0.030986151
A7: 3 | B7: =IFERROR(INDEX('SKU Data'!$A$2:$A$1780,MATCH($A7,'SKU Data'!$Y$2:$Y$1780,0)),"") -> RP19 | C7: =IFERROR(INDEX('SKU Data'!$B$2:$B$1780,MATCH($A7,'SKU Data'!$Y$2:$Y$1780,0)),"") -> Full Size Birthday Card | D7: =IFERROR(INDEX('SKU Data'!$D$2:$D$1780,MATCH($A7,'SKU Data'!$Y$2:$Y$1780,0)),"") -> RP | E7: =IFERROR(INDEX('SKU Data'!$E$2:$E$1780,MATCH($A7,'SKU Data'!$Y$2:$Y$1780,0)),"") -> 6456 | F7: =IFERROR(INDEX('SKU Data'!$F$2:$F$1780,MATCH($A7,'SKU Data'!$Y$2:$Y$1780,0)),"") -> 336 | G7: =IFERROR(INDEX('SKU Data'!$J$2:$J$1780,MATCH($A7,'SKU Data'!$Y$2:$Y$1780,0)),"") -> 0.05204461 | H7: =IFERROR(INDEX('SKU Data'!$H$2:$H$1780,MATCH($A7,'SKU Data'!$Y$2:$Y$1780,0)),"") -> 1172.41 | I7: =IFERROR(INDEX('SKU Data'!$K$2:$K$1780,MATCH($A7,'SKU Data'!$Y$2:$Y$1780,0)),"") -> 0.048685818 | J7: =IFERROR(INDEX('SKU Data'!$M$2:$M$1780,MATCH($A7,'SKU Data'!$Y$2:$Y$1780,0)),"") -> 9.1019347e-05 | K7: =IFERROR(INDEX('SKU Data'!$L$2:$L$1780,MATCH($A7,'SKU Data'!$Y$2:$Y$1780,0)),"") -> 0.0023430924 | M7: =Settings!$B$3 -> 0.030986151
A8: 4 | B8: =IFERROR(INDEX('SKU Data'!$A$2:$A$1780,MATCH($A8,'SKU Data'!$Y$2:$Y$1780,0)),"") -> AUMJ-NW-005 | C8: =IFERROR(INDEX('SKU Data'!$B$2:$B$1780,MATCH($A8,'SKU Data'!$Y$2:$Y$1780,0)),"") -> Native Flowers Bouquet in Mason Jar | D8: =IFERROR(INDEX('SKU Data'!$D$2:$D$1780,MATCH($A8,'SKU Data'!$Y$2:$Y$1780,0)),"") -> AUMJ | E8: =IFERROR(INDEX('SKU Data'!$E$2:$E$1780,MATCH($A8,'SKU Data'!$Y$2:$Y$1780,0)),"") -> 6304 | F8: =IFERROR(INDEX('SKU Data'!$F$2:$F$1780,MATCH($A8,'SKU Data'!$Y$2:$Y$1780,0)),"") -> 335 | G8: =IFERROR(INDEX('SKU Data'!$J$2:$J$1780,MATCH($A8,'SKU Data'!$Y$2:$Y$1780,0)),"") -> 0.053140863 | H8: =IFERROR(INDEX('SKU Data'!$H$2:$H$1780,MATCH($A8,'SKU Data'!$Y$2:$Y$1780,0)),"") -> 30439.34 | I8: =IFERROR(INDEX('SKU Data'!$K$2:$K$1780,MATCH($A8,'SKU Data'!$Y$2:$Y$1780,0)),"") -> 0.051522022 | J8: =IFERROR(INDEX('SKU Data'!$M$2:$M$1780,MATCH($A8,'SKU Data'!$Y$2:$Y$1780,0)),"") -> 0.0023631399 | K8: =IFERROR(INDEX('SKU Data'!$L$2:$L$1780,MATCH($A8,'SKU Data'!$Y$2:$Y$1780,0)),"") -> 0.060833826 | M8: =Settings!$B$3 -> 0.030986151
A9: 5 | B9: =IFERROR(INDEX('SKU Data'!$A$2:$A$1780,MATCH($A9,'SKU Data'!$Y$2:$Y$1780,0)),"") -> SC01 | C9: =IFERROR(INDEX('SKU Data'!$B$2:$B$1780,MATCH($A9,'SKU Data'!$Y$2:$Y$1780,0)),"") -> Full Size Sympathy Card | D9: =IFERROR(INDEX('SKU Data'!$D$2:$D$1780,MATCH($A9,'SKU Data'!$Y$2:$Y$1780,0)),"") -> SC | E9: =IFERROR(INDEX('SKU Data'!$E$2:$E$1780,MATCH($A9,'SKU Data'!$Y$2:$Y$1780,0)),"") -> 8341 | F9: =IFERROR(INDEX('SKU Data'!$F$2:$F$1780,MATCH($A9,'SKU Data'!$Y$2:$Y$1780,0)),"") -> 329 | G9: =IFERROR(INDEX('SKU Data'!$J$2:$J$1780,MATCH($A9,'SKU Data'!$Y$2:$Y$1780,0)),"") -> 0.039443712 | H9: =IFERROR(INDEX('SKU Data'!$H$2:$H$1780,MATCH($A9,'SKU Data'!$Y$2:$Y$1780,0)),"") -> 1189.07 | I9: =IFERROR(INDEX('SKU Data'!$K$2:$K$1780,MATCH($A9,'SKU Data'!$Y$2:$Y$1780,0)),"") -> 0.037598279 | J9: =IFERROR(INDEX('SKU Data'!$M$2:$M$1780,MATCH($A9,'SKU Data'!$Y$2:$Y$1780,0)),"") -> 9.2312736e-05 | K9: =IFERROR(INDEX('SKU Data'!$L$2:$L$1780,MATCH($A9,'SKU Data'!$Y$2:$Y$1780,0)),"") -> 0.0023763878 | M9: =Settings!$B$3 -> 0.030986151
A10: 6 | B10: =IFERROR(INDEX('SKU Data'!$A$2:$A$1780,MATCH($A10,'SKU Data'!$Y$2:$Y$1780,0)),"") -> AUSMJ100-11 | C10: =IFERROR(INDEX('SKU Data'!$B$2:$B$1780,MATCH($A10,'SKU Data'!$Y$2:$Y$1780,0)),"") -> Breathtaking Blooms In Mason Jar | D10: =IFERROR(INDEX('SKU Data'!$D$2:$D$1780,MATCH($A10,'SKU Data'!$Y$2:$Y$1780,0)),"") -> AUSMJ | E10: =IFERROR(INDEX('SKU Data'!$E$2:$E$1780,MATCH($A10,'SKU Data'!$Y$2:$Y$1780,0)),"") -> 4959 | F10: =IFERROR(INDEX('SKU Data'!$F$2:$F$1780,MATCH($A10,'SKU Data'!$Y$2:$Y$1780,0)),"") -> 203 | G10: =IFERROR(INDEX('SKU Data'!$J$2:$J$1780,MATCH($A10,'SKU Data'!$Y$2:$Y$1780,0)),"") -> 0.040935673 | H10: =IFERROR(INDEX('SKU Data'!$H$2:$H$1780,MATCH($A10,'SKU Data'!$Y$2:$Y$1780,0)),"") -> 13653.88 | I10: =IFERROR(INDEX('SKU Data'!$K$2:$K$1780,MATCH($A10,'SKU Data'!$Y$2:$Y$1780,0)),"") -> 0.039004288 | J10: =IFERROR(INDEX('SKU Data'!$M$2:$M$1780,MATCH($A10,'SKU Data'!$Y$2:$Y$1780,0)),"") -> 0.0010600108 | K10: =IFERROR(INDEX('SKU Data'!$L$2:$L$1780,MATCH($A10,'SKU Data'!$Y$2:$Y$1780,0)),"") -> 0.02728764 | M10: =Settings!$B$3 -> 0.030986151
A11: 7 | B11: =IFERROR(INDEX('SKU Data'!$A$2:$A$1780,MATCH($A11,'SKU Data'!$Y$2:$Y$1780,0)),"") -> AUMJ-NW-017 | C11: =IFERROR(INDEX('SKU Data'!$B$2:$B$1780,MATCH($A11,'SKU Data'!$Y$2:$Y$1780,0)),"") -> Pastel Buttercup Bouquet in Mason Jar | D11: =IFERROR(INDEX('SKU Data'!$D$2:$D$1780,MATCH($A11,'SKU Data'!$Y$2:$Y$1780,0)),"") -> AUMJ | E11: =IFERROR(INDEX('SKU Data'!$E$2:$E$1780,MATCH($A11,'SKU Data'!$Y$2:$Y$1780,0)),"") -> 3907 | F11: =IFERROR(INDEX('SKU Data'!$F$2:$F$1780,MATCH($A11,'SKU Data'!$Y$2:$Y$1780,0)),"") -> 172 | G11: =IFERROR(INDEX('SKU Data'!$J$2:$J$1780,MATCH($A11,'SKU Data'!$Y$2:$Y$1780,0)),"") -> 0.044023547 | H11: =IFERROR(INDEX('SKU Data'!$H$2:$H$1780,MATCH($A11,'SKU Data'!$Y$2:$Y$1780,0)),"") -> 14074.44 | I11: =IFERROR(INDEX('SKU Data'!$K$2:$K$1780,MATCH($A11,'SKU Data'!$Y$2:$Y$1780,0)),"") -> 0.040285179 | J11: =IFERROR(INDEX('SKU Data'!$M$2:$M$1780,MATCH($A11,'SKU Data'!$Y$2:$Y$1780,0)),"") -> 0.0010926607 | K11: =IFERROR(INDEX('SKU Data'!$L$2:$L$1780,MATCH($A11,'SKU Data'!$Y$2:$Y$1780,0)),"") -> 0.028128141 | M11: =Settings!$B$3 -> 0.030986151
A12: 8 | B12: =IFERROR(INDEX('SKU Data'!$A$2:$A$1780,MATCH($A12,'SKU Data'!$Y$2:$Y$1780,0)),"") -> AUSRP-16sp | C12: =IFERROR(INDEX('SKU Data'!$B$2:$B$1780,MATCH($A12,'SKU Data'!$Y$2:$Y$1780,0)),"") -> Truffles & Card | D12: =IFERROR(INDEX('SKU Data'!$D$2:$D$1780,MATCH($A12,'SKU Data'!$Y$2:$Y$1780,0)),"") -> AUSRP | E12: =IFERROR(INDEX('SKU Data'!$E$2:$E$1780,MATCH($A12,'SKU Data'!$Y$2:$Y$1780,0)),"") -> 2919 | F12: =IFERROR(INDEX('SKU Data'!$F$2:$F$1780,MATCH($A12,'SKU Data'!$Y$2:$Y$1780,0)),"") -> 152 | G12: =IFERROR(INDEX('SKU Data'!$J$2:$J$1780,MATCH($A12,'SKU Data'!$Y$2:$Y$1780,0)),"") -> 0.052072628 | H12: =IFERROR(INDEX('SKU Data'!$H$2:$H$1780,MATCH($A12,'SKU Data'!$Y$2:$Y$1780,0)),"") -> 1385.93 | I12: =IFERROR(INDEX('SKU Data'!$K$2:$K$1780,MATCH($A12,'SKU Data'!$Y$2:$Y$1780,0)),"") -> 0.047612504 | J12: =IFERROR(INDEX('SKU Data'!$M$2:$M$1780,MATCH($A12,'SKU Data'!$Y$2:$Y$1780,0)),"") -> 0.00010759584 | K12: =IFERROR(INDEX('SKU Data'!$L$2:$L$1780,MATCH($A12,'SKU Data'!$Y$2:$Y$1780,0)),"") -> 0.0027698178 | M12: =Settings!$B$3 -> 0.030986151
A13: 9 | B13: =IFERROR(INDEX('SKU Data'!$A$2:$A$1780,MATCH($A13,'SKU Data'!$Y$2:$Y$1780,0)),"") -> AU11-43 | C13: =IFERROR(INDEX('SKU Data'!$B$2:$B$1780,MATCH($A13,'SKU Data'!$Y$2:$Y$1780,0)),"") -> Warm Embrace | D13: =IFERROR(INDEX('SKU Data'!$D$2:$D$1780,MATCH($A13,'SKU Data'!$Y$2:$Y$1780,0)),"") -> AU | E13: =IFERROR(INDEX('SKU Data'!$E$2:$E$1780,MATCH($A13,'SKU Data'!$Y$2:$Y$1780,0)),"") -> 2594 | F13: =IFERROR(INDEX('SKU Data'!$F$2:$F$1780,MATCH($A13,'SKU Data'!$Y$2:$Y$1780,0)),"") -> 129 | G13: =IFERROR(INDEX('SKU Data'!$J$2:$J$1780,MATCH($A13,'SKU Data'!$Y$2:$Y$1780,0)),"") -> 0.049730146 | H13: =IFERROR(INDEX('SKU Data'!$H$2:$H$1780,MATCH($A13,'SKU Data'!$Y$2:$Y$1780,0)),"") -> 11840.22 | I13: =IFERROR(INDEX('SKU Data'!$K$2:$K$1780,MATCH($A13,'SKU Data'!$Y$2:$Y$1780,0)),"") -> 0.047722296 | J13: =IFERROR(INDEX('SKU Data'!$M$2:$M$1780,MATCH($A13,'SKU Data'!$Y$2:$Y$1780,0)),"") -> 0.00091920838 | K13: =IFERROR(INDEX('SKU Data'!$L$2:$L$1780,MATCH($A13,'SKU Data'!$Y$2:$Y$1780,0)),"") -> 0.023662993 | M13: =Settings!$B$3 -> 0.030986151
A14: 10 | B14: =IFERROR(INDEX('SKU Data'!$A$2:$A$1780,MATCH($A14,'SKU Data'!$Y$2:$Y$1780,0)),"") -> AUCH25-04 | C14: =IFERROR(INDEX('SKU Data'!$B$2:$B$1780,MATCH($A14,'SKU Data'!$Y$2:$Y$1780,0)),"") -> Snowy Rose in Mason Jar | D14: =IFERROR(INDEX('SKU Data'!$D$2:$D$1780,MATCH($A14,'SKU Data'!$Y$2:$Y$1780,0)),"") -> AUCH | E14: =IFERROR(INDEX('SKU Data'!$E$2:$E$1780,MATCH($A14,'SKU Data'!$Y$2:$Y$1780,0)),"") -> 2531 | F14: =IFERROR(INDEX('SKU Data'!$F$2:$F$1780,MATCH($A14,'SKU Data'!$Y$2:$Y$1780,0)),"") -> 116 | G14: =IFERROR(INDEX('SKU Data'!$J$2:$J$1780,MATCH($A14,'SKU Data'!$Y$2:$Y$1780,0)),"") -> 0.045831687 | H14: =IFERROR(INDEX('SKU Data'!$H$2:$H$1780,MATCH($A14,'SKU Data'!$Y$2:$Y$1780,0)),"") -> 5309.56 | I14: =IFERROR(INDEX('SKU Data'!$K$2:$K$1780,MATCH($A14,'SKU Data'!$Y$2:$Y$1780,0)),"") -> 0.042930038 | J14: =IFERROR(INDEX('SKU Data'!$M$2:$M$1780,MATCH($A14,'SKU Data'!$Y$2:$Y$1780,0)),"") -> 0.00041220451 | K14: =IFERROR(INDEX('SKU Data'!$L$2:$L$1780,MATCH($A14,'SKU Data'!$Y$2:$Y$1780,0)),"") -> 0.010611296 | M14: =Settings!$B$3 -> 0.030986151
A15: 11 | B15: =IFERROR(INDEX('SKU Data'!$A$2:$A$1780,MATCH($A15,'SKU Data'!$Y$2:$Y$1780,0)),"") -> AUMJ-NW-011 | C15: =IFERROR(INDEX('SKU Data'!$B$2:$B$1780,MATCH($A15,'SKU Data'!$Y$2:$Y$1780,0)),"") -> Best Birthday Ever Bouquet in Mason Jar | D15: =IFERROR(INDEX('SKU Data'!$D$2:$D$1780,MATCH($A15,'SKU Data'!$Y$2:$Y$1780,0)),"") -> AUMJ | E15: =IFERROR(INDEX('SKU Data'!$E$2:$E$1780,MATCH($A15,'SKU Data'!$Y$2:$Y$1780,0)),"") -> 2143 | F15: =IFERROR(INDEX('SKU Data'!$F$2:$F$1780,MATCH($A15,'SKU Data'!$Y$2:$Y$1780,0)),"") -> 115 | G15: =IFERROR(INDEX('SKU Data'!$J$2:$J$1780,MATCH($A15,'SKU Data'!$Y$2:$Y$1780,0)),"") -> 0.053663089 | H15: =IFERROR(INDEX('SKU Data'!$H$2:$H$1780,MATCH($A15,'SKU Data'!$Y$2:$Y$1780,0)),"") -> 9879.04 | I15: =IFERROR(INDEX('SKU Data'!$K$2:$K$1780,MATCH($A15,'SKU Data'!$Y$2:$Y$1780,0)),"") -> 0.053490444 | J15: =IFERROR(INDEX('SKU Data'!$M$2:$M$1780,MATCH($A15,'SKU Data'!$Y$2:$Y$1780,0)),"") -> 0.00076695335 | K15: =IFERROR(INDEX('SKU Data'!$L$2:$L$1780,MATCH($A15,'SKU Data'!$Y$2:$Y$1780,0)),"") -> 0.019743523 | M15: =Settings!$B$3 -> 0.030986151
A16: 12 | B16: =IFERROR(INDEX('SKU Data'!$A$2:$A$1780,MATCH($A16,'SKU Data'!$Y$2:$Y$1780,0)),"") -> AURP03 | C16: =IFERROR(INDEX('SKU Data'!$B$2:$B$1780,MATCH($A16,'SKU Data'!$Y$2:$Y$1780,0)),"") -> Glass Vase | D16: =IFERROR(INDEX('SKU Data'!$D$2:$D$1780,MATCH($A16,'SKU Data'!$Y$2:$Y$1780,0)),"") -> AURP | E16: =IFERROR(INDEX('SKU Data'!$E$2:$E$1780,MATCH($A16,'SKU Data'!$Y$2:$Y$1780,0)),"") -> 2409 | F16: =IFERROR(INDEX('SKU Data'!$F$2:$F$1780,MATCH($A16,'SKU Data'!$Y$2:$Y$1780,0)),"") -> 112 | G16: =IFERROR(INDEX('SKU Data'!$J$2:$J$1780,MATCH($A16,'SKU Data'!$Y$2:$Y$1780,0)),"") -> 0.04649232 | H16: =IFERROR(INDEX('SKU Data'!$H$2:$H$1780,MATCH($A16,'SKU Data'!$Y$2:$Y$1780,0)),"") -> 1180.39 | I16: =IFERROR(INDEX('SKU Data'!$K$2:$K$1780,MATCH($A16,'SKU Data'!$Y$2:$Y$1780,0)),"") -> 0.043241847 | J16: =IFERROR(INDEX('SKU Data'!$M$2:$M$1780,MATCH($A16,'SKU Data'!$Y$2:$Y$1780,0)),"") -> 9.163887e-05 | K16: =IFERROR(INDEX('SKU Data'!$L$2:$L$1780,MATCH($A16,'SKU Data'!$Y$2:$Y$1780,0)),"") -> 0.0023590406 | M16: =Settings!$B$3 -> 0.030986151
... A29: 25 | B29: =IFERROR(INDEX('SKU Data'!$A$2:$A$1780,MATCH($A29,'SKU Data'!$Y$2:$Y$1780,0)),"") -> AU222-80 | C29: =IFERROR(INDEX('SKU Data'!$B$2:$B$1780,MATCH($A29,'SKU Data'!$Y$2:$Y$1780,0)),"") -> Wild Spirits | D29: =IFERROR(INDEX('SKU Data'!$D$2:$D$1780,MATCH($A29,'SKU Data'!$Y$2:$Y$1780,0)),"") -> AU | E29: =IFERROR(INDEX('SKU Data'!$E$2:$E$1780,MATCH($A29,'SKU Data'!$Y$2:$Y$1780,0)),"") -> 1727 | F29: =IFERROR(INDEX('SKU Data'!$F$2:$F$1780,MATCH($A29,'SKU Data'!$Y$2:$Y$1780,0)),"") -> 80 | G29: =IFERROR(INDEX('SKU Data'!$J$2:$J$1780,MATCH($A29,'SKU Data'!$Y$2:$Y$1780,0)),"") -> 0.046323104 | H29: =IFERROR(INDEX('SKU Data'!$H$2:$H$1780,MATCH($A29,'SKU Data'!$Y$2:$Y$1780,0)),"") -> 6215.17 | I29: =IFERROR(INDEX('SKU Data'!$K$2:$K$1780,MATCH($A29,'SKU Data'!$Y$2:$Y$1780,0)),"") -> 0.044132978 | J29: =IFERROR(INDEX('SKU Data'!$M$2:$M$1780,MATCH($A29,'SKU Data'!$Y$2:$Y$1780,0)),"") -> 0.000482511 | K29: =IFERROR(INDEX('SKU Data'!$L$2:$L$1780,MATCH($A29,'SKU Data'!$Y$2:$Y$1780,0)),"") -> 0.012421182 | M29: =Settings!$B$3 -> 0.030986151
A32: 2) BY REVENUE IMPACT - largest refund $ (as % of total revenue)
A33: # | B33: SKU | C33: Product | D33: Brand / family | E33: Qty ordered | F33: Refunded units | G33: Refund rate (units) | H33: Refund $ | I33: Refund rate ($ own gross) | J33: % of total revenue | K33: % of SKU-attrib. refund $ | L33: Cumulative % of refunds | M33: Baseline rate
A34: 1 | B34: =IFERROR(INDEX('SKU Data'!$A$2:$A$1780,MATCH($A34,'SKU Data'!$Z$2:$Z$1780,0)),"") -> AUMJ-NW-005 | C34: =IFERROR(INDEX('SKU Data'!$B$2:$B$1780,MATCH($A34,'SKU Data'!$Z$2:$Z$1780,0)),"") -> Native Flowers Bouquet in Mason Jar | D34: =IFERROR(INDEX('SKU Data'!$D$2:$D$1780,MATCH($A34,'SKU Data'!$Z$2:$Z$1780,0)),"") -> AUMJ | E34: =IFERROR(INDEX('SKU Data'!$E$2:$E$1780,MATCH($A34,'SKU Data'!$Z$2:$Z$1780,0)),"") -> 6304 | F34: =IFERROR(INDEX('SKU Data'!$F$2:$F$1780,MATCH($A34,'SKU Data'!$Z$2:$Z$1780,0)),"") -> 335 | G34: =IFERROR(INDEX('SKU Data'!$J$2:$J$1780,MATCH($A34,'SKU Data'!$Z$2:$Z$1780,0)),"") -> 0.053140863 | H34: =IFERROR(INDEX('SKU Data'!$H$2:$H$1780,MATCH($A34,'SKU Data'!$Z$2:$Z$1780,0)),"") -> 30439.34 | I34: =IFERROR(INDEX('SKU Data'!$K$2:$K$1780,MATCH($A34,'SKU Data'!$Z$2:$Z$1780,0)),"") -> 0.051522022 | J34: =IFERROR(INDEX('SKU Data'!$M$2:$M$1780,MATCH($A34,'SKU Data'!$Z$2:$Z$1780,0)),"") -> 0.0023631399 | K34: =IFERROR(INDEX('SKU Data'!$L$2:$L$1780,MATCH($A34,'SKU Data'!$Z$2:$Z$1780,0)),"") -> 0.060833826 | L34: =SUM($K$34:K34) -> 0.060833826 | M34: =Settings!$B$3 -> 0.030986151
A35: 2 | B35: =IFERROR(INDEX('SKU Data'!$A$2:$A$1780,MATCH($A35,'SKU Data'!$Z$2:$Z$1780,0)),"") -> AUSGF16-115 | C35: =IFERROR(INDEX('SKU Data'!$B$2:$B$1780,MATCH($A35,'SKU Data'!$Z$2:$Z$1780,0)),"") -> Delicate Elegance | D35: =IFERROR(INDEX('SKU Data'!$D$2:$D$1780,MATCH($A35,'SKU Data'!$Z$2:$Z$1780,0)),"") -> AUSGF | E35: =IFERROR(INDEX('SKU Data'!$E$2:$E$1780,MATCH($A35,'SKU Data'!$Z$2:$Z$1780,0)),"") -> 11490 | F35: =IFERROR(INDEX('SKU Data'!$F$2:$F$1780,MATCH($A35,'SKU Data'!$Z$2:$Z$1780,0)),"") -> 419 | G35: =IFERROR(INDEX('SKU Data'!$J$2:$J$1780,MATCH($A35,'SKU Data'!$Z$2:$Z$1780,0)),"") -> 0.036466493 | H35: =IFERROR(INDEX('SKU Data'!$H$2:$H$1780,MATCH($A35,'SKU Data'!$Z$2:$Z$1780,0)),"") -> 25834.89 | I35: =IFERROR(INDEX('SKU Data'!$K$2:$K$1780,MATCH($A35,'SKU Data'!$Z$2:$Z$1780,0)),"") -> 0.035459214 | J35: =IFERROR(INDEX('SKU Data'!$M$2:$M$1780,MATCH($A35,'SKU Data'!$Z$2:$Z$1780,0)),"") -> 0.0020056762 | K35: =IFERROR(INDEX('SKU Data'!$L$2:$L$1780,MATCH($A35,'SKU Data'!$Z$2:$Z$1780,0)),"") -> 0.051631711 | L35: =SUM($K$34:K35) -> 0.11246554 | M35: =Settings!$B$3 -> 0.030986151
A36: 3 | B36: =IFERROR(INDEX('SKU Data'!$A$2:$A$1780,MATCH($A36,'SKU Data'!$Z$2:$Z$1780,0)),"") -> AUMJ-NW-017 | C36: =IFERROR(INDEX('SKU Data'!$B$2:$B$1780,MATCH($A36,'SKU Data'!$Z$2:$Z$1780,0)),"") -> Pastel Buttercup Bouquet in Mason Jar | D36: =IFERROR(INDEX('SKU Data'!$D$2:$D$1780,MATCH($A36,'SKU Data'!$Z$2:$Z$1780,0)),"") -> AUMJ | E36: =IFERROR(INDEX('SKU Data'!$E$2:$E$1780,MATCH($A36,'SKU Data'!$Z$2:$Z$1780,0)),"") -> 3907 | F36: =IFERROR(INDEX('SKU Data'!$F$2:$F$1780,MATCH($A36,'SKU Data'!$Z$2:$Z$1780,0)),"") -> 172 | G36: =IFERROR(INDEX('SKU Data'!$J$2:$J$1780,MATCH($A36,'SKU Data'!$Z$2:$Z$1780,0)),"") -> 0.044023547 | H36: =IFERROR(INDEX('SKU Data'!$H$2:$H$1780,MATCH($A36,'SKU Data'!$Z$2:$Z$1780,0)),"") -> 14074.44 | I36: =IFERROR(INDEX('SKU Data'!$K$2:$K$1780,MATCH($A36,'SKU Data'!$Z$2:$Z$1780,0)),"") -> 0.040285179 | J36: =IFERROR(INDEX('SKU Data'!$M$2:$M$1780,MATCH($A36,'SKU Data'!$Z$2:$Z$1780,0)),"") -> 0.0010926607 | K36: =IFERROR(INDEX('SKU Data'!$L$2:$L$1780,MATCH($A36,'SKU Data'!$Z$2:$Z$1780,0)),"") -> 0.028128141 | L36: =SUM($K$34:K36) -> 0.14059368 | M36: =Settings!$B$3 -> 0.030986151
A37: 4 | B37: =IFERROR(INDEX('SKU Data'!$A$2:$A$1780,MATCH($A37,'SKU Data'!$Z$2:$Z$1780,0)),"") -> AUSMJ100-11 | C37: =IFERROR(INDEX('SKU Data'!$B$2:$B$1780,MATCH($A37,'SKU Data'!$Z$2:$Z$1780,0)),"") -> Breathtaking Blooms In Mason Jar | D37: =IFERROR(INDEX('SKU Data'!$D$2:$D$1780,MATCH($A37,'SKU Data'!$Z$2:$Z$1780,0)),"") -> AUSMJ | E37: =IFERROR(INDEX('SKU Data'!$E$2:$E$1780,MATCH($A37,'SKU Data'!$Z$2:$Z$1780,0)),"") -> 4959 | F37: =IFERROR(INDEX('SKU Data'!$F$2:$F$1780,MATCH($A37,'SKU Data'!$Z$2:$Z$1780,0)),"") -> 203 | G37: =IFERROR(INDEX('SKU Data'!$J$2:$J$1780,MATCH($A37,'SKU Data'!$Z$2:$Z$1780,0)),"") -> 0.040935673 | H37: =IFERROR(INDEX('SKU Data'!$H$2:$H$1780,MATCH($A37,'SKU Data'!$Z$2:$Z$1780,0)),"") -> 13653.88 | I37: =IFERROR(INDEX('SKU Data'!$K$2:$K$1780,MATCH($A37,'SKU Data'!$Z$2:$Z$1780,0)),"") -> 0.039004288 | J37: =IFERROR(INDEX('SKU Data'!$M$2:$M$1780,MATCH($A37,'SKU Data'!$Z$2:$Z$1780,0)),"") -> 0.0010600108 | K37: =IFERROR(INDEX('SKU Data'!$L$2:$L$1780,MATCH($A37,'SKU Data'!$Z$2:$Z$1780,0)),"") -> 0.02728764 | L37: =SUM($K$34:K37) -> 0.16788132 | M37: =Settings!$B$3 -> 0.030986151
A38: 5 | B38: =IFERROR(INDEX('SKU Data'!$A$2:$A$1780,MATCH($A38,'SKU Data'!$Z$2:$Z$1780,0)),"") -> AU11-43 | C38: =IFERROR(INDEX('SKU Data'!$B$2:$B$1780,MATCH($A38,'SKU Data'!$Z$2:$Z$1780,0)),"") -> Warm Embrace | D38: =IFERROR(INDEX('SKU Data'!$D$2:$D$1780,MATCH($A38,'SKU Data'!$Z$2:$Z$1780,0)),"") -> AU | E38: =IFERROR(INDEX('SKU Data'!$E$2:$E$1780,MATCH($A38,'SKU Data'!$Z$2:$Z$1780,0)),"") -> 2594 | F38: =IFERROR(INDEX('SKU Data'!$F$2:$F$1780,MATCH($A38,'SKU Data'!$Z$2:$Z$1780,0)),"") -> 129 | G38: =IFERROR(INDEX('SKU Data'!$J$2:$J$1780,MATCH($A38,'SKU Data'!$Z$2:$Z$1780,0)),"") -> 0.049730146 | H38: =IFERROR(INDEX('SKU Data'!$H$2:$H$1780,MATCH($A38,'SKU Data'!$Z$2:$Z$1780,0)),"") -> 11840.22 | I38: =IFERROR(INDEX('SKU Data'!$K$2:$K$1780,MATCH($A38,'SKU Data'!$Z$2:$Z$1780,0)),"") -> 0.047722296 | J38: =IFERROR(INDEX('SKU Data'!$M$2:$M$1780,MATCH($A38,'SKU Data'!$Z$2:$Z$1780,0)),"") -> 0.00091920838 | K38: =IFERROR(INDEX('SKU Data'!$L$2:$L$1780,MATCH($A38,'SKU Data'!$Z$2:$Z$1780,0)),"") -> 0.023662993 | L38: =SUM($K$34:K38) -> 0.19154431 | M38: =Settings!$B$3 -> 0.030986151
A39: 6 | B39: =IFERROR(INDEX('SKU Data'!$A$2:$A$1780,MATCH($A39,'SKU Data'!$Z$2:$Z$1780,0)),"") -> AUMJ-NW-011 | C39: =IFERROR(INDEX('SKU Data'!$B$2:$B$1780,MATCH($A39,'SKU Data'!$Z$2:$Z$1780,0)),"") -> Best Birthday Ever Bouquet in Mason Jar | D39: =IFERROR(INDEX('SKU Data'!$D$2:$D$1780,MATCH($A39,'SKU Data'!$Z$2:$Z$1780,0)),"") -> AUMJ | E39: =IFERROR(INDEX('SKU Data'!$E$2:$E$1780,MATCH($A39,'SKU Data'!$Z$2:$Z$1780,0)),"") -> 2143 | F39: =IFERROR(INDEX('SKU Data'!$F$2:$F$1780,MATCH($A39,'SKU Data'!$Z$2:$Z$1780,0)),"") -> 115 | G39: =IFERROR(INDEX('SKU Data'!$J$2:$J$1780,MATCH($A39,'SKU Data'!$Z$2:$Z$1780,0)),"") -> 0.053663089 | H39: =IFERROR(INDEX('SKU Data'!$H$2:$H$1780,MATCH($A39,'SKU Data'!$Z$2:$Z$1780,0)),"") -> 9879.04 | I39: =IFERROR(INDEX('SKU Data'!$K$2:$K$1780,MATCH($A39,'SKU Data'!$Z$2:$Z$1780,0)),"") -> 0.053490444 | J39: =IFERROR(INDEX('SKU Data'!$M$2:$M$1780,MATCH($A39,'SKU Data'!$Z$2:$Z$1780,0)),"") -> 0.00076695335 | K39: =IFERROR(INDEX('SKU Data'!$L$2:$L$1780,MATCH($A39,'SKU Data'!$Z$2:$Z$1780,0)),"") -> 0.019743523 | L39: =SUM($K$34:K39) -> 0.21128783 | M39: =Settings!$B$3 -> 0.030986151
A40: 7 | B40: =IFERROR(INDEX('SKU Data'!$A$2:$A$1780,MATCH($A40,'SKU Data'!$Z$2:$Z$1780,0)),"") -> AU112-10 | C40: =IFERROR(INDEX('SKU Data'!$B$2:$B$1780,MATCH($A40,'SKU Data'!$Z$2:$Z$1780,0)),"") -> Lavender Love | D40: =IFERROR(INDEX('SKU Data'!$D$2:$D$1780,MATCH($A40,'SKU Data'!$Z$2:$Z$1780,0)),"") -> AU | E40: =IFERROR(INDEX('SKU Data'!$E$2:$E$1780,MATCH($A40,'SKU Data'!$Z$2:$Z$1780,0)),"") -> 2208 | F40: =IFERROR(INDEX('SKU Data'!$F$2:$F$1780,MATCH($A40,'SKU Data'!$Z$2:$Z$1780,0)),"") -> 108 | G40: =IFERROR(INDEX('SKU Data'!$J$2:$J$1780,MATCH($A40,'SKU Data'!$Z$2:$Z$1780,0)),"") -> 0.048913043 | H40: =IFERROR(INDEX('SKU Data'!$H$2:$H$1780,MATCH($A40,'SKU Data'!$Z$2:$Z$1780,0)),"") -> 9388.55 | I40: =IFERROR(INDEX('SKU Data'!$K$2:$K$1780,MATCH($A40,'SKU Data'!$Z$2:$Z$1780,0)),"") -> 0.046067461 | J40: =IFERROR(INDEX('SKU Data'!$M$2:$M$1780,MATCH($A40,'SKU Data'!$Z$2:$Z$1780,0)),"") -> 0.00072887445 | K40: =IFERROR(INDEX('SKU Data'!$L$2:$L$1780,MATCH($A40,'SKU Data'!$Z$2:$Z$1780,0)),"") -> 0.018763265 | L40: =SUM($K$34:K40) -> 0.2300511 | M40: =Settings!$B$3 -> 0.030986151
A41: 8 | B41: =IFERROR(INDEX('SKU Data'!$A$2:$A$1780,MATCH($A41,'SKU Data'!$Z$2:$Z$1780,0)),"") -> AUMJ-NW-003 | C41: =IFERROR(INDEX('SKU Data'!$B$2:$B$1780,MATCH($A41,'SKU Data'!$Z$2:$Z$1780,0)),"") -> 50 Blooms of Surprise Bud Roses in Mason Jar | D41: =IFERROR(INDEX('SKU Data'!$D$2:$D$1780,MATCH($A41,'SKU Data'!$Z$2:$Z$1780,0)),"") -> AUMJ | E41: =IFERROR(INDEX('SKU Data'!$E$2:$E$1780,MATCH($A41,'SKU Data'!$Z$2:$Z$1780,0)),"") -> 2769 | F41: =IFERROR(INDEX('SKU Data'!$F$2:$F$1780,MATCH($A41,'SKU Data'!$Z$2:$Z$1780,0)),"") -> 106 | G41: =IFERROR(INDEX('SKU Data'!$J$2:$J$1780,MATCH($A41,'SKU Data'!$Z$2:$Z$1780,0)),"") -> 0.038280968 | H41: =IFERROR(INDEX('SKU Data'!$H$2:$H$1780,MATCH($A41,'SKU Data'!$Z$2:$Z$1780,0)),"") -> 8978.84 | I41: =IFERROR(INDEX('SKU Data'!$K$2:$K$1780,MATCH($A41,'SKU Data'!$Z$2:$Z$1780,0)),"") -> 0.037401582 | J41: =IFERROR(INDEX('SKU Data'!$M$2:$M$1780,MATCH($A41,'SKU Data'!$Z$2:$Z$1780,0)),"") -> 0.00069706686 | K41: =IFERROR(INDEX('SKU Data'!$L$2:$L$1780,MATCH($A41,'SKU Data'!$Z$2:$Z$1780,0)),"") -> 0.017944449 | L41: =SUM($K$34:K41) -> 0.24799555 | M41: =Settings!$B$3 -> 0.030986151
A42: 9 | B42: =IFERROR(INDEX('SKU Data'!$A$2:$A$1780,MATCH($A42,'SKU Data'!$Z$2:$Z$1780,0)),"") -> DC-04S | C42: =IFERROR(INDEX('SKU Data'!$B$2:$B$1780,MATCH($A42,'SKU Data'!$Z$2:$Z$1780,0)),"") -> Designer Sympathy Collection IV | D42: =IFERROR(INDEX('SKU Data'!$D$2:$D$1780,MATCH($A42,'SKU Data'!$Z$2:$Z$1780,0)),"") -> DC | E42: =IFERROR(INDEX('SKU Data'!$E$2:$E$1780,MATCH($A42,'SKU Data'!$Z$2:$Z$1780,0)),"") -> 1695 | F42: =IFERROR(INDEX('SKU Data'!$F$2:$F$1780,MATCH($A42,'SKU Data'!$Z$2:$Z$1780,0)),"") -> 75 | G42: =IFERROR(INDEX('SKU Data'!$J$2:$J$1780,MATCH($A42,'SKU Data'!$Z$2:$Z$1780,0)),"") -> 0.044247788 | H42: =IFERROR(INDEX('SKU Data'!$H$2:$H$1780,MATCH($A42,'SKU Data'!$Z$2:$Z$1780,0)),"") -> 8683.47 | I42: =IFERROR(INDEX('SKU Data'!$K$2:$K$1780,MATCH($A42,'SKU Data'!$Z$2:$Z$1780,0)),"") -> 0.03898614 | J42: =IFERROR(INDEX('SKU Data'!$M$2:$M$1780,MATCH($A42,'SKU Data'!$Z$2:$Z$1780,0)),"") -> 0.00067413599 | K42: =IFERROR(INDEX('SKU Data'!$L$2:$L$1780,MATCH($A42,'SKU Data'!$Z$2:$Z$1780,0)),"") -> 0.017354144 | L42: =SUM($K$34:K42) -> 0.26534969 | M42: =Settings!$B$3 -> 0.030986151
A43: 10 | B43: =IFERROR(INDEX('SKU Data'!$A$2:$A$1780,MATCH($A43,'SKU Data'!$Z$2:$Z$1780,0)),"") -> AUMJ-NW-019 | C43: =IFERROR(INDEX('SKU Data'!$B$2:$B$1780,MATCH($A43,'SKU Data'!$Z$2:$Z$1780,0)),"") -> Garden Party Bouquet in Mason Jar | D43: =IFERROR(INDEX('SKU Data'!$D$2:$D$1780,MATCH($A43,'SKU Data'!$Z$2:$Z$1780,0)),"") -> AUMJ | E43: =IFERROR(INDEX('SKU Data'!$E$2:$E$1780,MATCH($A43,'SKU Data'!$Z$2:$Z$1780,0)),"") -> 1250 | F43: =IFERROR(INDEX('SKU Data'!$F$2:$F$1780,MATCH($A43,'SKU Data'!$Z$2:$Z$1780,0)),"") -> 74 | G43: =IFERROR(INDEX('SKU Data'!$J$2:$J$1780,MATCH($A43,'SKU Data'!$Z$2:$Z$1780,0)),"") -> 0.0592 | H43: =IFERROR(INDEX('SKU Data'!$H$2:$H$1780,MATCH($A43,'SKU Data'!$Z$2:$Z$1780,0)),"") -> 8226.91 | I43: =IFERROR(INDEX('SKU Data'!$K$2:$K$1780,MATCH($A43,'SKU Data'!$Z$2:$Z$1780,0)),"") -> 0.059694511 | J43: =IFERROR(INDEX('SKU Data'!$M$2:$M$1780,MATCH($A43,'SKU Data'!$Z$2:$Z$1780,0)),"") -> 0.00063869122 | K43: =IFERROR(INDEX('SKU Data'!$L$2:$L$1780,MATCH($A43,'SKU Data'!$Z$2:$Z$1780,0)),"") -> 0.016441697 | L43: =SUM($K$34:K43) -> 0.28179139 | M43: =Settings!$B$3 -> 0.030986151
A44: 11 | B44: =IFERROR(INDEX('SKU Data'!$A$2:$A$1780,MATCH($A44,'SKU Data'!$Z$2:$Z$1780,0)),"") -> GF16-100 | C44: =IFERROR(INDEX('SKU Data'!$B$2:$B$1780,MATCH($A44,'SKU Data'!$Z$2:$Z$1780,0)),"") -> Blushing Elegance | D44: =IFERROR(INDEX('SKU Data'!$D$2:$D$1780,MATCH($A44,'SKU Data'!$Z$2:$Z$1780,0)),"") -> GF | E44: =IFERROR(INDEX('SKU Data'!$E$2:$E$1780,MATCH($A44,'SKU Data'!$Z$2:$Z$1780,0)),"") -> 1333 | F44: =IFERROR(INDEX('SKU Data'!$F$2:$F$1780,MATCH($A44,'SKU Data'!$Z$2:$Z$1780,0)),"") -> 70 | G44: =IFERROR(INDEX('SKU Data'!$J$2:$J$1780,MATCH($A44,'SKU Data'!$Z$2:$Z$1780,0)),"") -> 0.052513128 | H44: =IFERROR(INDEX('SKU Data'!$H$2:$H$1780,MATCH($A44,'SKU Data'!$Z$2:$Z$1780,0)),"") -> 6992.71 | I44: =IFERROR(INDEX('SKU Data'!$K$2:$K$1780,MATCH($A44,'SKU Data'!$Z$2:$Z$1780,0)),"") -> 0.046691952 | J44: =IFERROR(INDEX('SKU Data'!$M$2:$M$1780,MATCH($A44,'SKU Data'!$Z$2:$Z$1780,0)),"") -> 0.00054287485 | K44: =IFERROR(INDEX('SKU Data'!$L$2:$L$1780,MATCH($A44,'SKU Data'!$Z$2:$Z$1780,0)),"") -> 0.013975116 | L44: =SUM($K$34:K44) -> 0.29576651 | M44: =Settings!$B$3 -> 0.030986151
A45: 12 | B45: =IFERROR(INDEX('SKU Data'!$A$2:$A$1780,MATCH($A45,'SKU Data'!$Z$2:$Z$1780,0)),"") -> GF16-110 | C45: =IFERROR(INDEX('SKU Data'!$B$2:$B$1780,MATCH($A45,'SKU Data'!$Z$2:$Z$1780,0)),"") -> Pastel Harmony | D45: =IFERROR(INDEX('SKU Data'!$D$2:$D$1780,MATCH($A45,'SKU Data'!$Z$2:$Z$1780,0)),"") -> GF | E45: =IFERROR(INDEX('SKU Data'!$E$2:$E$1780,MATCH($A45,'SKU Data'!$Z$2:$Z$1780,0)),"") -> 1130 | F45: =IFERROR(INDEX('SKU Data'!$F$2:$F$1780,MATCH($A45,'SKU Data'!$Z$2:$Z$1780,0)),"") -> 56 | G45: =IFERROR(INDEX('SKU Data'!$J$2:$J$1780,MATCH($A45,'SKU Data'!$Z$2:$Z$1780,0)),"") -> 0.049557522 | H45: =IFERROR(INDEX('SKU Data'!$H$2:$H$1780,MATCH($A45,'SKU Data'!$Z$2:$Z$1780,0)),"") -> 6386.94 | I45: =IFERROR(INDEX('SKU Data'!$K$2:$K$1780,MATCH($A45,'SKU Data'!$Z$2:$Z$1780,0)),"") -> 0.046227485 | J45: =IFERROR(INDEX('SKU Data'!$M$2:$M$1780,MATCH($A45,'SKU Data'!$Z$2:$Z$1780,0)),"") -> 0.00049584626 | K45: =IFERROR(INDEX('SKU Data'!$L$2:$L$1780,MATCH($A45,'SKU Data'!$Z$2:$Z$1780,0)),"") -> 0.012764469 | L45: =SUM($K$34:K45) -> 0.30853097 | M45: =Settings!$B$3 -> 0.030986151
... A58: 25 | B58: =IFERROR(INDEX('SKU Data'!$A$2:$A$1780,MATCH($A58,'SKU Data'!$Z$2:$Z$1780,0)),"") -> DC-01S | C58: =IFERROR(INDEX('SKU Data'!$B$2:$B$1780,MATCH($A58,'SKU Data'!$Z$2:$Z$1780,0)),"") -> Designer Sympathy Collection I | D58: =IFERROR(INDEX('SKU Data'!$D$2:$D$1780,MATCH($A58,'SKU Data'!$Z$2:$Z$1780,0)),"") -> DC | E58: =IFERROR(INDEX('SKU Data'!$E$2:$E$1780,MATCH($A58,'SKU Data'!$Z$2:$Z$1780,0)),"") -> 1991 | F58: =IFERROR(INDEX('SKU Data'!$F$2:$F$1780,MATCH($A58,'SKU Data'!$Z$2:$Z$1780,0)),"") -> 60 | G58: =IFERROR(INDEX('SKU Data'!$J$2:$J$1780,MATCH($A58,'SKU Data'!$Z$2:$Z$1780,0)),"") -> 0.03013561 | H58: =IFERROR(INDEX('SKU Data'!$H$2:$H$1780,MATCH($A58,'SKU Data'!$Z$2:$Z$1780,0)),"") -> 4255.73 | I58: =IFERROR(INDEX('SKU Data'!$K$2:$K$1780,MATCH($A58,'SKU Data'!$Z$2:$Z$1780,0)),"") -> 0.026901897 | J58: =IFERROR(INDEX('SKU Data'!$M$2:$M$1780,MATCH($A58,'SKU Data'!$Z$2:$Z$1780,0)),"") -> 0.00033039105 | K58: =IFERROR(INDEX('SKU Data'!$L$2:$L$1780,MATCH($A58,'SKU Data'!$Z$2:$Z$1780,0)),"") -> 0.008505189 | L58: =SUM($K$34:K58) -> 0.44728161 | M58: =Settings!$B$3 -> 0.030986151
A61: 3) BY OWN REFUND RATE - highest rate on the SKU's own sales (min volume applies)
A62: # | B62: SKU | C62: Product | D62: Brand / family | E62: Qty ordered | F62: Refunded units | G62: Refund rate (units) | H62: Refund $ | I62: Refund rate ($ own gross) | J62: % of total revenue | K62: % of SKU-attrib. refund $ | L62: Cumulative % of refunds | M62: Baseline rate
A63: 1 | B63: =IFERROR(INDEX('SKU Data'!$A$2:$A$1780,MATCH($A63,'SKU Data'!$AA$2:$AA$1780,0)),"") -> DCA-02-00 | C63: =IFERROR(INDEX('SKU Data'!$B$2:$B$1780,MATCH($A63,'SKU Data'!$AA$2:$AA$1780,0)),"") -> Anniversary Designer Collection II | D63: =IFERROR(INDEX('SKU Data'!$D$2:$D$1780,MATCH($A63,'SKU Data'!$AA$2:$AA$1780,0)),"") -> Other (small prefixes) | E63: =IFERROR(INDEX('SKU Data'!$E$2:$E$1780,MATCH($A63,'SKU Data'!$AA$2:$AA$1780,0)),"") -> 38 | F63: =IFERROR(INDEX('SKU Data'!$F$2:$F$1780,MATCH($A63,'SKU Data'!$AA$2:$AA$1780,0)),"") -> 8 | G63: =IFERROR(INDEX('SKU Data'!$J$2:$J$1780,MATCH($A63,'SKU Data'!$AA$2:$AA$1780,0)),"") -> 0.21052632 | H63: =IFERROR(INDEX('SKU Data'!$H$2:$H$1780,MATCH($A63,'SKU Data'!$AA$2:$AA$1780,0)),"") -> 735.3 | I63: =IFERROR(INDEX('SKU Data'!$K$2:$K$1780,MATCH($A63,'SKU Data'!$AA$2:$AA$1780,0)),"") -> 0.18217495 | J63: =IFERROR(INDEX('SKU Data'!$M$2:$M$1780,MATCH($A63,'SKU Data'!$AA$2:$AA$1780,0)),"") -> 5.7084575e-05 | K63: =IFERROR(INDEX('SKU Data'!$L$2:$L$1780,MATCH($A63,'SKU Data'!$AA$2:$AA$1780,0)),"") -> 0.0014695165 | M63: =Settings!$B$3 -> 0.030986151
A64: 2 | B64: =IFERROR(INDEX('SKU Data'!$A$2:$A$1780,MATCH($A64,'SKU Data'!$AA$2:$AA$1780,0)),"") -> AU100-571 | C64: =IFERROR(INDEX('SKU Data'!$B$2:$B$1780,MATCH($A64,'SKU Data'!$AA$2:$AA$1780,0)),"") -> Hope & Honour Cross | D64: =IFERROR(INDEX('SKU Data'!$D$2:$D$1780,MATCH($A64,'SKU Data'!$AA$2:$AA$1780,0)),"") -> AU | E64: =IFERROR(INDEX('SKU Data'!$E$2:$E$1780,MATCH($A64,'SKU Data'!$AA$2:$AA$1780,0)),"") -> 37 | F64: =IFERROR(INDEX('SKU Data'!$F$2:$F$1780,MATCH($A64,'SKU Data'!$AA$2:$AA$1780,0)),"") -> 7 | G64: =IFERROR(INDEX('SKU Data'!$J$2:$J$1780,MATCH($A64,'SKU Data'!$AA$2:$AA$1780,0)),"") -> 0.18918919 | H64: =IFERROR(INDEX('SKU Data'!$H$2:$H$1780,MATCH($A64,'SKU Data'!$AA$2:$AA$1780,0)),"") -> 1720.43 | I64: =IFERROR(INDEX('SKU Data'!$K$2:$K$1780,MATCH($A64,'SKU Data'!$AA$2:$AA$1780,0)),"") -> 0.18258994 | J64: =IFERROR(INDEX('SKU Data'!$M$2:$M$1780,MATCH($A64,'SKU Data'!$AA$2:$AA$1780,0)),"") -> 0.00013356455 | K64: =IFERROR(INDEX('SKU Data'!$L$2:$L$1780,MATCH($A64,'SKU Data'!$AA$2:$AA$1780,0)),"") -> 0.0034383249 | M64: =Settings!$B$3 -> 0.030986151
A65: 3 | B65: =IFERROR(INDEX('SKU Data'!$A$2:$A$1780,MATCH($A65,'SKU Data'!$AA$2:$AA$1780,0)),"") -> AU100-582 | C65: =IFERROR(INDEX('SKU Data'!$B$2:$B$1780,MATCH($A65,'SKU Data'!$AA$2:$AA$1780,0)),"") -> Rose Garden Heart | D65: =IFERROR(INDEX('SKU Data'!$D$2:$D$1780,MATCH($A65,'SKU Data'!$AA$2:$AA$1780,0)),"") -> AU | E65: =IFERROR(INDEX('SKU Data'!$E$2:$E$1780,MATCH($A65,'SKU Data'!$AA$2:$AA$1780,0)),"") -> 40 | F65: =IFERROR(INDEX('SKU Data'!$F$2:$F$1780,MATCH($A65,'SKU Data'!$AA$2:$AA$1780,0)),"") -> 6 | G65: =IFERROR(INDEX('SKU Data'!$J$2:$J$1780,MATCH($A65,'SKU Data'!$AA$2:$AA$1780,0)),"") -> 0.15 | H65: =IFERROR(INDEX('SKU Data'!$H$2:$H$1780,MATCH($A65,'SKU Data'!$AA$2:$AA$1780,0)),"") -> 1504.25 | I65: =IFERROR(INDEX('SKU Data'!$K$2:$K$1780,MATCH($A65,'SKU Data'!$AA$2:$AA$1780,0)),"") -> 0.13422079 | J65: =IFERROR(INDEX('SKU Data'!$M$2:$M$1780,MATCH($A65,'SKU Data'!$AA$2:$AA$1780,0)),"") -> 0.00011678155 | K65: =IFERROR(INDEX('SKU Data'!$L$2:$L$1780,MATCH($A65,'SKU Data'!$AA$2:$AA$1780,0)),"") -> 0.0030062834 | M65: =Settings!$B$3 -> 0.030986151
A66: 4 | B66: =IFERROR(INDEX('SKU Data'!$A$2:$A$1780,MATCH($A66,'SKU Data'!$AA$2:$AA$1780,0)),"") -> DCB-03 | C66: =IFERROR(INDEX('SKU Data'!$B$2:$B$1780,MATCH($A66,'SKU Data'!$AA$2:$AA$1780,0)),"") -> Birthday Designer Collection III | D66: =IFERROR(INDEX('SKU Data'!$D$2:$D$1780,MATCH($A66,'SKU Data'!$AA$2:$AA$1780,0)),"") -> DCB | E66: =IFERROR(INDEX('SKU Data'!$E$2:$E$1780,MATCH($A66,'SKU Data'!$AA$2:$AA$1780,0)),"") -> 35 | F66: =IFERROR(INDEX('SKU Data'!$F$2:$F$1780,MATCH($A66,'SKU Data'!$AA$2:$AA$1780,0)),"") -> 5 | G66: =IFERROR(INDEX('SKU Data'!$J$2:$J$1780,MATCH($A66,'SKU Data'!$AA$2:$AA$1780,0)),"") -> 0.14285714 | H66: =IFERROR(INDEX('SKU Data'!$H$2:$H$1780,MATCH($A66,'SKU Data'!$AA$2:$AA$1780,0)),"") -> 619.12 | I66: =IFERROR(INDEX('SKU Data'!$K$2:$K$1780,MATCH($A66,'SKU Data'!$AA$2:$AA$1780,0)),"") -> 0.11773946 | J66: =IFERROR(INDEX('SKU Data'!$M$2:$M$1780,MATCH($A66,'SKU Data'!$AA$2:$AA$1780,0)),"") -> 4.806501e-05 | K66: =IFERROR(INDEX('SKU Data'!$L$2:$L$1780,MATCH($A66,'SKU Data'!$AA$2:$AA$1780,0)),"") -> 0.0012373277 | M66: =Settings!$B$3 -> 0.030986151
A67: 5 | B67: =IFERROR(INDEX('SKU Data'!$A$2:$A$1780,MATCH($A67,'SKU Data'!$AA$2:$AA$1780,0)),"") -> AU1211-02 | C67: =IFERROR(INDEX('SKU Data'!$B$2:$B$1780,MATCH($A67,'SKU Data'!$AA$2:$AA$1780,0)),"") -> Three Dozen White Roses | D67: =IFERROR(INDEX('SKU Data'!$D$2:$D$1780,MATCH($A67,'SKU Data'!$AA$2:$AA$1780,0)),"") -> AU | E67: =IFERROR(INDEX('SKU Data'!$E$2:$E$1780,MATCH($A67,'SKU Data'!$AA$2:$AA$1780,0)),"") -> 40 | F67: =IFERROR(INDEX('SKU Data'!$F$2:$F$1780,MATCH($A67,'SKU Data'!$AA$2:$AA$1780,0)),"") -> 5 | G67: =IFERROR(INDEX('SKU Data'!$J$2:$J$1780,MATCH($A67,'SKU Data'!$AA$2:$AA$1780,0)),"") -> 0.125 | H67: =IFERROR(INDEX('SKU Data'!$H$2:$H$1780,MATCH($A67,'SKU Data'!$AA$2:$AA$1780,0)),"") -> 1187.73 | I67: =IFERROR(INDEX('SKU Data'!$K$2:$K$1780,MATCH($A67,'SKU Data'!$AA$2:$AA$1780,0)),"") -> 0.1173237 | J67: =IFERROR(INDEX('SKU Data'!$M$2:$M$1780,MATCH($A67,'SKU Data'!$AA$2:$AA$1780,0)),"") -> 9.2208706e-05 | K67: =IFERROR(INDEX('SKU Data'!$L$2:$L$1780,MATCH($A67,'SKU Data'!$AA$2:$AA$1780,0)),"") -> 0.0023737098 | M67: =Settings!$B$3 -> 0.030986151
